Workbook

Sheet Sheet1
A1: 00:13:50:ff:fe:70:f9:0f | B1: FALSE | C1: Preparing | D1: Idle | F1: Yes | G1: 13 Nov 2024 - 12:49 PM | H1: 13 Nov 2024 - 12:49 PM | I1: Remove Ping Images History
A2: 00:13:50:ff:fe:70:fd:d3 | B2: FALSE | C2: Preparing | D2: Idle | F2: Yes | G2: 13 Nov 2024 - 12:49 PM | H2: 13 Nov 2024 - 12:49 PM | I2: Remove Ping Images History
A3: 00:13:50:ff:fe:71:60:6d | B3: FALSE | C3: Preparing | D3: Idle | F3: Yes | G3: 13 Nov 2024 - 12:49 PM | H3: 13 Nov 2024 - 12:49 PM | I3: Remove Ping Images History
A4: 00:13:50:ff:fe:71:60:7b | B4: FALSE | C4: Preparing | D4: Idle | F4: Yes | G4: 13 Nov 2024 - 12:49 PM | H4: 13 Nov 2024 - 12:49 PM | I4: Remove Ping Images History
A5: 00:13:50:ff:fe:71:60:ab | B5: FALSE | C5: Preparing | D5: Idle | F5: Yes | G5: 13 Nov 2024 - 12:49 PM | H5: 13 Nov 2024 - 12:49 PM | I5: Remove Ping Images History
A6: 00:13:50:ff:fe:71:60:bd | B6: FALSE | C6: Preparing | D6: Idle | F6: Yes | G6: 13 Nov 2024 - 12:49 PM | H6: 13 Nov 2024 - 12:49 PM | I6: Remove Ping Images History
A7: 00:13:50:ff:fe:71:b4:eb | B7: FALSE | C7: Preparing | D7: Idle | F7: Yes | G7: 13 Nov 2024 - 12:49 PM | H7: 13 Nov 2024 - 12:49 PM | I7: Remove Ping Images History
A8: 00:13:50:ff:fe:71:b4:f0 | B8: FALSE | C8: Preparing | D8: Idle | F8: Yes | G8: 13 Nov 2024 - 12:49 PM | H8: 13 Nov 2024 - 12:49 PM | I8: Remove Ping Images History
A9: 00:13:50:ff:fe:71:b4:f7 | B9: FALSE | C9: Preparing | D9: Idle | F9: Yes | G9: 13 Nov 2024 - 12:49 PM | H9: 13 Nov 2024 - 12:49 PM | I9: Remove Ping Images History
A10: 00:13:50:ff:fe:71:b5:0d | B10: FALSE | C10: Preparing | D10: Idle | F10: Yes | G10: 13 Nov 2024 - 12:49 PM | H10: 13 Nov 2024 - 12:49 PM | I10: Remove Ping Images History
A11: 00:13:50:ff:fe:71:b5:25 | B11: FALSE | C11: Preparing | D11: Idle | F11: Yes | G11: 13 Nov 2024 - 12:49 PM | H11: 13 Nov 2024 - 12:49 PM | I11: Remove Ping Images History
A12: 00:13:50:ff:fe:71:b5:30 | B12: FALSE | C12: Preparing | D12: Idle | F12: Yes | G12: 13 Nov 2024 - 12:49 PM | H12: 13 Nov 2024 - 12:49 PM | I12: Remove Ping Images History
... A50: 00:13:50:ff:fe:72:28:ee | B50: FALSE | C50: Preparing | D50: Idle | F50: Yes | G50: 13 Nov 2024 - 12:49 PM | H50: 13 Nov 2024 - 12:49 PM | I50: Remove Ping Images History

Sheet General
A1: Jan | B1: 1
A2: Feb | B2: 2
A3: Mar | B3: 3
A4: Apr | B4: 4
A5: May | B5: 5
A6: Jun | B6: 6
A7: Jul | B7: 7
A8: Aug | B8: 8
A9: Sep | B9: 9
A10: Oct | B10: 10
A11: Nov | B11: 11
A12: Dec | B12: 12

Sheet AP Firmware deplyoment Pe
H1: Date of capturing data (Formula - DND) | L1: Date of capturing data All three stages post upgrade | P1: Date of capturing data (Stage 2a,2b,2c,2d, 2e and 2f post upgrade) | T1: Date of capturing data (Stage 2a,2b,2c,2d, 2e and 2f post upgrade) | X1: Date of capturing data (Stage 2a,2b,2c and 2d post upgrade) | AB1: Date of capturing data (Stage 2a and 2b post upgrade) | AF1: Date of capturing data - Stage 2 (Pre Upgrade) | AJ1: Date of capturing data | AN1: Day 11(Post Upgarde) | AR1: Day 10(Post Upgarde) | AV1: Day 9(Post Upgarde) | AZ1: Day 8(Post Upgarde) | BD1: Day 7(Post Upgarde) | BH1: Day 7(Post Upgarde) | BL1: Day 6(Post Upgarde) | BP1: Day 5(Post Upgarde) | BT1: Day 4(Post Upgarde) | BX1: Day 3(Post Upgarde) | CB1: Day 2 (Post Upgarde) | CF1: Day 3 (Post upgrade) | CJ1: Day 2 (Before upgarde) | CN1: Day 1 (Before Upgarde)
A2: Device_Util_ID | B2: Deployment Statge/Date | C2: City | D2: Region_Code | E2: NIC_MAC_Address | F2: NIC_IP | G2: NIC Version | H2: =TODAY() -> 45686 | I2: Success Rate | J2: Unread | K2: Duration | L2: 45625 | M2: Success Rate | N2: Unread | O2: Duration | P2: 45622 | Q2: Success Rate | R2: Unread | S2: Duration | T2: 45616 | U2: Success Rate | V2: Unread | W2: Duration | X2: 45615 | Y2: Success Rate | Z2: Unread | AA2: Duration | AB2: 45614 | AC2: Success Rate | AD2: Unread | AE2: Duration | AF2: 45609 | AG2: Success Rate | AH2: Unread | AI2: Duration | AJ2: 45509 | AK2: Success Rate | AL2: Unread | AM2: Duration | AN2: 45504 | AO2: Success Rate | AP2: Unread | AQ2: Duration | AR2: 45499 | AS2: Success Rate | AT2: Unread | AU2: Duration | AV2: 45495 | AW2: Success Rate | AX2: Unread | AY2: Duration | AZ2: 45489 | BA2: Success Rate | BB2: Unread | BC2: Duration | BD2: 45484 | BE2: Success Rate | BF2: Unread | BG2: Duration | BH2: 45482 | BI2: Success Rate | BJ2: Unread | BK2: Duration | BL2: 45481 | BM2: Success Rate | BN2: Unread | BO2: Duration | BP2: 45478 | BQ2: Success Rate | BR2: Unread | BS2: Duration | BT2: 45477 | BU2: Success Rate | BV2: Unread | BW2: Duration | BX2: 45475 | BY2: Success Rate | BZ2: Unread | CA2: Duration | CB2: 45474 | CC2: Success Rate | CD2: Unread | CE2: Duration | CF2: 45471 | CG2: Success Rate | CH2: Unread | CI2: Duration | CJ2: 45470 | CK2: Success Rate | CL2: Unread | CM2: Duration | CN2: 45469 | CO2: Success Rate | CP2: Unread | CQ2: Duration | CR2: CHECK
A3: AP2220950297 | B3: BVT - 27/06/2024 | C3: Hawthorn | D3: CitiPower East | E3: 00:13:50:ff:fe:70:df:93 | F3: fd89:1e09:aa00:108:213:50ff:fe70:df93 | G3: 4.8.6002 | H3: =VLOOKUP(A3,'AP Read Performance'!A:K,11,0) -> 1443 | I3: =VLOOKUP(A3,'AP Read Performance'!A:D,4,0) -> 0.98 | J3: =VLOOKUP(A3,'AP Read Performance'!A:I,9,0) -> 18 | K3: =VLOOKUP(A3,'AP Read Performance'!A:N,14,0) -> 0.018055556 | L3: 1443 | M3: 0.98 | N3: 18 | O3: 0.018055556 | P3: 901 | Q3: 0.99 | R3: 7 | S3: 0.011805556 | T3: 939 | U3: 0.99 | V3: 3 | W3: 0.011805556 | X3: 934 | Y3: 0.99 | Z3: 4 | AA3: 0.011111111 | AB3: 951 | AC3: 0.99 | AD3: 7 | AE3: 0.0097222222 | AF3: 911 | AG3: 0.98 | AH3: 11 | AI3: 0.011805556 | AJ3: 1058 | AK3: 0.99 | AL3: 8 | AM3: 0.011111111 | AN3: 1044 | AO3: 0.99 | AP3: 8 | AQ3: 0.0125 | AR3: 1073 | AS3: 0.98 | AT3: 20 | AU3: 0.018055556 | AV3: 1218 | AW3: 0.99 | AX3: 11 | AY3: 0.010416667 | AZ3: 1030 | BA3: 0.98 | BB3: 17 | BC3: 0.011805556 | BD3: 1031 | BE3: 0.98 | BF3: 15 | BG3: 0.019444444 | BH3: 1059 | BI3: 0.97 | BJ3: 24 | BK3: 0.01875 | BL3: 1207 | BM3: 0.99 | BN3: 10 | BO3: 0.011805556 | BP3: 1032 | BQ3: 0.97 | BR3: 27 | BS3: 0.022222222 | BT3: 985 | BU3: 0.99 | BV3: 9 | BW3: 0.011805556 | BX3: 823 | BY3: 0.98 | BZ3: 10 | CA3: 0.011111111 | CB3: 744 | CC3: 0.98 | CD3: 8 | CE3: 0.010416667 | CF3: 643 | CG3: 0.98 | CH3: 9 | CI3: 0.011111111 | CJ3: 966 | CK3: 0.98 | CL3: 12 | CM3: 0.019444444 | CN3: 1010 | CO3: 0.98 | CP3: 12 | CQ3: 0.010416667 | CR3: =VLOOKUP(E3,Sheet1!A:A,1,0) -> #N/A
A4: AP4122950038 | B4: BVT - 27/06/2024 | C4: Richmond | D4: CitiPower East | E4: 00:13:50:ff:fe:71:e9:a1 | F4: fd89:1e09:aa00:2ac:213:50ff:fe71:e9a1 | G4: 4.8.6002 | H4: =VLOOKUP(A4,'AP Read Performance'!A:K,11,0) -> 1354 | I4: =VLOOKUP(A4,'AP Read Performance'!A:D,4,0) -> 0.98 | J4: =VLOOKUP(A4,'AP Read Performance'!A:I,9,0) -> 21 | K4: =VLOOKUP(A4,'AP Read Performance'!A:N,14,0) -> 0.011805556 | L4: 1354 | M4: 0.98 | N4: 21 | O4: 0.011805556 | P4: 1306 | Q4: 0.98 | R4: 15 | S4: 0.011111111 | T4: 1469 | U4: 0.99 | V4: 14 | W4: 0.01875 | X4: 1405 | Y4: 0.98 | Z4: 18 | AA4: 0.011805556 | AB4: 1408 | AC4: 0.99 | AD4: 10 | AE4: 0.011111111 | AF4: 1439 | AG4: 0.99 | AH4: 12 | AI4: 0.011111111 | AJ4: 1547 | AK4: 0.99 | AL4: 11 | AM4: 0.010416667 | AN4: 1572 | AO4: 0.99 | AP4: 15 | AQ4: 0.0097222222 | AR4: 1465 | AS4: 0.98 | AT4: 25 | AU4: 0.010416667 | AV4: 1407 | AW4: 0.98 | AX4: 17 | AY4: 0.0097222222 | AZ4: 1479 | BA4: 0.98 | BB4: 16 | BC4: 0.015972222 | BD4: 1483 | BE4: 0.97 | BF4: 31 | BG4: 0.011805556 | BH4: 1468 | BI4: 0.98 | BJ4: 18 | BK4: 0.015972222 | BL4: 1439 | BM4: 0.98 | BN4: 23 | BO4: 0.016666667 | BP4: 1432 | BQ4: 0.98 | BR4: 18 | BS4: 0.0097222222 | BT4: 1422 | BU4: 0.98 | BV4: 24 | BW4: 0.010416667 | BX4: 1335 | BY4: 0.98 | BZ4: 17 | CA4: 0.015972222 | CB4: 1390 | CC4: 0.98 | CD4: 20 | CE4: 0.011111111 | CF4: 1250 | CG4: 0.98 | CH4: 21 | CI4: 0.0097222222 | CJ4: 1481 | CK4: 0.98 | CL4: 18 | CM4: 0.011111111 | CN4: 1475 | CO4: 0.98 | CP4: 18 | CQ4: 0.010416667 | CR4: =VLOOKUP(E4,Sheet1!A:A,1,0) -> #N/A
A5: AP3322951315 | B5: BVT - 27/06/2024 | C5: RICHMOND | D5: CitiPower East | E5: 00:13:50:ff:fe:71:cf:d2 | F5: fd89:1e09:aa00:27d:213:50ff:fe71:cfd2 | G5: 4.8.6002 | H5: =VLOOKUP(A5,'AP Read Performance'!A:K,11,0) -> 1884 | I5: =VLOOKUP(A5,'AP Read Performance'!A:D,4,0) -> 0.98 | J5: =VLOOKUP(A5,'AP Read Performance'!A:I,9,0) -> 25 | K5: =VLOOKUP(A5,'AP Read Performance'!A:N,14,0) -> 0.01875 | L5: 1884 | M5: 0.98 | N5: 25 | O5: 0.01875 | P5: 1644 | Q5: 0.99 | R5: 12 | S5: 0.013194444 | T5: 1927 | U5: 0.94 | V5: 113 | W5: 0.020138889 | X5: 1497 | Y5: 0.99 | Z5: 14 | AA5: 0.019444444 | AB5: 1507 | AC5: 0.98 | AD5: 17 | AE5: 0.015972222 | AF5: 1618 | AG5: 0.98 | AH5: 18 | AI5: 0.015972222 | AJ5: 1564 | AK5: 0.99 | AL5: 14 | AM5: 0.0125 | AN5: 1646 | AO5: 0.97 | AP5: 35 | AQ5: 0.018055556 | AR5: 1481 | AS5: 0.99 | AT5: 13 | AU5: 0.011805556 | AV5: 1623 | AW5: 0.98 | AX5: 26 | AY5: 0.015972222 | AZ5: 1742 | BA5: 0.98 | BB5: 19 | BC5: 0.016666667 | BD5: 1731 | BE5: 0.98 | BF5: 30 | BG5: 0.019444444 | BH5: 1736 | BI5: 0.97 | BJ5: 38 | BK5: 0.016666667 | BL5: 1827 | BM5: 0.98 | BN5: 23 | BO5: 0.022222222 | BP5: 2002 | BQ5: 0.98 | BR5: 26 | BS5: 0.019444444 | BT5: 1875 | BU5: 0.98 | BV5: 21 | BW5: 0.016666667 | BX5: 1620 | BY5: 0.98 | BZ5: 29 | CA5: 0.022916667 | CB5: 1589 | CC5: 0.97 | CD5: 42 | CE5: 0.023611111 | CF5: 1250 | CG5: 0.98 | CH5: 22 | CI5: 0.020138889 | CJ5: 1813 | CK5: 0.99 | CL5: 18 | CM5: 0.016666667 | CN5: 1820 | CO5: 0.98 | CP5: 23 | CQ5: 0.015972222 | CR5: =VLOOKUP(E5,Sheet1!A:A,1,0) -> #N/A
A6: AP3920950953 | B6: BVT - 27/06/2024 | C6: Richmond | D6: CitiPower East | E6: 00:13:50:ff:fe:70:fd:e1 | F6: fd89:1e09:aa00:133:213:50ff:fe70:fde1 | G6: 4.8.6002 | H6: =VLOOKUP(A6,'AP Read Performance'!A:K,11,0) -> 1815 | I6: =VLOOKUP(A6,'AP Read Performance'!A:D,4,0) -> 0.99 | J6: =VLOOKUP(A6,'AP Read Performance'!A:I,9,0) -> 17 | K6: =VLOOKUP(A6,'AP Read Performance'!A:N,14,0) -> 0.016666667 | L6: 1815 | M6: 0.99 | N6: 17 | O6: 0.016666667 | P6: 1775 | Q6: 0.99 | R6: 11 | S6: 0.015972222 | T6: 1754 | U6: 0.99 | V6: 17 | W6: 0.019444444 | X6: 1677 | Y6: 0.99 | Z6: 11 | AA6: 0.015972222 | AB6: 1656 | AC6: 0.99 | AD6: 7 | AE6: 0.011111111 | AF6: 1699 | AG6: 0.99 | AH6: 16 | AI6: 0.015972222 | AJ6: 1705 | AK6: 0.99 | AL6: 10 | AM6: 0.013194444 | AN6: 1772 | AO6: 0.99 | AP6: 4 | AQ6: 0.011805556 | AR6: 1702 | AS6: 0.99 | AT6: 12 | AU6: 0.011805556 | AV6: 1726 | AW6: 0.99 | AX6: 14 | AY6: 0.011805556 | AZ6: 1716 | BA6: 0.99 | BB6: 13 | BC6: 0.011111111 | BD6: 1655 | BE6: 0.98 | BF6: 22 | BG6: 0.023611111 | BH6: 1652 | BI6: 0.98 | BJ6: 24 | BK6: 0.011111111 | BL6: 1674 | BM6: 0.98 | BN6: 19 | BO6: 0.016666667 | BP6: 1612 | BQ6: 0.98 | BR6: 32 | BS6: 0.011111111 | BT6: 1618 | BU6: 0.99 | BV6: 16 | BW6: 0.0097222222 | BX6: 1538 | BY6: 0.98 | BZ6: 20 | CA6: 0.015277778 | CB6: 1507 | CC6: 0.99 | CD6: 13 | CE6: 0.011805556 | CF6: 1561 | CG6: 0.99 | CH6: 9 | CI6: 0.0090277778 | CJ6: 1719 | CK6: 0.99 | CL6: 10 | CM6: 0.015972222 | CN6: 1779 | CO6: 0.99 | CP6: 12 | CQ6: 0.016666667 | CR6: =VLOOKUP(E6,Sheet1!A:A,1,0) -> #N/A
A7: AP2322950383 | B7: BVT - 27/06/2024 | C7: Richmond | D7: CitiPower East | E7: 00:13:50:ff:fe:71:b4:e9 | F7: fd89:1e09:aa00:217:213:50ff:fe71:b4e9 | G7: 4.8.6002 | H7: =VLOOKUP(A7,'AP Read Performance'!A:K,11,0) -> 1761 | I7: =VLOOKUP(A7,'AP Read Performance'!A:D,4,0) -> 0.99 | J7: =VLOOKUP(A7,'AP Read Performance'!A:I,9,0) -> 15 | K7: =VLOOKUP(A7,'AP Read Performance'!A:N,14,0) -> 0.016666667 | L7: 1761 | M7: 0.99 | N7: 15 | O7: 0.016666667 | P7: 1751 | Q7: 0.98 | R7: 29 | S7: 0.016666667 | T7: 1649 | U7: 0.98 | V7: 28 | W7: 0.019444444 | X7: 1764 | Y7: 0.98 | Z7: 20 | AA7: 0.013194444 | AB7: 1714 | AC7: 0.98 | AD7: 22 | AE7: 0.020138889 | AF7: 1776 | AG7: 0.98 | AH7: 30 | AI7: 0.022222222 | AJ7: 1835 | AK7: 0.99 | AL7: 12 | AM7: 0.018055556 | AN7: 1970 | AO7: 0.98 | AP7: 27 | AQ7: 0.017361111 | AR7: 1963 | AS7: 0.99 | AT7: 18 | AU7: 0.017361111 | AV7: 2064 | AW7: 0.98 | AX7: 27 | AY7: 0.017361111 | AZ7: 2027 | BA7: 0.98 | BB7: 21 | BC7: 0.016666667 | BD7: 2156 | BE7: 0.98 | BF7: 40 | BG7: 0.019444444 | BH7: 2128 | BI7: 0.98 | BJ7: 32 | BK7: 0.017361111 | BL7: 2046 | BM7: 0.97 | BN7: 44 | BO7: 0.022916667 | BP7: 2063 | BQ7: 0.99 | BR7: 16 | BS7: 0.018055556 | BT7: 2039 | BU7: 0.98 | BV7: 22 | BW7: 0.018055556 | BX7: 1908 | BY7: 0.98 | BZ7: 34 | CA7: 0.024305556 | CB7: 1930 | CC7: 0.98 | CD7: 36 | CE7: 0.020138889 | CF7: 1667 | CG7: 0.97 | CH7: 34 | CI7: 0.015972222 | CJ7: 2133 | CK7: 0.98 | CL7: 23 | CM7: 0.017361111 | CN7: 2092 | CO7: 0.99 | CP7: 16 | CQ7: 0.017361111 | CR7: =VLOOKUP(E7,Sheet1!A:A,1,0) -> #N/A
A8: AP3322951383 | B8: BVT - 27/06/2024 | C8: RICHMOND | D8: CitiPower East | E8: 00:13:50:ff:fe:71:cf:ff | F8: fd89:1e09:aa00:264:213:50ff:fe71:cfff | G8: 4.8.6002 | H8: =VLOOKUP(A8,'AP Read Performance'!A:K,11,0) -> 2925 | I8: =VLOOKUP(A8,'AP Read Performance'!A:D,4,0) -> 0.99 | J8: =VLOOKUP(A8,'AP Read Performance'!A:I,9,0) -> 23 | K8: =VLOOKUP(A8,'AP Read Performance'!A:N,14,0) -> 0.020138889 | L8: 2925 | M8: 0.99 | N8: 23 | O8: 0.020138889 | P8: 2709 | Q8: 0.98 | R8: 30 | S8: 0.019444444 | T8: 2672 | U8: 0.99 | V8: 23 | W8: 0.01875 | X8: 2555 | Y8: 0.99 | Z8: 25 | AA8: 0.018055556 | AB8: 2586 | AC8: 0.99 | AD8: 21 | AE8: 0.017361111 | AF8: 2713 | AG8: 0.99 | AH8: 24 | AI8: 0.018055556 | AJ8: 1946 | AK8: 0.99 | AL8: 11 | AM8: 0.018055556 | AN8: 1929 | AO8: 0.99 | AP8: 16 | AQ8: 0.016666667 | AR8: 1919 | AS8: 0.99 | AT8: 9 | AU8: 0.018055556 | AV8: 1909 | AW8: 0.98 | AX8: 21 | AY8: 0.017361111 | AZ8: 1879 | BA8: 0.98 | BB8: 21 | BC8: 0.017361111 | BD8: 1997 | BE8: 0.98 | BF8: 29 | BG8: 0.01875 | BH8: 1953 | BI8: 0.98 | BJ8: 29 | BK8: 0.017361111 | BL8: 1961 | BM8: 0.98 | BN8: 20 | BO8: 0.01875 | BP8: 2036 | BQ8: 0.99 | BR8: 20 | BS8: 0.020138889 | BT8: 2015 | BU8: 0.98 | BV8: 24 | BW8: 0.016666667 | BX8: 2062 | BY8: 0.99 | BZ8: 11 | CA8: 0.017361111 | CB8: 2034 | CC8: 0.99 | CD8: 20 | CE8: 0.018055556 | CF8: 1587 | CG8: 0.98 | CH8: 21 | CI8: 0.015972222 | CJ8: 2437 | CK8: 0.99 | CL8: 17 | CM8: 0.018055556 | CN8: 2457 | CO8: 0.99 | CP8: 21 | CQ8: 0.017361111 | CR8: =VLOOKUP(E8,Sheet1!A:A,1,0) -> #N/A
A9: AP2220950311 | B9: BVT - 27/06/2024 | C9: RICHMOND | D9: CitiPower East | E9: 00:13:50:ff:fe:70:df:a9 | F9: fd89:1e09:aa00:10a:213:50ff:fe70:dfa9 | G9: 4.8.6002 | H9: =VLOOKUP(A9,'AP Read Performance'!A:K,11,0) -> 2333 | I9: =VLOOKUP(A9,'AP Read Performance'!A:D,4,0) -> 0.98 | J9: =VLOOKUP(A9,'AP Read Performance'!A:I,9,0) -> 46 | K9: =VLOOKUP(A9,'AP Read Performance'!A:N,14,0) -> 0.020138889 | L9: 2333 | M9: 0.98 | N9: 46 | O9: 0.020138889 | P9: 2222 | Q9: 0.97 | R9: 65 | S9: 0.019444444 | T9: 2081 | U9: 0.98 | V9: 34 | W9: 0.020138889 | X9: 2110 | Y9: 0.98 | Z9: 34 | AA9: 0.018055556 | AB9: 2079 | AC9: 0.98 | AD9: 31 | AE9: 0.015972222 | AF9: 2046 | AG9: 0.97 | AH9: 44 | AI9: 0.011111111 | AJ9: 2105 | AK9: 0.98 | AL9: 26 | AM9: 0.01875 | AN9: 2061 | AO9: 0.99 | AP9: 14 | AQ9: 0.019444444 | AR9: 2105 | AS9: 0.98 | AT9: 29 | AU9: 0.016666667 | AV9: 1988 | AW9: 0.98 | AX9: 22 | AY9: 0.017361111 | AZ9: 2172 | BA9: 0.99 | BB9: 21 | BC9: 0.020833333 | BD9: 2147 | BE9: 0.95 | BF9: 100 | BG9: 0.023611111 | BH9: 2152 | BI9: 0.98 | BJ9: 33 | BK9: 0.017361111 | BL9: 2133 | BM9: 0.98 | BN9: 23 | BO9: 0.016666667 | BP9: 2336 | BQ9: 0.98 | BR9: 39 | BS9: 0.020138889 | BT9: 2418 | BU9: 0.98 | BV9: 28 | BW9: 0.016666667 | BX9: 2067 | BY9: 0.98 | BZ9: 26 | CA9: 0.017361111 | CB9: 2061 | CC9: 0.98 | CD9: 28 | CE9: 0.016666667 | CF9: 1852 | CG9: 0.99 | CH9: 14 | CI9: 0.015972222 | CJ9: 2171 | CK9: 0.98 | CL9: 37 | CM9: 0.017361111 | CN9: 2194 | CO9: 0.98 | CP9: 24 | CQ9: 0.015972222 | CR9: =VLOOKUP(E9,Sheet1!A:A,1,0) -> #N/A
A10: AP2123950455 | B10: BVT - 27/06/2024 | C10: Richmond | D10: CitiPower East | E10: 00:13:50:ff:fe:72:3c:b3 | F10: fd89:1e09:aa00:646:213:50ff:fe72:3cb3 | G10: 5.4.6040 | H10: =VLOOKUP(A10,'AP Read Performance'!A:K,11,0) -> 2887 | I10: =VLOOKUP(A10,'AP Read Performance'!A:D,4,0) -> 0.98 | J10: =VLOOKUP(A10,'AP Read Performance'!A:I,9,0) -> 51 | K10: =VLOOKUP(A10,'AP Read Performance'!A:N,14,0) -> 0.022916667 | L10: 2887 | M10: 0.98 | N10: 51 | O10: 0.022916667 | P10: 2634 | Q10: 0.97 | R10: 58 | S10: 0.01875 | T10: 2799 | U10: 0.98 | V10: 32 | W10: 0.021527778 | X10: 2833 | Y10: 0.99 | Z10: 25 | AA10: 0.016666667 | AB10: 2935 | AC10: 0.97 | AD10: 77 | AE10: 0.021527778 | AF10: 2573 | AG10: 0.98 | AH10: 29 | AI10: 0.017361111 | AJ10: 2370 | AK10: 0.97 | AL10: 69 | AM10: 0.025694444 | AN10: 2480 | AO10: 0.98 | AP10: 27 | AQ10: 0.018055556 | AR10: 2471 | AS10: 0.98 | AT10: 29 | AU10: 0.01875 | AV10: 2519 | AW10: 0.98 | AX10: 42 | AY10: 0.017361111 | AZ10: 2315 | BA10: 0.96 | BB10: 71 | BC10: 0.024305556 | BD10: 2234 | BE10: 0.92 | BF10: 168 | BG10: 0.024305556 | BH10: 2250 | BI10: 0.96 | BJ10: 79 | BK10: 0.021527778 | BL10: 2429 | BM10: 0.99 | BN10: 24 | BO10: 0.017361111 | BP10: 2209 | BQ10: 0.98 | BR10: 34 | BS10: 0.019444444 | BT10: 2439 | BU10: 0.99 | BV10: 24 | BW10: 0.019444444 | BX10: 1886 | BY10: 0.97 | BZ10: 38 | CA10: 0.016666667 | CB10: 1885 | CC10: 0.98 | CD10: 28 | CE10: 0.015972222 | CF10: 1740 | CG10: 0.98 | CH10: 24 | CI10: 0.015972222 | CJ10: 2357 | CK10: 0.98 | CL10: 37 | CM10: 0.018055556 | CN10: 2333 | CO10: 0.98 | CP10: 24 | CQ10: 0.01875 | CR10: =VLOOKUP(E10,Sheet1!A:A,1,0) -> #N/A
A11: AP4122950098 | B11: BVT - 27/06/2024 | C11: RICHMOND | D11: CitiPower East | E11: 00:13:50:ff:fe:71:e9:2e | F11: fd89:1e09:aa00:2f4:213:50ff:fe71:e92e | G11: 4.8.6002 | H11: =VLOOKUP(A11,'AP Read Performance'!A:K,11,0) -> 2674 | I11: =VLOOKUP(A11,'AP Read Performance'!A:D,4,0) -> 0.98 | J11: =VLOOKUP(A11,'AP Read Performance'!A:I,9,0) -> 28 | K11: =VLOOKUP(A11,'AP Read Performance'!A:N,14,0) -> 0.020833333 | L11: 2674 | M11: 0.98 | N11: 28 | O11: 0.020833333 | P11: 2521 | Q11: 0.98 | R11: 27 | S11: 0.022222222 | T11: 2383 | U11: 0.98 | V11: 40 | W11: 0.019444444 | X11: 2630 | Y11: 0.98 | Z11: 27 | AA11: 0.022222222 | AB11: 2665 | AC11: 0.99 | AD11: 11 | AE11: 0.019444444 | AF11: 2547 | AG11: 0.99 | AH11: 11 | AI11: 0.018055556 | AJ11: 2672 | AK11: 0.99 | AL11: 15 | AM11: 0.011805556 | AN11: 2713 | AO11: 0.99 | AP11: 27 | AQ11: 0.01875 | AR11: 2827 | AS11: 0.99 | AT11: 15 | AU11: 0.019444444 | AV11: 2801 | AW11: 0.99 | AX11: 17 | AY11: 0.01875 | AZ11: 2606 | BA11: 0.99 | BB11: 14 | BC11: 0.01875 | BD11: 2795 | BE11: 0.99 | BF11: 13 | BG11: 0.020833333 | BH11: 2644 | BI11: 0.99 | BJ11: 20 | BK11: 0.016666667 | BL11: 2594 | BM11: 0.99 | BN11: 14 | BO11: 0.016666667 | BP11: 2937 | BQ11: 0.99 | BR11: 18 | BS11: 0.020138889 | BT11: 2929 | BU11: 0.99 | BV11: 17 | BW11: 0.01875 | BX11: 2538 | BY11: 0.99 | BZ11: 23 | CA11: 0.01875 | CB11: 2491 | CC11: 0.99 | CD11: 8 | CE11: 0.019444444 | CF11: 2025 | CG11: 0.99 | CH11: 11 | CI11: 0.016666667 | CJ11: 2774 | CK11: 0.99 | CL11: 23 | CM11: 0.01875 | CN11: 2771 | CO11: 0.98 | CP11: 38 | CQ11: 0.01875 | CR11: =VLOOKUP(E11,Sheet1!A:A,1,0) -> #N/A
A12: AP1223950064 | B12: BVT - 27/06/2024 | C12: RICHMOND | D12: CitiPower East | E12: 00:13:50:ff:fe:72:31:44 | F12: fd89:1e09:aa00:4b2:213:50ff:fe72:3144 | G12: 5.4.6040 | H12: =VLOOKUP(A12,'AP Read Performance'!A:K,11,0) -> 3524 | I12: =VLOOKUP(A12,'AP Read Performance'!A:D,4,0) -> 0.98 | J12: =VLOOKUP(A12,'AP Read Performance'!A:I,9,0) -> 36 | K12: =VLOOKUP(A12,'AP Read Performance'!A:N,14,0) -> 0.022222222 | L12: 3524 | M12: 0.98 | N12: 36 | O12: 0.022222222 | P12: 3404 | Q12: 0.98 | R12: 38 | S12: 0.020833333 | T12: 3380 | U12: 0.97 | V12: 81 | W12: 0.022916667 | X12: 3431 | Y12: 0.99 | Z12: 23 | AA12: 0.01875 | AB12: 3497 | AC12: 0.98 | AD12: 37 | AE12: 0.01875 | AF12: 3525 | AG12: 0.98 | AH12: 36 | AI12: 0.021527778 | AJ12: 3314 | AK12: 0.99 | AL12: 30 | AM12: 0.019444444 | AN12: 3399 | AO12: 0.99 | AP12: 27 | AQ12: 0.020833333 | AR12: 3174 | AS12: 0.99 | AT12: 28 | AU12: 0.019444444 | AV12: 3106 | AW12: 0.99 | AX12: 31 | AY12: 0.019444444 | AZ12: 2943 | BA12: 0.99 | BB12: 24 | BC12: 0.01875 | BD12: 3179 | BE12: 0.98 | BF12: 33 | BG12: 0.020138889 | BH12: 3364 | BI12: 0.98 | BJ12: 39 | BK12: 0.018055556 | BL12: 3268 | BM12: 0.98 | BN12: 48 | BO12: 0.023611111 | BP12: 3511 | BQ12: 0.99 | BR12: 27 | BS12: 0.021527778 | BT12: 3714 | BU12: 0.99 | BV12: 26 | BW12: 0.019444444 | BX12: 3197 | BY12: 0.98 | BZ12: 41 | CA12: 0.022916667 | CB12: 3059 | CC12: 0.98 | CD12: 35 | CE12: 0.022222222 | CF12: 2795 | CG12: 0.98 | CH12: 28 | CI12: 0.016666667 | CJ12: 2158 | CK12: 0.98 | CL12: 22 | CM12: 0.015972222 | CN12: 2051 | CO12: 0.99 | CP12: 13 | CQ12: 0.011111111 | CR12: =VLOOKUP(E12,Sheet1!A:A,1,0) -> #N/A
A13: AP3322951343 | B13: Stage 1 - 03/07/2024 | C13: PARKVILLE | D13: CitiPower North | E13: 00:13:50:ff:fe:71:d0:18 | F13: fd89:1e09:aa00:253:213:50ff:fe71:d018 | G13: 4.8.6002 | H13: =VLOOKUP(A13,'AP Read Performance'!A:K,11,0) -> 366 | I13: =VLOOKUP(A13,'AP Read Performance'!A:D,4,0) -> 0.99 | J13: =VLOOKUP(A13,'AP Read Performance'!A:I,9,0) -> 1 | K13: =VLOOKUP(A13,'AP Read Performance'!A:N,14,0) -> 0.0083333333 | L13: 366 | M13: 0.99 | N13: 1 | O13: 0.0083333333 | P13: 321 | Q13: 0.99 | R13: 2 | S13: 0.0083333333 | T13: 510 | U13: 0.89 | V13: 55 | W13: 0.011805556 | X13: 286 | Y13: 0.99 | Z13: 1 | AA13: 0.0076388889 | AB13: 276 | AC13: 0.98 | AD13: 3 | AE13: 0.0090277778 | AF13: 399 | AG13: 0.99 | AH13: 1 | AI13: 0.0090277778 | AJ13: 351 | AK13: 0.99 | AL13: 2 | AM13: 0.0090277778 | AN13: 314 | AO13: 1 | AP13: 0 | AQ13: 0.0076388889 | AR13: 350 | AS13: 0.99 | AT13: 3 | AU13: 0.0076388889 | AV13: 420 | AW13: 0.99 | AX13: 3 | AY13: 0.0090277778 | AZ13: 354 | BA13: 0.98 | BB13: 4 | BC13: 0.0083333333 | BD13: 431 | BE13: 0.98 | BF13: 6 | BG13: 0.0097222222 | BH13: 320 | BI13: 0.99 | BJ13: 1 | BK13: 0.0097222222 | BL13: 348 | BM13: 0.97 | BN13: 7 | BO13: 0.010416667 | BP13: 396 | BQ13: 0.99 | BR13: 2 | BS13: 0.0090277778 | BT13: 610 | BU13: 0.99 | BV13: 2 | BW13: 0.0090277778 | BX13: 347 | BY13: 0.99 | BZ13: 2 | CA13: 0.0090277778 | CB13: 302 | CC13: 1 | CD13: 0 | CE13: 0.0090277778 | CF13: 487 | CG13: 0.99 | CH13: 1 | CI13: 0.0097222222 | CJ13: 327 | CK13: 0.99 | CL13: 3 | CM13: 0.0090277778 | CN13: 327 | CO13: 0.99 | CP13: 2 | CQ13: 0.0125 | CR13: =VLOOKUP(E13,Sheet1!A:A,1,0) -> #N/A
A14: AP3322951329 | B14: Stage 1 - 03/07/2024 | C14: Docklands | D14: CitiPower North | E14: 00:13:50:ff:fe:71:cf:d7 | F14: fd89:1e09:aa00:278:213:50ff:fe71:cfd7 | G14: 4.8.6002 | H14: =VLOOKUP(A14,'AP Read Performance'!A:K,11,0) -> 404 | I14: =VLOOKUP(A14,'AP Read Performance'!A:D,4,0) -> 0.99 | J14: =VLOOKUP(A14,'AP Read Performance'!A:I,9,0) -> 3 | K14: =VLOOKUP(A14,'AP Read Performance'!A:N,14,0) -> 0.0097222222 | L14: 404 | M14: 0.99 | N14: 3 | O14: 0.0097222222 | P14: 409 | Q14: 0.98 | R14: 6 | S14: 0.011805556 | T14: 428 | U14: 0.98 | V14: 8 | W14: 0.011805556 | X14: 395 | Y14: 1 | Z14: 0 | AA14: 0.0097222222 | AB14: 379 | AC14: 0.98 | AD14: 5 | AE14: 0.010416667 | AF14: 385 | AG14: 1 | AH14: 0 | AI14: 0.0083333333 | AJ14: 423 | AK14: 0.98 | AL14: 7 | AM14: 0.011111111 | AN14: 409 | AO14: 0.98 | AP14: 6 | AQ14: 0.010416667 | AR14: 421 | AS14: 0.99 | AT14: 1 | AU14: 0.011111111 | AV14: 432 | AW14: 1 | AX14: 0 | AY14: 0.011111111 | AZ14: 448 | BA14: 0.99 | BB14: 4 | BC14: 0.0097222222 | BD14: 508 | BE14: 0.98 | BF14: 9 | BG14: 0.0097222222 | BH14: 444 | BI14: 0.99 | BJ14: 3 | BK14: 0.010416667 | BL14: 461 | BM14: 0.99 | BN14: 2 | BO14: 0.011111111 | BP14: 414 | BQ14: 0.99 | BR14: 3 | BS14: 0.0097222222 | BT14: 366 | BU14: 0.99 | BV14: 1 | BW14: 0.010416667 | BX14: 472 | BY14: 0.98 | BZ14: 5 | CA14: 0.010416667 | CB14: 397 | CC14: 0.98 | CD14: 4 | CE14: 0.010416667 | CF14: 396 | CG14: 0.99 | CH14: 3 | CI14: 0.0090277778 | CJ14: 439 | CK14: 0.92 | CL14: 35 | CM14: 0.011805556 | CN14: 407 | CO14: 0.99 | CP14: 3 | CQ14: 0.010416667 | CR14: =VLOOKUP(E14,Sheet1!A:A,1,0) -> #N/A
... A44: AP3920950905 | B44: Stage 1 - 03/07/2024 | C44: Corio | D44: Geelong | E44: 00:13:50:ff:fe:70:fd:c2 | F44: fd89:1e09:aa00:147:213:50ff:fe70:fdc2 | G44: 4.8.6002 | H44: =VLOOKUP(A44,'AP Read Performance'!A:K,11,0) -> 2103 | I44: =VLOOKUP(A44,'AP Read Performance'!A:D,4,0) -> 0.99 | J44: =VLOOKUP(A44,'AP Read Performance'!A:I,9,0) -> 16 | K44: =VLOOKUP(A44,'AP Read Performance'!A:N,14,0) -> 0.016666667 | L44: 2103 | M44: 0.99 | N44: 16 | O44: 0.016666667 | P44: 2006 | Q44: 0.99 | R44: 14 | S44: 0.016666667 | T44: 2006 | U44: 0.99 | V44: 13 | W44: 0.016666667 | X44: 2031 | Y44: 0.98 | Z44: 22 | AA44: 0.017361111 | AB44: 1908 | AC44: 0.99 | AD44: 7 | AE44: 0.016666667 | AF44: 1942 | AG44: 0.99 | AH44: 16 | AI44: 0.015277778 | AJ44: 1683 | AK44: 0.99 | AL44: 6 | AM44: 0.016666667 | AN44: 1659 | AO44: 0.99 | AP44: 10 | AQ44: 0.016666667 | AR44: 1611 | AS44: 0.98 | AT44: 18 | AU44: 0.011805556 | AV44: 1584 | AW44: 0.99 | AX44: 7 | AY44: 0.011805556 | AZ44: 1519 | BA44: 0.98 | BB44: 21 | BC44: 0.011111111 | BD44: 1426 | BE44: 0.98 | BF44: 24 | BG44: 0.0125 | BH44: 1363 | BI44: 0.98 | BJ44: 17 | BK44: 0.0125 | BL44: 1349 | BM44: 0.99 | BN44: 11 | BO44: 0.011805556 | BP44: 1212 | BQ44: 0.98 | BR44: 13 | BS44: 0.013194444 | BT44: 1205 | BU44: 0.99 | BV44: 7 | BW44: 0.011805556 | BX44: 1955 | BY44: 0.99 | BZ44: 11 | CA44: 0.016666667 | CB44: 1956 | CC44: 0.98 | CD44: 21 | CE44: 0.016666667 | CF44: 2012 | CG44: 0.99 | CH44: 9 | CI44: 0.016666667 | CJ44: 2009 | CK44: 0.99 | CL44: 15 | CM44: 0.018055556 | CN44: 2008 | CO44: 0.99 | CP44: 16 | CQ44: 0.019444444 | CR44: =VLOOKUP(E44,Sheet1!A:A,1,0) -> #N/A
A45: AP3621950949 | B45: Stage 1 - 03/07/2024 | C45: Tarneit | D45: Ardeer | E45: 00:13:50:ff:fe:71:60:80 | F45: fd89:1e09:aa00:16c:213:50ff:fe71:6080 | G45: 4.8.6002 | H45: =VLOOKUP(A45,'AP Read Performance'!A:K,11,0) -> #N/A | I45: =VLOOKUP(A45,'AP Read Performance'!A:D,4,0) -> #N/A | J45: =VLOOKUP(A45,'AP Read Performance'!A:I,9,0) -> #N/A | K45: =VLOOKUP(A45,'AP Read Performance'!A:N,14,0) -> #N/A | L45: #N/A | M45: #N/A | N45: #N/A | O45: #N/A | P45: #N/A | Q45: #N/A | R45: #N/A | S45: #N/A | T45: 1831 | U45: 0.99 | V45: 13 | W45: 0.016666667 | X45: 1837 | Y45: 0.99 | Z45: 16 | AA45: 0.010416667 | AB45: 1816 | AC45: 0.99 | AD45: 13 | AE45: 0.010416667 | AF45: 1803 | AG45: 0.99 | AH45: 15 | AI45: 0.015972222 | AJ45: 1687 | AK45: 0.99 | AL45: 10 | AM45: 0.013194444 | AN45: 1720 | AO45: 0.99 | AP45: 10 | AQ45: 0.011805556 | AR45: 1641 | AS45: 0.99 | AT45: 15 | AU45: 0.011805556 | AV45: 1647 | AW45: 0.99 | AX45: 8 | AY45: 0.011805556 | AZ45: 1489 | BA45: 0.99 | BB45: 13 | BC45: 0.020138889 | BD45: 1349 | BE45: 0.98 | BF45: 16 | BG45: 0.018055556 | BH45: 1090 | BI45: 0.97 | BJ45: 24 | BK45: 0.011805556 | BL45: 919 | BM45: 0.99 | BN45: 6 | BO45: 0.011805556 | BP45: 688 | BQ45: 0.99 | BR45: 6 | BS45: 0.011805556 | BT45: 546 | BU45: 0.98 | BV45: 9 | BW45: 0.0097222222 | BX45: 1059 | BY45: 0.99 | BZ45: 6 | CA45: 0.0125 | CB45: 1088 | CC45: 0.98 | CD45: 13 | CE45: 0.018055556 | CF45: 977 | CG45: 0.99 | CH45: 8 | CI45: 0.011805556 | CJ45: 969 | CK45: 0.99 | CL45: 3 | CM45: 0.011111111 | CN45: 874 | CO45: 0.99 | CP45: 6 | CQ45: 0.011111111 | CR45: =VLOOKUP(E45,Sheet1!A:A,1,0) -> #N/A
A46: AP4122950074 | B46: Stage 1 - 03/07/2024 | C46: CARLTON | D46: CitiPower North | E46: 00:13:50:ff:fe:71:e9:82 | F46: fd89:1e09:aa00:2c0:213:50ff:fe71:e982 | G46: 4.8.6002 | H46: =VLOOKUP(A46,'AP Read Performance'!A:K,11,0) -> 3024 | I46: =VLOOKUP(A46,'AP Read Performance'!A:D,4,0) -> 0.99 | J46: =VLOOKUP(A46,'AP Read Performance'!A:I,9,0) -> 27 | K46: =VLOOKUP(A46,'AP Read Performance'!A:N,14,0) -> 0.022222222 | L46: 3024 | M46: 0.99 | N46: 27 | O46: 0.022222222 | P46: 2285 | Q46: 0.98 | R46: 24 | S46: 0.016666667 | T46: 2347 | U46: 0.98 | V46: 37 | W46: 0.021527778 | X46: 2366 | Y46: 0.99 | Z46: 18 | AA46: 0.016666667 | AB46: 2351 | AC46: 0.99 | AD46: 19 | AE46: 0.01875 | AF46: 2308 | AG46: 0.99 | AH46: 12 | AI46: 0.018055556 | AJ46: 1720 | AK46: 0.99 | AL46: 10 | AM46: 0.017361111 | AN46: 1432 | AO46: 0.99 | AP46: 14 | AQ46: 0.011805556 | AR46: 1417 | AS46: 0.99 | AT46: 14 | AU46: 0.011805556 | AV46: 2220 | AW46: 0.98 | AX46: 25 | AY46: 0.017361111 | AZ46: 2134 | BA46: 0.99 | BB46: 13 | BC46: 0.016666667 | BD46: 2195 | BE46: 0.96 | BF46: 74 | BG46: 0.01875 | BH46: 1997 | BI46: 0.98 | BJ46: 21 | BK46: 0.017361111 | BL46: 1947 | BM46: 0.98 | BN46: 24 | BO46: 0.016666667 | BP46: 1650 | BQ46: 0.99 | BR46: 12 | BS46: 0.0125 | BT46: 1588 | BU46: 0.99 | BV46: 14 | BW46: 0.015972222 | BX46: 2442 | BY46: 0.99 | BZ46: 24 | CA46: 0.017361111 | CB46: 2413 | CC46: 0.98 | CD46: 27 | CE46: 0.01875 | CF46: 2336 | CG46: 0.99 | CH46: 17 | CI46: 0.018055556 | CJ46: 2357 | CK46: 0.99 | CL46: 20 | CM46: 0.017361111 | CN46: 2378 | CO46: 0.99 | CP46: 19 | CQ46: 0.017361111 | CR46: =VLOOKUP(E46,Sheet1!A:A,1,0) -> #N/A
A47: AP3920950952 | B47: Stage 1 - 03/07/2024 | C47: Melton South | D47: Ardeer | E47: 00:13:50:ff:fe:70:fd:e0 | F47: fd89:1e09:aa00:134:213:50ff:fe70:fde0 | G47: 4.8.6002 | H47: =VLOOKUP(A47,'AP Read Performance'!A:K,11,0) -> 2875 | I47: =VLOOKUP(A47,'AP Read Performance'!A:D,4,0) -> 0.99 | J47: =VLOOKUP(A47,'AP Read Performance'!A:I,9,0) -> 17 | K47: =VLOOKUP(A47,'AP Read Performance'!A:N,14,0) -> 0.01875 | L47: 2875 | M47: 0.99 | N47: 17 | O47: 0.01875 | P47: 1399 | Q47: 0.99 | R47: 7 | S47: 0.020138889 | T47: 1773 | U47: 0.98 | V47: 18 | W47: 0.015972222 | X47: 1698 | Y47: 0.99 | Z47: 15 | AA47: 0.013194444 | AB47: 1723 | AC47: 0.99 | AD47: 17 | AE47: 0.016666667 | AF47: 1762 | AG47: 0.98 | AH47: 19 | AI47: 0.018055556 | AJ47: 1770 | AK47: 0.98 | AL47: 21 | AM47: 0.0125 | AN47: 2079 | AO47: 0.99 | AP47: 13 | AQ47: 0.016666667 | AR47: 2064 | AS47: 0.99 | AT47: 13 | AU47: 0.01875 | AV47: 1782 | AW47: 0.97 | AX47: 37 | AY47: 0.011805556 | AZ47: 1735 | BA47: 0.98 | BB47: 26 | BC47: 0.020138889 | BD47: 1599 | BE47: 0.98 | BF47: 29 | BG47: 0.020138889 | BH47: 1717 | BI47: 0.98 | BJ47: 18 | BK47: 0.016666667 | BL47: 1660 | BM47: 0.98 | BN47: 17 | BO47: 0.015972222 | BP47: 1182 | BQ47: 0.99 | BR47: 10 | BS47: 0.0125 | BT47: 866 | BU47: 0.99 | BV47: 7 | BW47: 0.0125 | BX47: 2132 | BY47: 0.99 | BZ47: 21 | CA47: 0.020833333 | CB47: 2100 | CC47: 0.99 | CD47: 17 | CE47: 0.011111111 | CF47: 2126 | CG47: 0.99 | CH47: 15 | CI47: 0.018055556 | CJ47: 2017 | CK47: 0.99 | CL47: 13 | CM47: 0.01875 | CN47: 2044 | CO47: 0.98 | CP47: 22 | CQ47: 0.016666667 | CR47: =VLOOKUP(E47,Sheet1!A:A,1,0) -> #N/A
A48: AP3322951344 | B48: Stage 1 - 03/07/2024 | C48: ALBERT PARK | D48: CitiPower South | E48: 00:13:50:ff:fe:71:d0:48 | F48: fd89:1e09:aa00:237:213:50ff:fe71:d048 | G48: 4.8.6002 | H48: =VLOOKUP(A48,'AP Read Performance'!A:K,11,0) -> 2561 | I48: =VLOOKUP(A48,'AP Read Performance'!A:D,4,0) -> 0.99 | J48: =VLOOKUP(A48,'AP Read Performance'!A:I,9,0) -> 23 | K48: =VLOOKUP(A48,'AP Read Performance'!A:N,14,0) -> 0.021527778 | L48: 2561 | M48: 0.99 | N48: 23 | O48: 0.021527778 | P48: 2149 | Q48: 0.99 | R48: 15 | S48: 0.017361111 | T48: 2223 | U48: 0.99 | V48: 21 | W48: 0.019444444 | X48: 2172 | Y48: 0.99 | Z48: 18 | AA48: 0.01875 | AB48: 2161 | AC48: 0.99 | AD48: 17 | AE48: 0.016666667 | AF48: 2297 | AG48: 0.99 | AH48: 22 | AI48: 0.018055556 | AJ48: 1832 | AK48: 0.99 | AL48: 10 | AM48: 0.016666667 | AN48: 1846 | AO48: 0.99 | AP48: 11 | AQ48: 0.015972222 | AR48: 1647 | AS48: 0.99 | AT48: 10 | AU48: 0.010416667 | AV48: 2065 | AW48: 0.99 | AX48: 16 | AY48: 0.034722222 | AZ48: 2155 | BA48: 0.99 | BB48: 12 | BC48: 0.015972222 | BD48: 1999 | BE48: 0.98 | BF48: 21 | BG48: 0.01875 | BH48: 2186 | BI48: 0.98 | BJ48: 32 | BK48: 0.017361111 | BL48: 2105 | BM48: 0.99 | BN48: 14 | BO48: 0.016666667 | BP48: 1574 | BQ48: 0.98 | BR48: 16 | BS48: 0.0125 | BT48: 1508 | BU48: 0.99 | BV48: 14 | BW48: 0.015972222 | BX48: 2242 | BY48: 0.99 | BZ48: 14 | CA48: 0.01875 | CB48: 2213 | CC48: 0.99 | CD48: 19 | CE48: 0.041666667 | CF48: 2351 | CG48: 0.99 | CH48: 20 | CI48: 0.016666667 | CJ48: 2373 | CK48: 0.98 | CL48: 25 | CM48: 0.018055556 | CN48: 2315 | CO48: 0.99 | CP48: 11 | CQ48: 0.017361111 | CR48: =VLOOKUP(E48,Sheet1!A:A,1,0) -> #N/A
A49: AP3920950922 | B49: Stage 1 - 03/07/2024 | C49: Bell Park | D49: Geelong | E49: 00:13:50:ff:fe:70:fd:be | F49: fd89:1e09:aa00:14b:213:50ff:fe70:fdbe | G49: 4.8.6002 | H49: =VLOOKUP(A49,'AP Read Performance'!A:K,11,0) -> 1925 | I49: =VLOOKUP(A49,'AP Read Performance'!A:D,4,0) -> 0.98 | J49: =VLOOKUP(A49,'AP Read Performance'!A:I,9,0) -> 29 | K49: =VLOOKUP(A49,'AP Read Performance'!A:N,14,0) -> 0.020138889 | L49: 1925 | M49: 0.98 | N49: 29 | O49: 0.020138889 | P49: 1541 | Q49: 0.98 | R49: 30 | S49: 0.011805556 | T49: 1869 | U49: 0.98 | V49: 25 | W49: 0.020138889 | X49: 1931 | Y49: 0.98 | Z49: 29 | AA49: 0.01875 | AB49: 1981 | AC49: 0.98 | AD49: 34 | AE49: 0.016666667 | AF49: 1598 | AG49: 0.98 | AH49: 22 | AI49: 0.015972222 | AJ49: 1834 | AK49: 0.98 | AL49: 21 | AM49: 0.018055556 | AN49: 1851 | AO49: 0.98 | AP49: 24 | AQ49: 0.017361111 | AR49: 1900 | AS49: 0.98 | AT49: 29 | AU49: 0.017361111 | AV49: 1918 | AW49: 0.98 | AX49: 22 | AY49: 0.020138889 | AZ49: 1990 | BA49: 0.98 | BB49: 22 | BC49: 0.017361111 | BD49: 1976 | BE49: 0.97 | BF49: 44 | BG49: 0.023611111 | BH49: 2014 | BI49: 0.98 | BJ49: 31 | BK49: 0.021527778 | BL49: 1928 | BM49: 0.98 | BN49: 26 | BO49: 0.020138889 | BP49: 1715 | BQ49: 0.98 | BR49: 19 | BS49: 0.018055556 | BT49: 1591 | BU49: 0.96 | BV49: 53 | BW49: 0.019444444 | BX49: 1919 | BY49: 0.98 | BZ49: 28 | CA49: 0.017361111 | CB49: 1876 | CC49: 0.98 | CD49: 26 | CE49: 0.016666667 | CF49: 1798 | CG49: 0.99 | CH49: 16 | CI49: 0.01875 | CJ49: 1800 | CK49: 0.98 | CL49: 24 | CM49: 0.011111111 | CN49: 1787 | CO49: 0.98 | CP49: 31 | CQ49: 0.015972222 | CR49: =VLOOKUP(E49,Sheet1!A:A,1,0) -> #N/A
A50: AP3920950925 | B50: Stage 1 - 03/07/2024 | C50: Leopold | D50: Geelong | E50: 00:13:50:ff:fe:70:fd:cb | F50: fd89:1e09:aa00:143:213:50ff:fe70:fdcb | G50: 4.8.6002 | H50: =VLOOKUP(A50,'AP Read Performance'!A:K,11,0) -> 2602 | I50: =VLOOKUP(A50,'AP Read Performance'!A:D,4,0) -> 0.98 | J50: =VLOOKUP(A50,'AP Read Performance'!A:I,9,0) -> 35 | K50: =VLOOKUP(A50,'AP Read Performance'!A:N,14,0) -> 0.020138889 | L50: 2602 | M50: 0.98 | N50: 35 | O50: 0.020138889 | P50: 2144 | Q50: 0.97 | R50: 48 | S50: 0.019444444 | T50: 2462 | U50: 0.98 | V50: 25 | W50: 0.019444444 | X50: 2448 | Y50: 0.98 | Z50: 33 | AA50: 0.022222222 | AB50: 2339 | AC50: 0.98 | AD50: 25 | AE50: 0.020833333 | AF50: 2480 | AG50: 0.98 | AH50: 33 | AI50: 0.020138889 | AJ50: 1836 | AK50: 0.98 | AL50: 28 | AM50: 0.013194444 | AN50: 1826 | AO50: 0.99 | AP50: 15 | AQ50: 0.017361111 | AR50: 1848 | AS50: 0.98 | AT50: 21 | AU50: 0.020138889 | AV50: 2313 | AW50: 0.99 | AX50: 19 | AY50: 0.017361111 | AZ50: 2038 | BA50: 0.98 | BB50: 26 | BC50: 0.020833333 | BD50: 1998 | BE50: 0.98 | BF50: 38 | BG50: 0.018055556 | BH50: 1899 | BI50: 0.97 | BJ50: 38 | BK50: 0.015972222 | BL50: 1826 | BM50: 0.99 | BN50: 10 | BO50: 0.020138889 | BP50: 1349 | BQ50: 0.97 | BR50: 33 | BS50: 0.015972222 | BT50: 1251 | BU50: 0.98 | BV50: 14 | BW50: 0.0125 | BX50: 2066 | BY50: 0.98 | BZ50: 22 | CA50: 0.017361111 | CB50: 2009 | CC50: 0.98 | CD50: 31 | CE50: 0.018055556 | CF50: 2144 | CG50: 0.99 | CH50: 20 | CI50: 0.018055556 | CJ50: 2197 | CK50: 0.98 | CL50: 38 | CM50: 0.017361111 | CN50: 2170 | CO50: 0.99 | CP50: 19 | CQ50: 0.018055556 | CR50: =VLOOKUP(E50,Sheet1!A:A,1,0) -> #N/A
A51: AP2422950130 | B51: Stage 1 - 03/07/2024 | C51: Toorak | D51: CitiPower South | E51: 00:13:50:ff:fe:71:ba:47 | F51: fd89:1e09:aa00:1c8:213:50ff:fe71:ba47 | G51: 4.8.6002 | H51: =VLOOKUP(A51,'AP Read Performance'!A:K,11,0) -> 1993 | I51: =VLOOKUP(A51,'AP Read Performance'!A:D,4,0) -> 0.97 | J51: =VLOOKUP(A51,'AP Read Performance'!A:I,9,0) -> 53 | K51: =VLOOKUP(A51,'AP Read Performance'!A:N,14,0) -> 0.01875 | L51: 1993 | M51: 0.97 | N51: 53 | O51: 0.01875 | P51: 1700 | Q51: 0.95 | R51: 77 | S51: 0.025694444 | T51: 1811 | U51: 0.97 | V51: 40 | W51: 0.019444444 | X51: 1563 | Y51: 0.97 | Z51: 42 | AA51: 0.018055556 | AB51: 1620 | AC51: 0.97 | AD51: 40 | AE51: 0.013194444 | AF51: 1680 | AG51: 0.94 | AH51: 88 | AI51: 0.01875 | AJ51: 1839 | AK51: 0.98 | AL51: 25 | AM51: 0.022222222 | AN51: 1823 | AO51: 0.96 | AP51: 65 | AQ51: 0.022916667 | AR51: 1832 | AS51: 0.98 | AT51: 19 | AU51: 0.019444444 | AV51: 1969 | AW51: 0.99 | AX51: 18 | AY51: 0.017361111 | AZ51: 2263 | BA51: 0.98 | BB51: 32 | BC51: 0.017361111 | BD51: 1778 | BE51: 0.96 | BF51: 54 | BG51: 0.019444444 | BH51: 1742 | BI51: 0.97 | BJ51: 36 | BK51: 0.015972222 | BL51: 1661 | BM51: 0.98 | BN51: 22 | BO51: 0.0125 | BP51: 1400 | BQ51: 0.98 | BR51: 17 | BS51: 0.020833333 | BT51: 1184 | BU51: 0.98 | BV51: 14 | BW51: 0.019444444 | BX51: 1823 | BY51: 0.98 | BZ51: 30 | CA51: 0.015972222 | CB51: 1804 | CC51: 0.97 | CD51: 45 | CE51: 0.020138889 | CF51: 2048 | CG51: 0.98 | CH51: 36 | CI51: 0.016666667 | CJ51: 1658 | CK51: 0.98 | CL51: 29 | CM51: 0.013888889 | CN51: 1560 | CO51: 0.98 | CP51: 21 | CQ51: 0.0125 | CR51: =VLOOKUP(E51,Sheet1!A:A,1,0) -> #N/A
A52: AP1223950235 | B52: Stage 1 - 03/07/2024 | C52: BALWYN NORTH | D52: CitiPower East | E52: 00:13:50:ff:fe:72:28:d9 | F52: fd89:1e09:aa00:59e:213:50ff:fe72:28d9 | G52: 5.4.6040 | H52: =VLOOKUP(A52,'AP Read Performance'!A:K,11,0) -> 1931 | I52: =VLOOKUP(A52,'AP Read Performance'!A:D,4,0) -> 0.98 | J52: =VLOOKUP(A52,'AP Read Performance'!A:I,9,0) -> 26 | K52: =VLOOKUP(A52,'AP Read Performance'!A:N,14,0) -> 0.016666667 | L52: 1931 | M52: 0.98 | N52: 26 | O52: 0.016666667 | P52: 1745 | Q52: 0.98 | R52: 25 | S52: 0.016666667 | T52: 1812 | U52: 0.99 | V52: 17 | W52: 0.01875 | X52: 1785 | Y52: 0.98 | Z52: 21 | AA52: 0.016666667 | AB52: 1865 | AC52: 0.98 | AD52: 24 | AE52: 0.016666667 | AF52: 1843 | AG52: 0.98 | AH52: 19 | AI52: 0.016666667 | AJ52: 1841 | AK52: 0.98 | AL52: 21 | AM52: 0.019444444 | AN52: 1829 | AO52: 0.98 | AP52: 32 | AQ52: 0.01875 | AR52: 1904 | AS52: 0.98 | AT52: 33 | AU52: 0.01875 | AV52: 1793 | AW52: 0.98 | AX52: 33 | AY52: 0.011111111 | AZ52: 1785 | BA52: 0.97 | BB52: 36 | BC52: 0.01875 | BD52: 1836 | BE52: 0.98 | BF52: 33 | BG52: 0.018055556 | BH52: 1672 | BI52: 0.97 | BJ52: 38 | BK52: 0.01875 | BL52: 1789 | BM52: 0.98 | BN52: 28 | BO52: 0.015972222 | BP52: 1767 | BQ52: 0.98 | BR52: 26 | BS52: 0.019444444 | BT52: 1818 | BU52: 0.98 | BV52: 35 | BW52: 0.017361111 | BX52: 1844 | BY52: 0.98 | BZ52: 23 | CA52: 0.01875 | CB52: 1823 | CC52: 0.98 | CD52: 30 | CE52: 0.019444444 | CF52: 1821 | CG52: 0.99 | CH52: 13 | CI52: 0.018055556 | CJ52: 1829 | CK52: 0.98 | CL52: 24 | CM52: 0.016666667 | CN52: 1796 | CO52: 0.98 | CP52: 25 | CQ52: 0.016666667 | CR52: =VLOOKUP(E52,Sheet1!A:A,1,0) -> #N/A
A53: AP4122950087 | B53: Stage 1 - 03/07/2024 | C53: Caulfield North | D53: CitiPower South | E53: 00:13:50:ff:fe:71:e9:39 | F53: fd89:1e09:aa00:2f1:213:50ff:fe71:e939 | G53: 4.8.6002 | H53: =VLOOKUP(A53,'AP Read Performance'!A:K,11,0) -> 2298 | I53: =VLOOKUP(A53,'AP Read Performance'!A:D,4,0) -> 0.98 | J53: =VLOOKUP(A53,'AP Read Performance'!A:I,9,0) -> 34 | K53: =VLOOKUP(A53,'AP Read Performance'!A:N,14,0) -> 0.020833333 | L53: 2298 | M53: 0.98 | N53: 34 | O53: 0.020833333 | P53: 1856 | Q53: 0.98 | R53: 26 | S53: 0.018055556 | T53: 1937 | U53: 0.98 | V53: 27 | W53: 0.0097222222 | X53: 1870 | Y53: 0.99 | Z53: 9 | AA53: 0.016666667 | AB53: 1876 | AC53: 0.99 | AD53: 17 | AE53: 0.017361111 | AF53: 1877 | AG53: 0.98 | AH53: 23 | AI53: 0.021527778 | AJ53: 1845 | AK53: 0.98 | AL53: 28 | AM53: 0.016666667 | AN53: 1909 | AO53: 0.99 | AP53: 19 | AQ53: 0.0097222222 | AR53: 2041 | AS53: 0.99 | AT53: 11 | AU53: 0.015972222 | AV53: 1969 | AW53: 0.98 | AX53: 22 | AY53: 0.018055556 | AZ53: 1947 | BA53: 0.99 | BB53: 14 | BC53: 0.016666667 | BD53: 1919 | BE53: 0.99 | BF53: 16 | BG53: 0.015972222 | BH53: 1819 | BI53: 0.98 | BJ53: 31 | BK53: 0.018055556 | BL53: 1769 | BM53: 0.99 | BN53: 11 | BO53: 0.011111111 | BP53: 1521 | BQ53: 0.99 | BR53: 14 | BS53: 0.010416667 | BT53: 1375 | BU53: 0.99 | BV53: 12 | BW53: 0.0090277778 | BX53: 1867 | BY53: 0.96 | BZ53: 57 | CA53: 0.01875 | CB53: 1827 | CC53: 0.99 | CD53: 12 | CE53: 0.015972222 | CF53: 1934 | CG53: 0.96 | CH53: 67 | CI53: 0.016666667 | CJ53: 1883 | CK53: 0.99 | CL53: 18 | CM53: 0.016666667 | CN53: 1922 | CO53: 0.99 | CP53: 17 | CQ53: 0.0097222222 | CR53: =VLOOKUP(E53,Sheet1!A:A,1,0) -> #N/A
A54: AP4122950039 | B54: Stage 1 - 03/07/2024 | C54: ALBERT PARK | D54: CitiPower South | E54: 00:13:50:ff:fe:71:e9:c0 | F54: fd89:1e09:aa00:294:213:50ff:fe71:e9c0 | G54: 4.8.6002 | H54: =VLOOKUP(A54,'AP Read Performance'!A:K,11,0) -> 2183 | I54: =VLOOKUP(A54,'AP Read Performance'!A:D,4,0) -> 0.98 | J54: =VLOOKUP(A54,'AP Read Performance'!A:I,9,0) -> 28 | K54: =VLOOKUP(A54,'AP Read Performance'!A:N,14,0) -> 0.01875 | L54: 2183 | M54: 0.98 | N54: 28 | O54: 0.01875 | P54: 1740 | Q54: 0.98 | R54: 19 | S54: 0.015972222 | T54: 1643 | U54: 0.98 | V54: 19 | W54: 0.019444444 | X54: 2000 | Y54: 0.98 | Z54: 21 | AA54: 0.017361111 | AB54: 2005 | AC54: 0.98 | AD54: 25 | AE54: 0.017361111 | AF54: 2031 | AG54: 0.98 | AH54: 34 | AI54: 0.01875 | AJ54: 1861 | AK54: 0.98 | AL54: 23 | AM54: 0.017361111 | AN54: 1786 | AO54: 0.97 | AP54: 47 | AQ54: 0.01875 | AR54: 1687 | AS54: 0.98 | AT54: 22 | AU54: 0.010416667 | AV54: 1559 | AW54: 0.99 | AX54: 14 | AY54: 0.010416667 | AZ54: 1303 | BA54: 0.98 | BB54: 17 | BC54: 0.0097222222 | BD54: 1623 | BE54: 0.98 | BF54: 25 | BG54: 0.019444444 | BH54: 1619 | BI54: 0.98 | BJ54: 23 | BK54: 0.017361111 | BL54: 1605 | BM54: 0.98 | BN54: 18 | BO54: 0.013194444 | BP54: 1831 | BQ54: 0.98 | BR54: 23 | BS54: 0.016666667 | BT54: 1757 | BU54: 0.99 | BV54: 17 | BW54: 0.0097222222 | BX54: 1797 | BY54: 0.98 | BZ54: 18 | CA54: 0.016666667 | CB54: 1758 | CC54: 0.98 | CD54: 20 | CE54: 0.016666667 | CF54: 1532 | CG54: 0.99 | CH54: 8 | CI54: 0.011111111 | CJ54: 1557 | CK54: 0.98 | CL54: 20 | CM54: 0.011111111 | CN54: 1541 | CO54: 0.98 | CP54: 21 | CQ54: 0.010416667 | CR54: =VLOOKUP(E54,Sheet1!A:A,1,0) -> #N/A
A55: AP0222950044 | B55: Stage 1 - 03/07/2024 | C55: Highton | D55: Geelong | E55: 00:13:50:ff:fe:71:91:ab | F55: fd89:1e09:aa00:193:213:50ff:fe71:91ab | G55: 4.8.6002 | H55: =VLOOKUP(A55,'AP Read Performance'!A:K,11,0) -> 2250 | I55: =VLOOKUP(A55,'AP Read Performance'!A:D,4,0) -> 0.98 | J55: =VLOOKUP(A55,'AP Read Performance'!A:I,9,0) -> 40 | K55: =VLOOKUP(A55,'AP Read Performance'!A:N,14,0) -> 0.018055556 | L55: 2250 | M55: 0.98 | N55: 40 | O55: 0.018055556 | P55: 2215 | Q55: 0.98 | R55: 27 | S55: 0.018055556 | T55: 2297 | U55: 0.98 | V55: 29 | W55: 0.019444444 | X55: 2100 | Y55: 0.98 | Z55: 38 | AA55: 0.016666667 | AB55: 2103 | AC55: 0.98 | AD55: 24 | AE55: 0.018055556 | AF55: 2105 | AG55: 0.98 | AH55: 23 | AI55: 0.020833333 | AJ55: 1872 | AK55: 0.98 | AL55: 25 | AM55: 0.019444444 | AN55: 1816 | AO55: 0.98 | AP55: 28 | AQ55: 0.017361111 | AR55: 1886 | AS55: 0.98 | AT55: 30 | AU55: 0.018055556 | AV55: 1825 | AW55: 0.99 | AX55: 13 | AY55: 0.021527778 | AZ55: 1816 | BA55: 0.98 | BB55: 26 | BC55: 0.016666667 | BD55: 1602 | BE55: 0.97 | BF55: 33 | BG55: 0.016666667 | BH55: 1553 | BI55: 0.97 | BJ55: 41 | BK55: 0.016666667 | BL55: 1433 | BM55: 0.99 | BN55: 12 | BO55: 0.015972222 | BP55: 950 | BQ55: 0.98 | BR55: 18 | BS55: 0.022916667 | BT55: 724 | BU55: 0.96 | BV55: 22 | BW55: 0.020833333 | BX55: 2169 | BY55: 0.99 | BZ55: 12 | CA55: 0.018055556 | CB55: 2120 | CC55: 0.99 | CD55: 18 | CE55: 0.016666667 | CF55: 2136 | CG55: 0.99 | CH55: 20 | CI55: 0.018055556 | CJ55: 2120 | CK55: 0.98 | CL55: 24 | CM55: 0.019444444 | CN55: 2128 | CO55: 0.98 | CP55: 26 | CQ55: 0.017361111 | CR55: =VLOOKUP(E55,Sheet1!A:A,1,0) -> #N/A
A56: AP3920950928 | B56: Stage 1 - 03/07/2024 | C56: St Albans Park | D56: Geelong | E56: 00:13:50:ff:fe:70:fd:cf | F56: fd89:1e09:aa00:140:213:50ff:fe70:fdcf | G56: 4.8.6002 | H56: =VLOOKUP(A56,'AP Read Performance'!A:K,11,0) -> 2396 | I56: =VLOOKUP(A56,'AP Read Performance'!A:D,4,0) -> 0.99 | J56: =VLOOKUP(A56,'AP Read Performance'!A:I,9,0) -> 10 | K56: =VLOOKUP(A56,'AP Read Performance'!A:N,14,0) -> 0.018055556 | L56: 2396 | M56: 0.99 | N56: 10 | O56: 0.018055556 | P56: 1802 | Q56: 0.98 | R56: 19 | S56: 0.016666667 | T56: 2453 | U56: 0.98 | V56: 29 | W56: 0.019444444 | X56: 2372 | Y56: 0.99 | Z56: 17 | AA56: 0.017361111 | AB56: 2372 | AC56: 0.98 | AD56: 24 | AE56: 0.018055556 | AF56: 2257 | AG56: 0.99 | AH56: 21 | AI56: 0.018055556 | AJ56: 1878 | AK56: 0.99 | AL56: 15 | AM56: 0.017361111 | AN56: 1740 | AO56: 0.99 | AP56: 13 | AQ56: 0.016666667 | AR56: 1735 | AS56: 0.99 | AT56: 13 | AU56: 0.016666667 | AV56: 1681 | AW56: 0.99 | AX56: 10 | AY56: 0.0097222222 | AZ56: 1780 | BA56: 0.99 | BB56: 16 | BC56: 0.016666667 | BD56: 1695 | BE56: 0.98 | BF56: 19 | BG56: 0.016666667 | BH56: 1680 | BI56: 0.98 | BJ56: 21 | BK56: 0.016666667 | BL56: 1639 | BM56: 0.99 | BN56: 11 | BO56: 0.017361111 | BP56: 1430 | BQ56: 0.97 | BR56: 31 | BS56: 0.016666667 | BT56: 1265 | BU56: 0.99 | BV56: 10 | BW56: 0.011111111 | BX56: 2110 | BY56: 0.99 | BZ56: 15 | CA56: 0.016666667 | CB56: 2110 | CC56: 0.98 | CD56: 26 | CE56: 0.017361111 | CF56: 2042 | CG56: 0.98 | CH56: 28 | CI56: 0.018055556 | CJ56: 2096 | CK56: 0.98 | CL56: 21 | CM56: 0.017361111 | CN56: 2177 | CO56: 0.99 | CP56: 14 | CQ56: 0.017361111 | CR56: =VLOOKUP(E56,Sheet1!A:A,1,0) -> #N/A
A57: AP4122950114 | B57: Stage 1 - 03/07/2024 | C57: Port Melbourne | D57: CitiPower South | E57: 00:13:50:ff:fe:71:e9:9b | F57: fd89:1e09:aa00:2b0:213:50ff:fe71:e99b | G57: 4.8.6002 | H57: =VLOOKUP(A57,'AP Read Performance'!A:K,11,0) -> 1799 | I57: =VLOOKUP(A57,'AP Read Performance'!A:D,4,0) -> 0.98 | J57: =VLOOKUP(A57,'AP Read Performance'!A:I,9,0) -> 29 | K57: =VLOOKUP(A57,'AP Read Performance'!A:N,14,0) -> 0.019444444 | L57: 1799 | M57: 0.98 | N57: 29 | O57: 0.019444444 | P57: 1697 | Q57: 0.98 | R57: 18 | S57: 0.016666667 | T57: 1812 | U57: 0.99 | V57: 8 | W57: 0.017361111 | X57: 1804 | Y57: 0.98 | Z57: 24 | AA57: 0.016666667 | AB57: 1825 | AC57: 0.99 | AD57: 7 | AE57: 0.015972222 | AF57: 1801 | AG57: 0.97 | AH57: 42 | AI57: 0.01875 | AJ57: 1879 | AK57: 0.97 | AL57: 51 | AM57: 0.01875 | AN57: 1824 | AO57: 0.98 | AP57: 35 | AQ57: 0.020138889 | AR57: 1798 | AS57: 0.97 | AT57: 37 | AU57: 0.019444444 | AV57: 1884 | AW57: 0.98 | AX57: 19 | AY57: 0.016666667 | AZ57: 1761 | BA57: 0.98 | BB57: 22 | BC57: 0.016666667 | BD57: 1919 | BE57: 0.97 | BF57: 43 | BG57: 0.022222222 | BH57: 1936 | BI57: 0.97 | BJ57: 44 | BK57: 0.01875 | BL57: 1988 | BM57: 0.97 | BN57: 50 | BO57: 0.01875 | BP57: 2012 | BQ57: 0.98 | BR57: 35 | BS57: 0.016666667 | BT57: 1826 | BU57: 0.98 | BV57: 21 | BW57: 0.015972222 | BX57: 2105 | BY57: 0.99 | BZ57: 17 | CA57: 0.018055556 | CB57: 2137 | CC57: 0.99 | CD57: 11 | CE57: 0.016666667 | CF57: 2101 | CG57: 0.99 | CH57: 18 | CI57: 0.016666667 | CJ57: 2066 | CK57: 0.98 | CL57: 23 | CM57: 0.016666667 | CN57: 2021 | CO57: 0.98 | CP57: 22 | CQ57: 0.01875 | CR57: =VLOOKUP(E57,Sheet1!A:A,1,0) -> #N/A
... A230: AP3322951323 | B230: Stage 2c - 2024/11/18 | C230: ULTIMA | D230: Swan Hill | E230: 00:13:50:ff:fe:71:d0:2e | F230: fd89:1e09:aa00:24a:213:50ff:fe71:d02e | G230: 4.8.6002 | H230: =VLOOKUP(A230,'AP Read Performance'!A:K,11,0) -> 239 | I230: =VLOOKUP(A230,'AP Read Performance'!A:D,4,0) -> 0.91 | J230: =VLOOKUP(A230,'AP Read Performance'!A:I,9,0) -> 20 | K230: =VLOOKUP(A230,'AP Read Performance'!A:N,14,0) -> 0.010416667 | L230: 239 | M230: 0.91 | N230: 20 | O230: 0.010416667 | P230: 242 | Q230: 0.91 | R230: 21 | S230: 0.018055556 | T230: 343 | U230: 0.97 | V230: 10 | W230: 0.0090277778 | X230: 206 | Y230: 0.96 | Z230: 7 | AA230: 0.0090277778 | AB230: 235 | AC230: 0.97 | AD230: 5 | AE230: 0.010416667 | AF230: 221 | AG230: 0.98 | AH230: 4 | AI230: 0.0090277778 | AJ230: 242 | AK230: 0.98 | AL230: 3 | AM230: 0.0090277778 | AN230: 229 | AO230: 0.99 | AP230: 2 | AQ230: 0.0090277778 | AR230: 250 | AS230: 0.96 | AT230: 9 | AU230: 0.010416667 | AV230: 297 | AW230: 0.98 | AX230: 5 | AY230: 0.0090277778 | AZ230: 258 | BA230: 0.97 | BB230: 7 | BC230: 0.0090277778 | BD230: 256 | BE230: 0.98 | BF230: 4 | BG230: 0.0083333333 | BH230: 218 | BI230: 0.98 | BJ230: 3 | BK230: 0.0097222222 | BL230: 216 | BM230: 0.98 | BN230: 3 | BO230: 0.0090277778 | BP230: 210 | BQ230: 0.99 | BR230: 1 | BS230: 0.0083333333 | BT230: 205 | BU230: 1 | BV230: 0 | BW230: 0.0090277778 | BX230: 231 | BY230: 0.98 | BZ230: 3 | CA230: 0.0090277778 | CB230: 217 | CC230: 0.98 | CD230: 4 | CE230: 0.0090277778 | CF230: 229 | CG230: 0.98 | CH230: 3 | CI230: 0.010416667 | CJ230: 205 | CK230: 0.98 | CL230: 3 | CM230: 0.0083333333 | CN230: 219 | CO230: 0.94 | CP230: 11 | CQ230: 0.011111111 | CR230: =VLOOKUP(E230,Sheet1!A:A,1,0) -> #N/A
A231: AP5222950123 | B231: Stage 2c - 2024/11/18 | C231: Barmah | D231: Echuca | E231: 00:13:50:ff:fe:71:fb:fc | F231: fd89:1e09:aa00:412:213:50ff:fe71:fbfc | G231: 5.4.6040 | H231: =VLOOKUP(A231,'AP Read Performance'!A:K,11,0) -> #N/A | I231: =VLOOKUP(A231,'AP Read Performance'!A:D,4,0) -> #N/A | J231: =VLOOKUP(A231,'AP Read Performance'!A:I,9,0) -> #N/A | K231: =VLOOKUP(A231,'AP Read Performance'!A:N,14,0) -> #N/A | L231: #N/A | M231: #N/A | N231: #N/A | O231: #N/A | P231: 173 | Q231: 1 | R231: 0 | S231: 0.0083333333 | T231: 183 | U231: 1 | V231: 0 | W231: 0.0020833333 | X231: 187 | Y231: 0.93 | Z231: 13 | AA231: 0.0097222222 | AB231: 183 | AC231: 1 | AD231: 0 | AE231: 0.0020833333 | AF231: 231 | AG231: 0.87 | AH231: 28 | AI231: 0.0090277778 | AJ231: 244 | AK231: 1 | AL231: 0 | AM231: 0.0020833333 | AN231: 183 | AO231: 1 | AP231: 0 | AQ231: 0.0076388889 | AR231: 222 | AS231: 1 | AT231: 0 | AU231: 0.0076388889 | AV231: 209 | AW231: 1 | AX231: 0 | AY231: 0.0076388889 | AZ231: 216 | BA231: 0.97 | BB231: 6 | BC231: 0.0083333333 | BD231: 211 | BE231: 0.98 | BF231: 3 | BG231: 0.0083333333 | BH231: 201 | BI231: 0.98 | BJ231: 4 | BK231: 0.0083333333 | BL231: 183 | BM231: 1 | BN231: 0 | BO231: 0.0083333333 | BP231: 180 | BQ231: 0.98 | BR231: 3 | BS231: 0.0076388889 | BT231: 170 | BU231: 0.99 | BV231: 1 | BW231: 0.0076388889 | BX231: 194 | BY231: 0.98 | BZ231: 3 | CA231: 0.0083333333 | CB231: 186 | CC231: 1 | CD231: 0 | CE231: 0.0083333333 | CF231: 205 | CG231: 0.98 | CH231: 3 | CI231: 0.0083333333 | CJ231: 195 | CK231: 0.97 | CL231: 5 | CM231: 0.0090277778 | CN231: 198 | CO231: 0.99 | CP231: 1 | CQ231: 0.0076388889 | CR231: =VLOOKUP(E231,Sheet1!A:A,1,0) -> #N/A
A232: AP3322951384 | B232: Stage 2c - 2024/11/18 | C232: Landsborough | D232: Ararat | E232: 00:13:50:ff:fe:71:d0:4d | F232: fd89:1e09:aa00:233:213:50ff:fe71:d04d | G232: 4.8.6002 | H232: =VLOOKUP(A232,'AP Read Performance'!A:K,11,0) -> 199 | I232: =VLOOKUP(A232,'AP Read Performance'!A:D,4,0) -> 0.96 | J232: =VLOOKUP(A232,'AP Read Performance'!A:I,9,0) -> 7 | K232: =VLOOKUP(A232,'AP Read Performance'!A:N,14,0) -> 0.0090277778 | L232: 199 | M232: 0.96 | N232: 7 | O232: 0.0090277778 | P232: 175 | Q232: 0.95 | R232: 8 | S232: 0.0090277778 | T232: 186 | U232: 0.95 | V232: 8 | W232: 0.0090277778 | X232: 195 | Y232: 0.98 | Z232: 3 | AA232: 0.0090277778 | AB232: 183 | AC232: 0.98 | AD232: 2 | AE232: 0.0090277778 | AF232: 148 | AG232: 0.96 | AH232: 5 | AI232: 0.0097222222 | AJ232: 248 | AK232: 0.97 | AL232: 5 | AM232: 0.0097222222 | AN232: 183 | AO232: 0.96 | AP232: 7 | AQ232: 0.0083333333 | AR232: 198 | AS232: 0.95 | AT232: 8 | AU232: 0.0090277778 | AV232: 177 | AW232: 0.97 | AX232: 4 | AY232: 0.0083333333 | AZ232: 175 | BA232: 0.97 | BB232: 5 | BC232: 0.0090277778 | BD232: 210 | BE232: 0.95 | BF232: 9 | BG232: 0.0097222222 | BH232: 144 | BI232: 0.99 | BJ232: 1 | BK232: 0.0097222222 | BL232: 189 | BM232: 0.98 | BN232: 2 | BO232: 0.0083333333 | BP232: 168 | BQ232: 0.95 | BR232: 7 | BS232: 0.0097222222 | BT232: 147 | BU232: 0.98 | BV232: 2 | BW232: 0.0090277778 | BX232: 166 | BY232: 0.92 | BZ232: 12 | CA232: 0.0090277778 | CB232: 157 | CC232: 0.98 | CD232: 3 | CE232: 0.0090277778 | CF232: 196 | CG232: 0.98 | CH232: 3 | CI232: 0.0090277778 | CJ232: 204 | CK232: 0.97 | CL232: 5 | CM232: 0.0090277778 | CN232: 220 | CO232: 0.96 | CP232: 7 | CQ232: 0.0083333333 | CR232: =VLOOKUP(E232,Sheet1!A:A,1,0) -> #N/A
A233: AP2422950075 | B233: Stage 2c - 2024/11/18 | C233: Mafeking | D233: Ararat | E233: 00:13:50:ff:fe:71:b5:37 | F233: fd89:1e09:aa00:1cc:213:50ff:fe71:b537 | G233: 4.8.6002 | H233: =VLOOKUP(A233,'AP Read Performance'!A:K,11,0) -> 255 | I233: =VLOOKUP(A233,'AP Read Performance'!A:D,4,0) -> 0.99 | J233: =VLOOKUP(A233,'AP Read Performance'!A:I,9,0) -> 2 | K233: =VLOOKUP(A233,'AP Read Performance'!A:N,14,0) -> 0.0097222222 | L233: 255 | M233: 0.99 | N233: 2 | O233: 0.0097222222 | P233: 207 | Q233: 0.99 | R233: 1 | S233: 0.0076388889 | T233: 160 | U233: 1 | V233: 0 | W233: 0.0090277778 | X233: 143 | Y233: 0.97 | Z233: 3 | AA233: 0.0027777778 | AB233: 243 | AC233: 0.98 | AD233: 3 | AE233: 0.0090277778 | AF233: 188 | AG233: 0.98 | AH233: 2 | AI233: 0.0041666667 | AJ233: 248 | AK233: 0.97 | AL233: 5 | AM233: 0.0097222222 | AN233: 249 | AO233: 0.98 | AP233: 4 | AQ233: 0.0090277778 | AR233: 245 | AS233: 0.98 | AT233: 3 | AU233: 0.0076388889 | AV233: 293 | AW233: 0.96 | AX233: 10 | AY233: 0.0076388889 | AZ233: 237 | BA233: 0.94 | BB233: 12 | BC233: 0.0090277778 | BD233: 197 | BE233: 0.95 | BF233: 9 | BG233: 0.0097222222 | BH233: 206 | BI233: 0.96 | BJ233: 7 | BK233: 0.0090277778 | BL233: 200 | BM233: 0.97 | BN233: 6 | BO233: 0.0090277778 | BP233: 218 | BQ233: 0.97 | BR233: 5 | BS233: 0.0083333333 | BT233: 210 | BU233: 0.98 | BV233: 4 | BW233: 0.0090277778 | BX233: 205 | BY233: 0.99 | BZ233: 2 | CA233: 0.0090277778 | CB233: 203 | CC233: 1 | CD233: 0 | CE233: 0.0083333333 | CF233: 246 | CG233: 0.97 | CH233: 5 | CI233: 0.0090277778 | CJ233: 227 | CK233: 0.99 | CL233: 2 | CM233: 0.0083333333 | CN233: 220 | CO233: 0.99 | CP233: 1 | CQ233: 0.0076388889 | CR233: =VLOOKUP(E233,Sheet1!A:A,1,0) -> #N/A
A234: AP5222950158 | B234: Stage 2c - 2024/11/18 | C234: Moyston | D234: Ararat | E234: 00:13:50:ff:fe:71:fc:13 | F234: fd89:1e09:aa00:404:213:50ff:fe71:fc13 | G234: 5.4.6040 | H234: =VLOOKUP(A234,'AP Read Performance'!A:K,11,0) -> 175 | I234: =VLOOKUP(A234,'AP Read Performance'!A:D,4,0) -> 0.94 | J234: =VLOOKUP(A234,'AP Read Performance'!A:I,9,0) -> 9 | K234: =VLOOKUP(A234,'AP Read Performance'!A:N,14,0) -> 0.015972222 | L234: 175 | M234: 0.94 | N234: 9 | O234: 0.015972222 | P234: 155 | Q234: 1 | R234: 0 | S234: 0.0020833333 | T234: 463 | U234: 0.99 | V234: 2 | W234: 0.0090277778 | X234: 198 | Y234: 0.97 | Z234: 4 | AA234: 0.01875 | AB234: 205 | AC234: 0.98 | AD234: 3 | AE234: 0.0097222222 | AF234: 190 | AG234: 0.97 | AH234: 5 | AI234: 0.0125 | AJ234: 251 | AK234: 0.98 | AL234: 3 | AM234: 0.0097222222 | AN234: 231 | AO234: 0.98 | AP234: 4 | AQ234: 0.011805556 | AR234: 240 | AS234: 0.98 | AT234: 4 | AU234: 0.01875 | AV234: 214 | AW234: 0.99 | AX234: 2 | AY234: 0.011111111 | AZ234: 197 | BA234: 0.98 | BB234: 2 | BC234: 0.010416667 | BD234: 252 | BE234: 0.98 | BF234: 5 | BG234: 0.0097222222 | BH234: 221 | BI234: 0.99 | BJ234: 1 | BK234: 0.0090277778 | BL234: 220 | BM234: 0.99 | BN234: 1 | BO234: 0.010416667 | BP234: 221 | BQ234: 1 | BR234: 0 | BS234: 0.0076388889 | BT234: 234 | BU234: 0.98 | BV234: 3 | BW234: 0.0090277778 | BX234: 236 | BY234: 0.98 | BZ234: 3 | CA234: 0.011111111 | CB234: 246 | CC234: 0.97 | CD234: 6 | CE234: 0.01875 | CF234: 222 | CG234: 0.99 | CH234: 2 | CI234: 0.0083333333 | CJ234: 213 | CK234: 0.99 | CL234: 1 | CM234: 0.0020833333 | CN234: 229 | CO234: 1 | CP234: 0 | CQ234: 0.0090277778 | CR234: =VLOOKUP(E234,Sheet1!A:A,1,0) -> #N/A
A235: AP3322951398 | B235: Stage 2c - 2024/11/18 | C235: PIANGIL | D235: Swan Hill | E235: 00:13:50:ff:fe:71:d0:0c | F235: fd89:1e09:aa00:25b:213:50ff:fe71:d00c | G235: 4.8.6002 | H235: =VLOOKUP(A235,'AP Read Performance'!A:K,11,0) -> 176 | I235: =VLOOKUP(A235,'AP Read Performance'!A:D,4,0) -> 0.99 | J235: =VLOOKUP(A235,'AP Read Performance'!A:I,9,0) -> 1 | K235: =VLOOKUP(A235,'AP Read Performance'!A:N,14,0) -> 0.0076388889 | L235: 176 | M235: 0.99 | N235: 1 | O235: 0.0076388889 | P235: 183 | Q235: 0.98 | R235: 3 | S235: 0.0090277778 | T235: 248 | U235: 0.99 | V235: 2 | W235: 0.0083333333 | X235: 195 | Y235: 0.98 | Z235: 2 | AA235: 0.010416667 | AB235: 254 | AC235: 0.96 | AD235: 9 | AE235: 0.0090277778 | AF235: 251 | AG235: 1 | AH235: 0 | AI235: 0.0076388889 | AJ235: 252 | AK235: 0.99 | AL235: 1 | AM235: 0.0097222222 | AN235: 217 | AO235: 0.98 | AP235: 4 | AQ235: 0.0083333333 | AR235: 184 | AS235: 1 | AT235: 0 | AU235: 0.00625 | AV235: 229 | AW235: 0.99 | AX235: 1 | AY235: 0.0076388889 | AZ235: 256 | BA235: 0.97 | BB235: 7 | BC235: 0.0090277778 | BD235: 259 | BE235: 1 | BF235: 0 | BG235: 0.0076388889 | BH235: 235 | BI235: 0.97 | BJ235: 6 | BK235: 0.0097222222 | BL235: 192 | BM235: 0.98 | BN235: 3 | BO235: 0.0090277778 | BP235: 188 | BQ235: 0.99 | BR235: 1 | BS235: 0.0090277778 | BT235: 231 | BU235: 0.99 | BV235: 1 | BW235: 0.0083333333 | BX235: 227 | BY235: 0.71 | BZ235: 65 | CA235: 0.0097222222 | CB235: 248 | CC235: 0.99 | CD235: 2 | CE235: 0.0083333333 | CF235: 225 | CG235: 0.98 | CH235: 4 | CI235: 0.0090277778 | CJ235: 232 | CK235: 0.98 | CL235: 3 | CM235: 0.0090277778 | CN235: 221 | CO235: 0.98 | CP235: 3 | CQ235: 0.0090277778 | CR235: =VLOOKUP(E235,Sheet1!A:A,1,0) -> #N/A
A236: AP5222950181 | B236: Stage 2c - 2024/11/18 | C236: IRAAK | D236: Mildura | E236: 00:13:50:ff:fe:71:fc:54 | F236: fd89:1e09:aa00:3cd:213:50ff:fe71:fc54 | G236: 5.4.6040 | H236: =VLOOKUP(A236,'AP Read Performance'!A:K,11,0) -> 182 | I236: =VLOOKUP(A236,'AP Read Performance'!A:D,4,0) -> 0.55 | J236: =VLOOKUP(A236,'AP Read Performance'!A:I,9,0) -> 81 | K236: =VLOOKUP(A236,'AP Read Performance'!A:N,14,0) -> 0.0097222222 | L236: 182 | M236: 0.55 | N236: 81 | O236: 0.0097222222 | P236: 213 | Q236: 0.95 | R236: 9 | S236: 0.0090277778 | T236: 383 | U236: 0.99 | V236: 3 | W236: 0.013194444 | X236: 275 | Y236: 0.98 | Z236: 4 | AA236: 0.019444444 | AB236: 279 | AC236: 0.98 | AD236: 4 | AE236: 0.013194444 | AF236: 234 | AG236: 0.97 | AH236: 5 | AI236: 0.0097222222 | AJ236: 261 | AK236: 0.98 | AL236: 4 | AM236: 0.0090277778 | AN236: 188 | AO236: 0.98 | AP236: 2 | AQ236: 0.0076388889 | AR236: 380 | AS236: 0.99 | AT236: 2 | AU236: 0.010416667 | AV236: 291 | AW236: 0.98 | AX236: 5 | AY236: 0.0090277778 | AZ236: 313 | BA236: 0.91 | BB236: 26 | BC236: 0.011805556 | BD236: 277 | BE236: 0.98 | BF236: 3 | BG236: 0.0125 | BH236: 212 | BI236: 0.95 | BJ236: 10 | BK236: 0.0125 | BL236: 239 | BM236: 0.95 | BN236: 10 | BO236: 0.0090277778 | BP236: 772 | BQ236: 0.85 | BR236: 115 | BS236: 0.020138889 | BT236: 251 | BU236: 0.99 | BV236: 1 | BW236: 0.011111111 | BX236: 202 | BY236: 0.98 | BZ236: 4 | CA236: 0.0090277778 | CB236: 211 | CC236: 1 | CD236: 0 | CE236: 0.0076388889 | CF236: 232 | CG236: 0.98 | CH236: 3 | CI236: 0.0090277778 | CJ236: 242 | CK236: 0.99 | CL236: 2 | CM236: 0.0090277778 | CN236: 246 | CO236: 0.98 | CP236: 4 | CQ236: 0.0090277778 | CR236: =VLOOKUP(E236,Sheet1!A:A,1,0) -> #N/A
