Workbook

Sheet UE Full List (534)
A1: Device_Util_ID | B1: Premise_Util_Id | C1: Service Point | D1: MAC Address | E1: NIC Serial Number | F1: Tariff_Id | G1: Admin Status | H1: Operational Status | I1: Meter Subtype | J1: Device_SW_Ver_No | K1: Device_Mfg_Date | L1: NIC_SW_Ver_No | M1: NIC_SW_Rev_No | N1: NIC_SW_Patch_No | O1: Meter_Program_ID | P1: Address1 | Q1: CITY | R1: Install_Date | S1: POST CODE | T1: GPS_Longitude | U1: GPS_Latitude | V1: COMPLETED | W1: STAGE
A2: 5010948 | B2: 6408266116 | C2: 40778056 | D2: 00:13:50:05:ff:02:93:e2 | E2: 00135005FF0293E2 | F2: 00L6aC3V02 | G2: Active | H2: Active | I2: L+G IEC U3350 3PH CT CONN LC | J2: S00237-05.05.R50 | K2: 44890 | L2: 5 | M2: 4 | N2: 33 | O2: 24306 | P2: 269-271 CANTERBURY RD | Q2: FOREST HILL | R2: 45001 | S2: 3175 | T2: 145.16873 | U2: -37.834151 | V2: =VLOOKUP(A:A,'BVT (50)'!A:A,1,0) -> #N/A
A3: 5010953 | B3: 6407524265 | C3: 40654591 | D3: 00:13:50:05:ff:02:93:e3 | E3: 00135005FF0293E3 | F3: 00L6aC3V02 | G3: Active | H3: Active | I3: L+G IEC U3350 3PH CT CONN LC | J3: S00237-05.05.R50 | K3: 44890 | L3: 5 | M3: 4 | N3: 33 | O3: 24306 | P3: 103 DANDENONG-HASTINGS RD | Q3: SOMERVILLE | R3: 44918 | S3: 3175 | T3: 145.22032 | U3: -38.220039 | V3: =VLOOKUP(A:A,'BVT (50)'!A:A,1,0) -> #N/A
A4: 5010967 | B4: U317731748 | C4: U317731748 | D4: 00:13:50:05:ff:02:93:e4 | E4: 00135005FF0293E4 | F4: 00L6aC3V02 | G4: Active | H4: Active | I4: L+G IEC U3350 3PH CT CONN LC | J4: S00237-05.05.R50 | K4: 44890 | L4: 5 | M4: 4 | N4: 33 | O4: 24306 | P4: 979 NEPEAN HIGHWAY | Q4: MOORABBIN | R4: 0 | S4: 3170 | T4: 145.03621 | U4: -37.933533 | V4: =VLOOKUP(A:A,'BVT (50)'!A:A,1,0) -> #N/A
A5: 5010961 | B5: 6408463012 | C5: 41062362 | D5: 00:13:50:05:ff:02:93:e5 | E5: 00135005FF0293E5 | F5: 00L6aC3V02 | G5: Active | H5: Active | I5: L+G IEC U3350 3PH CT CONN LC | J5: S00237-05.05.R50 | K5: 44890 | L5: 5 | M5: 4 | N5: 33 | O5: 24306 | P5: 510N NEPEAN HWY | Q5: FRANKSTON | R5: 44944 | S5: 3107 | T5: 145.11874 | U5: -38.145863 | V5: =VLOOKUP(A:A,'BVT (50)'!A:A,1,0) -> #N/A
A6: 5010956 | B6: 6407574131 | C6: 40448006 | D6: 00:13:50:05:ff:02:93:f8 | E6: 00135005FF0293F8 | F6: 00L6aC4V02 | G6: Active | H6: Active | I6: L+G IEC U3350 3PH CT CONN LC | J6: S00237-05.05.R50 | K6: 44890 | L6: 5 | M6: 4 | N6: 33 | O6: 24310 | P6: 259 JONES RD | Q6: SOMERVILLE | R6: 44963 | S6: 3175 | T6: 145.17429 | U6: -38.230969 | V6: =VLOOKUP(A:A,'BVT (50)'!A:A,1,0) -> 5010956 | W6: BVT
A7: 5010950 | B7: 6407686363 | C7: 40632241 | D7: 00:13:50:05:ff:02:93:fb | E7: 00135005FF0293FB | F7: 00L6aC4V02 | G7: Active | H7: Active | I7: L+G IEC U3350 3PH CT CONN LC | J7: S00237-05.05.R50 | K7: 44890 | L7: 5 | M7: 4 | N7: 33 | O7: 24310 | P7: RESV RESV 120 Leila Rd 120 LEILA RD | Q7: CARNEGIE | R7: 44951 | S7: 3175 | T7: 145.05845 | U7: -37.902053 | V7: =VLOOKUP(A:A,'BVT (50)'!A:A,1,0) -> 5010950 | W7: BVT
A8: 5010927 | B8: U317109522 | C8: U317109522 | D8: 00:13:50:05:ff:02:93:fd | E8: 00135005FF0293FD | F8: 00L6aC3V02 | G8: Active | H8: Active | I8: L+G IEC U3350 3PH CT CONN LC | J8: S00237-05.05.R50 | K8: 44890 | L8: 5 | M8: 4 | N8: 33 | O8: 24306 | P8: 4 FREIGHTER ROAD | Q8: MOORABBIN | R8: 0 | S8: 0 | T8: 145.07566 | U8: -37.948591 | V8: =VLOOKUP(A:A,'BVT (50)'!A:A,1,0) -> #N/A
A9: 5010936 | B9: 6408441384 | C9: 41041205 | D9: 00:13:50:05:ff:02:94:0b | E9: 00135005FF02940B | F9: 00L6aC4V02 | G9: Active | H9: Active | I9: L+G IEC U3350 3PH CT CONN LC | J9: S00237-05.05.R50 | K9: 44890 | L9: 5 | M9: 4 | N9: 33 | O9: 24310 | P9: 5 BEAUMARIS PDE | Q9: HIGHETT | R9: 45000 | S9: 3190 | T9: 145.03458 | U9: -37.954363 | V9: =VLOOKUP(A:A,'BVT (50)'!A:A,1,0) -> 5010936 | W9: BVT
A10: 5010949 | B10: 6408479113 | C10: 41076913 | D10: 00:13:50:05:ff:02:94:28 | E10: 00135005FF029428 | F10: 00L6aC3V02 | G10: Active | H10: Active | I10: L+G IEC U3350 3PH CT CONN LC | J10: S00237-05.05.R50 | K10: 44890 | L10: 5 | M10: 4 | N10: 33 | O10: 24306 | P10: 358 HAMPTON ST | Q10: HAMPTON | R10: 45119 | S10: 3175 | T10: 145.00239 | U10: -37.940344 | V10: =VLOOKUP(A:A,'BVT (50)'!A:A,1,0) -> #N/A
A11: 5010941 | B11: 6408456028 | C11: 41056251 | D11: 00:13:50:05:ff:02:94:38 | E11: 00135005FF029438 | F11: 00L6aC3V02 | G11: Active | H11: Active | I11: L+G IEC U3350 3PH CT CONN LC | J11: S00237-05.05.R50 | K11: 44890 | L11: 5 | M11: 4 | N11: 33 | O11: 24306 | P11: 35-45 BEND RD | Q11: KEYSBOROUGH | R11: 44963 | S11: 3190 | T11: 145.18621 | U11: -38.002785 | V11: =VLOOKUP(A:A,'BVT (50)'!A:A,1,0) -> #N/A
A12: 5010973 | B12: 6407818698 | C12: 40675957 | D12: 00:13:50:05:ff:02:94:39 | E12: 00135005FF029439 | F12: 00L6aC3V02 | G12: Active | H12: Active | I12: L+G IEC U3350 3PH CT CONN LC | J12: S00237-05.05.R50 | K12: 44890 | L12: 5 | M12: 4 | N12: 33 | O12: 24306 | P12: 9 DANDENONG ST | Q12: DANDENONG | R12: 44964 | S12: 3170 | T12: 145.20032 | U12: -37.991276 | V12: =VLOOKUP(A:A,'BVT (50)'!A:A,1,0) -> #N/A
A13: 5010931 | B13: 6408476691 | C13: 41075915 | D13: 00:13:50:05:ff:02:94:3a | E13: 00135005FF02943A | F13: 00L6aC3V02 | G13: Active | H13: Active | I13: L+G IEC U3350 3PH CT CONN LC | J13: S00237-05.05.R50 | K13: 44890 | L13: 5 | M13: 4 | N13: 33 | O13: 24306 | P13: 113 HIGH ST | Q13: DONCASTER | R13: 45270 | S13: 0 | T13: 145.11188 | U13: -37.780259 | V13: =VLOOKUP(A:A,'BVT (50)'!A:A,1,0) -> #N/A
A14: 5010975 | B14: 6408460776 | C14: 41061812 | D14: 00:13:50:05:ff:02:94:3d | E14: 00135005FF02943D | F14: 00L6aC3V02 | G14: Active | H14: Active | I14: L+G IEC U3350 3PH CT CONN LC | J14: S00237-05.05.R50 | K14: 44890 | L14: 5 | M14: 4 | N14: 33 | O14: 24306 | P14: 48 MARLBOROUGH ST | Q14: BALACLAVA | R14: 44974 | S14: 3170 | T14: 144.99289 | U14: -37.869201 | V14: =VLOOKUP(A:A,'BVT (50)'!A:A,1,0) -> #N/A
A15: 5010958 | B15: 6407604478 | C15: 41066582 | D15: 00:13:50:05:ff:02:94:43 | E15: 00135005FF029443 | F15: 00L6aC4V02 | G15: Active | H15: Active | I15: L+G IEC U3350 3PH CT CONN LC | J15: S00237-05.05.R50 | K15: 44890 | L15: 5 | M15: 4 | N15: 33 | O15: 24310 | P15: 306 JETTY RD | Q15: ROSEBUD | R15: 44973 | S15: 3175 | T15: 144.91024 | U15: -38.379971 | V15: =VLOOKUP(A:A,'BVT (50)'!A:A,1,0) -> 5010958 | W15: BVT
A16: 5010947 | B16: 6408443112 | C16: 41040489 | D16: 00:13:50:05:ff:02:94:4a | E16: 00135005FF02944A | F16: 00L6aC3V02 | G16: Active | H16: Active | I16: L+G IEC U3350 3PH CT CONN LC | J16: S00237-05.05.R50 | K16: 44890 | L16: 5 | M16: 4 | N16: 33 | O16: 24306 | P16: 5 IBIS CCT | Q16: DANDENONG SOUTH | R16: 45124 | S16: 3175 | T16: 145.22548 | U16: -38.047133 | V16: =VLOOKUP(A:A,'BVT (50)'!A:A,1,0) -> #N/A
A17: 5010940 | B17: 6408467185 | C17: 41066645 | D17: 00:13:50:05:ff:02:94:4d | E17: 00135005FF02944D | F17: 00L6aC3V02 | G17: Active | H17: Active | I17: L+G IEC U3350 3PH CT CONN LC | J17: S00237-05.05.R50 | K17: 44890 | L17: 5 | M17: 4 | N17: 33 | O17: 24306 | P17: 165 STUD RD | Q17: DANDENONG NORTH | R17: 45020 | S17: 3190 | T17: 145.223 | U17: -37.970812 | V17: =VLOOKUP(A:A,'BVT (50)'!A:A,1,0) -> #N/A
A18: 5010962 | B18: U317690104 | C18: U317690104 | D18: 00:13:50:05:ff:02:94:61 | E18: 00135005FF029461 | F18: 00L6aC3V02 | G18: Active | H18: Active | I18: L+G IEC U3350 3PH CT CONN LC | J18: S00237-05.05.R50 | K18: 44890 | L18: 5 | M18: 4 | N18: 33 | O18: 24306 | P18: 970 NEPEAN HIGHWAY | Q18: MOORABBIN | R18: 0 | S18: 3107 | T18: 145.03783 | U18: -37.939223 | V18: =VLOOKUP(A:A,'BVT (50)'!A:A,1,0) -> #N/A
A19: 5010972 | B19: 6407650778 | C19: 40678672 | D19: 00:13:50:05:ff:02:94:66 | E19: 00135005FF029466 | F19: 00L6aC3V02 | G19: Active | H19: Active | I19: L+G IEC U3350 3PH CT CONN LC | J19: S00237-05.05.R50 | K19: 44890 | L19: 5 | M19: 4 | N19: 33 | O19: 24306 | P19: 8 JELLICO DR | Q19: SCORESBY | R19: 44953 | S19: 3170 | T19: 145.21895 | U19: -37.898653 | V19: =VLOOKUP(A:A,'BVT (50)'!A:A,1,0) -> #N/A
A20: 5010959 | B20: 6408280169 | C20: 40790819 | D20: 00:13:50:05:ff:02:94:67 | E20: 00135005FF029467 | F20: 00L6aC3V02 | G20: Active | H20: Active | I20: L+G IEC U3350 3PH CT CONN LC | J20: S00237-05.05.R50 | K20: 44890 | L20: 5 | M20: 4 | N20: 33 | O20: 24306 | P20: 808-814 HEATHERTON RD | Q20: SPRINGVALE SOUTH | R20: 44945 | S20: 3172 | T20: 145.1448 | U20: -37.961666 | V20: =VLOOKUP(A:A,'BVT (50)'!A:A,1,0) -> #N/A
A21: 5010968 | B21: 6408461039 | C21: 41061630 | D21: 00:13:50:05:ff:02:94:6b | E21: 00135005FF02946B | F21: 00L6aC3V02 | G21: Active | H21: Active | I21: L+G IEC U3350 3PH CT CONN LC | J21: S00237-05.05.R50 | K21: 44890 | L21: 5 | M21: 4 | N21: 33 | O21: 24306 | P21: 1239 NEPEAN HWY | Q21: CHELTENHAM | R21: 44951 | S21: 3170 | T21: 145.055 | U21: -37.957931 | V21: =VLOOKUP(A:A,'BVT (50)'!A:A,1,0) -> #N/A
A22: 5010957 | B22: 6408314304 | C22: 40813705 | D22: 00:13:50:05:ff:02:94:76 | E22: 00135005FF029476 | F22: 00L6aC3V02 | G22: Active | H22: Active | I22: L+G IEC U3350 3PH CT CONN LC | J22: S00237-05.05.R50 | K22: 44890 | L22: 5 | M22: 4 | N22: 33 | O22: 24306 | P22: 90 WALLACES RD | Q22: DROMANA | R22: 44957 | S22: 3175 | T22: 145.02346 | U22: -38.322957 | V22: =VLOOKUP(A:A,'BVT (50)'!A:A,1,0) -> #N/A
A23: 5010926 | B23: 6408470533 | C23: 41072732 | D23: 00:13:50:05:ff:02:94:77 | E23: 00135005FF029477 | F23: 00L6aC3V02 | G23: Active | H23: Active | I23: L+G IEC U3350 3PH CT CONN LC | J23: S00237-05.05.R50 | K23: 44890 | L23: 5 | M23: 4 | N23: 33 | O23: 24306 | P23: 185 MANNINGHAM RD | Q23: TEMPLESTOWE LOWER | R23: 45270 | S23: #N/A | T23: 145.10035 | U23: -37.770961 | V23: =VLOOKUP(A:A,'BVT (50)'!A:A,1,0) -> #N/A
A24: 5010969 | B24: 6407171344 | C24: 40672558 | D24: 00:13:50:05:ff:02:94:7b | E24: 00135005FF02947B | F24: 00L6aC3V02 | G24: Active | H24: Active | I24: L+G IEC U3350 3PH CT CONN LC | J24: S00237-05.05.R50 | K24: 44890 | L24: 5 | M24: 4 | N24: 33 | O24: 24306 | P24: 10 WESLEY CT | Q24: BURWOOD EAST | R24: 44963 | S24: 3170 | T24: 145.16609 | U24: -37.857486 | V24: =VLOOKUP(A:A,'BVT (50)'!A:A,1,0) -> #N/A
A25: 5010945 | B25: 6407651513 | C25: 40670962 | D25: 00:13:50:05:ff:02:94:81 | E25: 00135005FF029481 | F25: 00L6aC3V02 | G25: Active | H25: Active | I25: L+G IEC U3350 3PH CT CONN LC | J25: S00237-05.05.R50 | K25: 44890 | L25: 5 | M25: 4 | N25: 33 | O25: 24306 | P25: SHOP 11 HARBOUR PLAZA 21 THOMPSON RD | Q25: PATTERSON LAKES | R25: 44945 | S25: 3190 | T25: 145.14276 | U25: -38.068189 | V25: =VLOOKUP(A:A,'BVT (50)'!A:A,1,0) -> #N/A
A26: 5010963 | B26: 6408065508 | C26: 40406676 | D26: 00:13:50:05:ff:02:94:86 | E26: 00135005FF029486 | F26: 00L6aC4V02 | G26: Active | H26: Active | I26: L+G IEC U3350 3PH CT CONN LC | J26: S00237-05.05.R50 | K26: 44890 | L26: 5 | M26: 4 | N26: 33 | O26: 24310 | P26: 140 GARNETT RD | Q26: WHEELERS HILL | R26: 44991 | S26: 3107 | T26: 145.2003 | U26: -37.920276 | V26: =VLOOKUP(A:A,'Pilot (10)'!A:A,1,0) -> 5010963 | W26: PILOT
A27: 5010933 | B27: 6407387774 | C27: 41066118 | D27: 00:13:50:05:ff:02:94:88 | E27: 00135005FF029488 | F27: 00L6aC3V02 | G27: Active | H27: Active | I27: L+G IEC U3350 3PH CT CONN LC | J27: S00237-05.05.R50 | K27: 44890 | L27: 5 | M27: 4 | N27: 33 | O27: 24306 | P27: 16 DISSIK ST | Q27: CHELTENHAM | R27: 44949 | S27: 0 | T27: 145.07162 | U27: -37.952736 | V27: =VLOOKUP(A:A,'BVT (50)'!A:A,1,0) -> #N/A
A28: 5010952 | B28: 6407136308 | C28: 40732908 | D28: 00:13:50:05:ff:02:94:89 | E28: 00135005FF029489 | F28: 00L6aC4V02 | G28: Active | H28: Active | I28: L+G IEC U3350 3PH CT CONN LC | J28: S00237-05.05.R50 | K28: 44890 | L28: 5 | M28: 4 | N28: 33 | O28: 24310 | P28: 12-14 VARMAN CT | Q28: NUNAWADING | R28: 44965 | S28: 3175 | T28: 145.17238 | U28: -37.819949 | V28: =VLOOKUP(A:A,'BVT (50)'!A:A,1,0) -> 5010952 | W28: BVT
A29: 5010938 | B29: VEEE0WBATL | C29: 41123370 | D29: 00:13:50:05:ff:02:94:8a | E29: 00135005FF02948A | F29: C0ML0F3001 | G29: Active | H29: Active | I29: L+G IEC U3350 3PH CT CONN LC | J29: S00237-05.05.R50 | K29: 44890 | L29: 5 | M29: 4 | N29: 33 | O29: 28300 | P29: 13-17 Manning Drive | Q29: Noble Park | R29: 45898 | S29: 3190 | T29: 0 | U29: 0 | V29: =VLOOKUP(A:A,'BVT (50)'!A:A,1,0) -> #N/A
A30: 5010934 | B30: 6407285664 | C30: 40549882 | D30: 00:13:50:05:ff:02:94:a7 | E30: 00135005FF0294A7 | F30: 00L6aC3V02 | G30: Active | H30: Active | I30: L+G IEC U3350 3PH CT CONN LC | J30: S00237-05.05.R50 | K30: 44890 | L30: 5 | M30: 4 | N30: 33 | O30: 24306 | P30: 175 CHAPEL ST | Q30: ST KILDA | R30: 44999 | S30: 0 | T30: 144.9897 | U30: -37.870691 | V30: =VLOOKUP(A:A,'BVT (50)'!A:A,1,0) -> #N/A
A31: 5010960 | B31: VEEE02EEU0 | C31: 40676472 | D31: 00:13:50:05:ff:02:94:af | E31: 00135005FF0294AF | F31: 00L6aC3V02 | G31: Active | H31: Active | I31: L+G IEC U3350 3PH CT CONN LC | J31: S00237-05.05.R50 | K31: 44890 | L31: 5 | M31: 4 | N31: 33 | O31: 24306 | P31: 6 BROOKLYN AVE | Q31: DANDENONG | R31: 44937 | S31: 3107 | T31: 145.19739 | U31: -37.992931 | V31: =VLOOKUP(A:A,'BVT (50)'!A:A,1,0) -> #N/A
A32: 5010966 | B32: U317739235 | C32: U317739235 | D32: 00:13:50:05:ff:02:94:be | E32: 00135005FF0294BE | F32: 00L6aC3V02 | G32: Active | H32: Active | I32: L+G IEC U3350 3PH CT CONN LC | J32: S00237-05.05.R50 | K32: 44890 | L32: 5 | M32: 4 | N32: 33 | O32: 24306 | P32: 1 FEDERATION WAY | Q32: MOORABBIN AIRPORT | R32: 0 | S32: 0 | T32: 145.10169 | U32: -37.972387 | V32: =VLOOKUP(A:A,'BVT (50)'!A:A,1,0) -> #N/A
A33: 5010932 | B33: 6408460836 | C33: 41061924 | D33: 00:13:50:05:ff:02:94:c5 | E33: 00135005FF0294C5 | F33: 00L6aC3V02 | G33: Active | H33: Active | I33: L+G IEC U3350 3PH CT CONN LC | J33: S00237-05.05.R50 | K33: 44890 | L33: 5 | M33: 4 | N33: 33 | O33: 24306 | P33: 35-45 BEND RD | Q33: KEYSBOROUGH | R33: 44963 | S33: 0 | T33: 145.18473 | U33: -38.001825 | V33: =VLOOKUP(A:A,'BVT (50)'!A:A,1,0) -> #N/A
A34: 5010935 | B34: 6407512054 | C34: 40787158 | D34: 00:13:50:05:ff:02:94:c7 | E34: 00135005FF0294C7 | F34: 00L6aC3V02 | G34: Active | H34: Active | I34: L+G IEC U3350 3PH CT CONN LC | J34: S00237-05.05.R50 | K34: 44890 | L34: 5 | M34: 4 | N34: 33 | O34: 24902 | P34: Blue Dolphin on Bayside 382-384 NEPEAN HWY | Q34: FRANKSTON | R34: 44981 | S34: 0 | T34: 145.12339 | U34: -38.136696 | V34: =VLOOKUP(A:A,'BVT (50)'!A:A,1,0) -> #N/A
A35: 5010943 | B35: 6408463137 | C35: 41062632 | D35: 00:13:50:05:ff:02:94:c9 | E35: 00135005FF0294C9 | F35: 00L6aC4V02 | G35: Active | H35: Active | I35: L+G IEC U3350 3PH CT CONN LC | J35: S00237-05.05.R50 | K35: 44890 | L35: 5 | M35: 4 | N35: 33 | O35: 24310 | P35: 45 SEYMOUR RD | Q35: ELSTERNWICK | R35: 44944 | S35: 3190 | T35: 145.01066 | U35: -37.880433 | V35: =VLOOKUP(A:A,'BVT (50)'!A:A,1,0) -> 5010943 | W35: BVT
A36: 5010946 | B36: 6407476920 | C36: 40624837 | D36: 00:13:50:05:ff:02:94:ce | E36: 00135005FF0294CE | F36: 00L6aC3V02 | G36: Active | H36: Active | I36: L+G IEC U3350 3PH CT CONN LC | J36: S00237-05.05.R50 | K36: 44890 | L36: 5 | M36: 4 | N36: 33 | O36: 24306 | P36: 6-10 NANTILLA RD | Q36: CLAYTON | R36: 45124 | S36: 3190 | T36: 145.15086 | U36: -37.910726 | V36: =VLOOKUP(A:A,'BVT (50)'!A:A,1,0) -> #N/A
A37: 5010929 | B37: 6407621452 | C37: 40850049 | D37: 00:13:50:05:ff:02:94:de | E37: 00135005FF0294DE | F37: 00L6aC4V02 | G37: Active | H37: Active | I37: L+G IEC U3350 3PH CT CONN LC | J37: S00237-05.05.R50 | K37: 44890 | L37: 5 | M37: 4 | N37: 33 | O37: 24310 | P37: F 1 46 DANDENONG ST | Q37: DANDENONG | R37: 45428 | S37: 0 | T37: 145.19907 | U37: -37.995161 | V37: =VLOOKUP(A:A,'BVT (50)'!A:A,1,0) -> 5010929 | W37: BVT
A38: 5010971 | B38: 6407818242 | C38: 40545525 | D38: 00:13:50:05:ff:02:94:df | E38: 00135005FF0294DF | F38: 00L6aC4V02 | G38: Active | H38: Active | I38: L+G IEC U3350 3PH CT CONN LC | J38: S00237-05.05.R50 | K38: 44890 | L38: 5 | M38: 4 | N38: 33 | O38: 24310 | P38: 97R ROBINSONS RD | Q38: FRANKSTON | R38: 44957 | S38: 3170 | T38: 145.15825 | U38: -38.17553 | V38: =VLOOKUP(A:A,'BVT (50)'!A:A,1,0) -> 5010971 | W38: BVT
A39: 5010954 | B39: 6407387968 | C39: 40682630 | D39: 00:13:50:05:ff:02:94:f6 | E39: 00135005FF0294F6 | F39: 00L6aC3V02 | G39: Active | H39: Active | I39: L+G IEC U3350 3PH CT CONN LC | J39: S00237-05.05.R50 | K39: 44890 | L39: 5 | M39: 4 | N39: 33 | O39: 24306 | P39: 8 LEVANSWELL RD | Q39: MOORABBIN | R39: 44918 | S39: 3175 | T39: 145.06145 | U39: -37.944431 | V39: =VLOOKUP(A:A,'BVT (50)'!A:A,1,0) -> #N/A
A40: 5010944 | B40: VEEE0WMAB3 | C40: 41119926 | D40: 00:13:50:05:ff:02:94:fd | E40: 00135005FF0294FD | F40: C0ML0F3001 | G40: Active | H40: Active | I40: L+G IEC U3350 3PH CT CONN LC | J40: S00237-05.05.R50 | K40: 44890 | L40: 5 | M40: 4 | N40: 33 | O40: 28300 | P40: 21-31 Malcolm Road | Q40: Braeside | R40: 45826 | S40: 3190 | T40: 0 | U40: 0 | V40: =VLOOKUP(A:A,'BVT (50)'!A:A,1,0) -> #N/A
...

Sheet Pilot (10)
J1: Pre Upgrade | O1: Post Upgrade
A2: Device_Util_ID | B2: Stage | C2: MAC Address | D2: Meter Subtype | E2: Device_Status | F2: Device_Operational_Status | G2: NIC_SW_Ver_No | H2: NIC_SW_Rev_No | I2: NIC_SW_Patch_No | J2: Device_SW_Ver_No | K2: Meter_Program_ID | L2: Meter_Form_Type | M2: Tariff_Id | N2: Pre Upgrade Interval reads | O2: Device_SW_Ver_No | P2: Meter_Program_ID | Q2: Meter_Form_Type | R2: Tariff_Id | S2: Post Upgrade Interval reads
A3: 5010963 | B3: Pilot - 15/04/2026 | C3: =VLOOKUP(A:A,'UE Full List (534)'!A:D,4,0) -> 00:13:50:05:ff:02:94:86 | D3: =VLOOKUP(A:A,'UE Full List (534)'!A:I,9,0) -> L+G IEC U3350 3PH CT CONN LC | E3: =VLOOKUP(A:A,'UE Full List (534)'!A:G,7,0) -> Active | F3: =VLOOKUP(A:A,'UE Full List (534)'!A:H,8,0) -> Active | G3: =VLOOKUP(A:A,'UE Full List (534)'!A:L,12,0) -> 5 | H3: =VLOOKUP(A:A,'UE Full List (534)'!A:M,13,0) -> 4 | I3: =VLOOKUP(A:A,'UE Full List (534)'!A:N,14,0) -> 33 | J3: =VLOOKUP(A:A,'UE Full List (534)'!A:J,10,0) -> S00237-05.05.R50 | K3: =VLOOKUP(A:A,'UE Full List (534)'!A:O,15,0) -> 24310 | L3: =D3 -> L+G IEC U3350 3PH CT CONN LC | M3: =VLOOKUP(A:A,'UE Full List (534)'!A:F,6,0) -> 00L6aC4V02 | N3: Successful | O3: 6.2.R62 | P3: 24310 | Q3: L+G IEC U3350 3PH CT CONN LC | R3: 00L6aC4V02 | S3: Successful
A4: 5014273 | B4: Pilot - 15/04/2026 | C4: =VLOOKUP(A:A,'UE Full List (534)'!A:D,4,0) -> 00:13:50:05:ff:4d:a9:55 | D4: =VLOOKUP(A:A,'UE Full List (534)'!A:I,9,0) -> L+G IEC U3350 3PH CT CONN LC | E4: =VLOOKUP(A:A,'UE Full List (534)'!A:G,7,0) -> Active | F4: =VLOOKUP(A:A,'UE Full List (534)'!A:H,8,0) -> Active | G4: =VLOOKUP(A:A,'UE Full List (534)'!A:L,12,0) -> 5 | H4: =VLOOKUP(A:A,'UE Full List (534)'!A:M,13,0) -> 4 | I4: =VLOOKUP(A:A,'UE Full List (534)'!A:N,14,0) -> 33 | J4: =VLOOKUP(A:A,'UE Full List (534)'!A:J,10,0) -> S00237-05.05.R50 | K4: =VLOOKUP(A:A,'UE Full List (534)'!A:O,15,0) -> 24306 | L4: =D4 -> L+G IEC U3350 3PH CT CONN LC | M4: =VLOOKUP(A:A,'UE Full List (534)'!A:F,6,0) -> 00L6aC3V02 | N4: Successful | O4: 6.2.R62 | P4: 24306 | Q4: L+G IEC U3350 3PH CT CONN LC | R4: 00L6aC3V02 | S4: Successful
A5: 5014284 | B5: Pilot - 15/04/2026 | C5: =VLOOKUP(A:A,'UE Full List (534)'!A:D,4,0) -> 00:13:50:05:ff:4d:a9:b7 | D5: =VLOOKUP(A:A,'UE Full List (534)'!A:I,9,0) -> L+G IEC U3350 3PH CT CONN LC | E5: =VLOOKUP(A:A,'UE Full List (534)'!A:G,7,0) -> Active | F5: =VLOOKUP(A:A,'UE Full List (534)'!A:H,8,0) -> Active | G5: =VLOOKUP(A:A,'UE Full List (534)'!A:L,12,0) -> 5 | H5: =VLOOKUP(A:A,'UE Full List (534)'!A:M,13,0) -> 4 | I5: =VLOOKUP(A:A,'UE Full List (534)'!A:N,14,0) -> 33 | J5: =VLOOKUP(A:A,'UE Full List (534)'!A:J,10,0) -> S00237-05.05.R50 | K5: =VLOOKUP(A:A,'UE Full List (534)'!A:O,15,0) -> 24306 | L5: =D5 -> L+G IEC U3350 3PH CT CONN LC | M5: =VLOOKUP(A:A,'UE Full List (534)'!A:F,6,0) -> 00L6aC3V02 | N5: Successful | O5: 6.2.R62 | P5: 24306 | Q5: L+G IEC U3350 3PH CT CONN LC | R5: 00L6aC3V02 | S5: Successful
A6: 5014281 | B6: Pilot - 15/04/2026 | C6: =VLOOKUP(A:A,'UE Full List (534)'!A:D,4,0) -> 00:13:50:05:ff:4d:aa:8f | D6: =VLOOKUP(A:A,'UE Full List (534)'!A:I,9,0) -> L+G IEC U3350 3PH CT CONN LC | E6: =VLOOKUP(A:A,'UE Full List (534)'!A:G,7,0) -> Active | F6: =VLOOKUP(A:A,'UE Full List (534)'!A:H,8,0) -> Active | G6: =VLOOKUP(A:A,'UE Full List (534)'!A:L,12,0) -> 5 | H6: =VLOOKUP(A:A,'UE Full List (534)'!A:M,13,0) -> 4 | I6: =VLOOKUP(A:A,'UE Full List (534)'!A:N,14,0) -> 33 | J6: =VLOOKUP(A:A,'UE Full List (534)'!A:J,10,0) -> S00237-05.05.R50 | K6: =VLOOKUP(A:A,'UE Full List (534)'!A:O,15,0) -> 24306 | L6: =D6 -> L+G IEC U3350 3PH CT CONN LC | M6: =VLOOKUP(A:A,'UE Full List (534)'!A:F,6,0) -> 00L6aC3V02 | N6: Successful | O6: 6.2.R62 | P6: 24306 | Q6: L+G IEC U3350 3PH CT CONN LC | R6: 00L6aC3V02 | S6: Successful
A7: 5014271 | B7: Pilot - 15/04/2026 | C7: =VLOOKUP(A:A,'UE Full List (534)'!A:D,4,0) -> 00:13:50:05:ff:4d:aa:9d | D7: =VLOOKUP(A:A,'UE Full List (534)'!A:I,9,0) -> L+G IEC U3350 3PH CT CONN LC | E7: =VLOOKUP(A:A,'UE Full List (534)'!A:G,7,0) -> Active | F7: =VLOOKUP(A:A,'UE Full List (534)'!A:H,8,0) -> Active | G7: =VLOOKUP(A:A,'UE Full List (534)'!A:L,12,0) -> 5 | H7: =VLOOKUP(A:A,'UE Full List (534)'!A:M,13,0) -> 4 | I7: =VLOOKUP(A:A,'UE Full List (534)'!A:N,14,0) -> 33 | J7: =VLOOKUP(A:A,'UE Full List (534)'!A:J,10,0) -> S00237-05.05.R50 | K7: =VLOOKUP(A:A,'UE Full List (534)'!A:O,15,0) -> 24310 | L7: =D7 -> L+G IEC U3350 3PH CT CONN LC | M7: =VLOOKUP(A:A,'UE Full List (534)'!A:F,6,0) -> 00L6aC4V02 | N7: Successful | O7: 6.2.R62 | P7: 24310 | Q7: L+G IEC U3350 3PH CT CONN LC | R7: 00L6aC4V02 | S7: Successful
A8: 5014254 | B8: Pilot - 15/04/2026 | C8: =VLOOKUP(A:A,'UE Full List (534)'!A:D,4,0) -> 00:13:50:05:ff:4d:ab:78 | D8: =VLOOKUP(A:A,'UE Full List (534)'!A:I,9,0) -> L+G IEC U3350 3PH CT CONN LC | E8: =VLOOKUP(A:A,'UE Full List (534)'!A:G,7,0) -> Active | F8: =VLOOKUP(A:A,'UE Full List (534)'!A:H,8,0) -> Active | G8: =VLOOKUP(A:A,'UE Full List (534)'!A:L,12,0) -> 5 | H8: =VLOOKUP(A:A,'UE Full List (534)'!A:M,13,0) -> 4 | I8: =VLOOKUP(A:A,'UE Full List (534)'!A:N,14,0) -> 33 | J8: =VLOOKUP(A:A,'UE Full List (534)'!A:J,10,0) -> S00237-05.05.R50 | K8: =VLOOKUP(A:A,'UE Full List (534)'!A:O,15,0) -> 24306 | L8: =D8 -> L+G IEC U3350 3PH CT CONN LC | M8: =VLOOKUP(A:A,'UE Full List (534)'!A:F,6,0) -> 00L6aC3V02 | N8: Successful | O8: 6.2.R62 | P8: 24306 | Q8: L+G IEC U3350 3PH CT CONN LC | R8: 00L6aC3V02 | S8: Successful
A9: 5014280 | B9: Pilot - 15/04/2026 | C9: =VLOOKUP(A:A,'UE Full List (534)'!A:D,4,0) -> 00:13:50:05:ff:4d:ab:ef | D9: =VLOOKUP(A:A,'UE Full List (534)'!A:I,9,0) -> L+G IEC U3350 3PH CT CONN LC | E9: =VLOOKUP(A:A,'UE Full List (534)'!A:G,7,0) -> Active | F9: =VLOOKUP(A:A,'UE Full List (534)'!A:H,8,0) -> Active | G9: =VLOOKUP(A:A,'UE Full List (534)'!A:L,12,0) -> 5 | H9: =VLOOKUP(A:A,'UE Full List (534)'!A:M,13,0) -> 4 | I9: =VLOOKUP(A:A,'UE Full List (534)'!A:N,14,0) -> 33 | J9: =VLOOKUP(A:A,'UE Full List (534)'!A:J,10,0) -> S00237-05.05.R50 | K9: =VLOOKUP(A:A,'UE Full List (534)'!A:O,15,0) -> 24306 | L9: =D9 -> L+G IEC U3350 3PH CT CONN LC | M9: =VLOOKUP(A:A,'UE Full List (534)'!A:F,6,0) -> 00L6aC3V02 | N9: Successful | O9: 6.2.R62 | P9: 24306 | Q9: L+G IEC U3350 3PH CT CONN LC | R9: 00L6aC3V02 | S9: Successful
A10: 5014415 | B10: Pilot - 15/04/2026 | C10: =VLOOKUP(A:A,'UE Full List (534)'!A:D,4,0) -> 00:13:50:05:ff:4d:ac:2f | D10: =VLOOKUP(A:A,'UE Full List (534)'!A:I,9,0) -> L+G IEC U3350 3PH CT CONN LC | E10: =VLOOKUP(A:A,'UE Full List (534)'!A:G,7,0) -> Active | F10: =VLOOKUP(A:A,'UE Full List (534)'!A:H,8,0) -> Active | G10: =VLOOKUP(A:A,'UE Full List (534)'!A:L,12,0) -> 5 | H10: =VLOOKUP(A:A,'UE Full List (534)'!A:M,13,0) -> 4 | I10: =VLOOKUP(A:A,'UE Full List (534)'!A:N,14,0) -> 33 | J10: =VLOOKUP(A:A,'UE Full List (534)'!A:J,10,0) -> S00237-05.05.R50 | K10: =VLOOKUP(A:A,'UE Full List (534)'!A:O,15,0) -> 24306 | L10: =D10 -> L+G IEC U3350 3PH CT CONN LC | M10: =VLOOKUP(A:A,'UE Full List (534)'!A:F,6,0) -> 00L6aC3V02 | N10: Successful | O10: 6.2.R62 | P10: 24306 | Q10: L+G IEC U3350 3PH CT CONN LC | R10: 00L6aC3V02 | S10: Successful
A11: 5014288 | B11: Pilot - 15/04/2026 | C11: =VLOOKUP(A:A,'UE Full List (534)'!A:D,4,0) -> 00:13:50:05:ff:4d:ac:94 | D11: =VLOOKUP(A:A,'UE Full List (534)'!A:I,9,0) -> L+G IEC U3350 3PH CT CONN LC | E11: =VLOOKUP(A:A,'UE Full List (534)'!A:G,7,0) -> Active | F11: =VLOOKUP(A:A,'UE Full List (534)'!A:H,8,0) -> Active | G11: =VLOOKUP(A:A,'UE Full List (534)'!A:L,12,0) -> 5 | H11: =VLOOKUP(A:A,'UE Full List (534)'!A:M,13,0) -> 4 | I11: =VLOOKUP(A:A,'UE Full List (534)'!A:N,14,0) -> 33 | J11: =VLOOKUP(A:A,'UE Full List (534)'!A:J,10,0) -> S00237-05.05.R50 | K11: =VLOOKUP(A:A,'UE Full List (534)'!A:O,15,0) -> 24310 | L11: =D11 -> L+G IEC U3350 3PH CT CONN LC | M11: =VLOOKUP(A:A,'UE Full List (534)'!A:F,6,0) -> 00L6aC4V02 | N11: Successful | O11: 6.2.R62 | P11: 24310 | Q11: L+G IEC U3350 3PH CT CONN LC | R11: 00L6aC4V02 | S11: Successful
A12: 5023552 | B12: Pilot - 15/04/2026 | C12: =VLOOKUP(A:A,'UE Full List (534)'!A:D,4,0) -> 00:13:50:05:ff:50:cb:f1 | D12: =VLOOKUP(A:A,'UE Full List (534)'!A:I,9,0) -> L+G IEC U3350 3PH CT CONN LC | E12: =VLOOKUP(A:A,'UE Full List (534)'!A:G,7,0) -> Active | F12: =VLOOKUP(A:A,'UE Full List (534)'!A:H,8,0) -> Active | G12: =VLOOKUP(A:A,'UE Full List (534)'!A:L,12,0) -> 5 | H12: =VLOOKUP(A:A,'UE Full List (534)'!A:M,13,0) -> 4 | I12: =VLOOKUP(A:A,'UE Full List (534)'!A:N,14,0) -> 33 | J12: =VLOOKUP(A:A,'UE Full List (534)'!A:J,10,0) -> S00237-05.05.R50 | K12: =VLOOKUP(A:A,'UE Full List (534)'!A:O,15,0) -> 26203 | L12: =D12 -> L+G IEC U3350 3PH CT CONN LC | M12: =VLOOKUP(A:A,'UE Full List (534)'!A:F,6,0) -> 00L6aC3V03 | N12: Successful | O12: 6.2.R62 | P12: 26203 | Q12: L+G IEC U3350 3PH CT CONN LC | R12: 00L6aC3V03 | S12: Successful

Sheet Pilot Project Meter events
A1: 5010963
A15: 5014273
A47: 5014284
A97: 5014281
A124: 5014271
A165: 5014254
A180: 5014280
A225: 5014415
A250: 5014288
A295: 5023552

Sheet BVT (50)
J1: Pre Upgrade | O1: Post Upgrade
A2: Device_Util_ID | B2: Stage | C2: MAC Address | D2: Meter Subtype | E2: Device_Status | F2: Device_Operational_Status | G2: NIC_SW_Ver_No | H2: NIC_SW_Rev_No | I2: NIC_SW_Patch_No | J2: Device_SW_Ver_No | K2: Meter_Program_ID | L2: Meter_Form_Type | M2: Tariff_Id | N2: Pre Upgrade Interval reads | O2: Device_SW_Ver_No | P2: Meter_Program_ID | Q2: Meter_Form_Type | R2: Tariff_Id | S2: Post Upgrade Interval reads
A3: 5010956 | B3: BVT - 20/04/2026 | C3: =VLOOKUP(A:A,'UE Full List (534)'!A:D,4,0) -> 00:13:50:05:ff:02:93:f8 | D3: =VLOOKUP(A:A,'UE Full List (534)'!A:I,9,0) -> L+G IEC U3350 3PH CT CONN LC | E3: =VLOOKUP(A:A,'UE Full List (534)'!A:G,7,0) -> Active | F3: =VLOOKUP(A:A,'UE Full List (534)'!A:H,8,0) -> Active | G3: =VLOOKUP(A:A,'UE Full List (534)'!A:L,12,0) -> 5 | H3: =VLOOKUP(A:A,'UE Full List (534)'!A:M,13,0) -> 4 | I3: =VLOOKUP(A:A,'UE Full List (534)'!A:N,14,0) -> 33 | J3: =VLOOKUP(A:A,'UE Full List (534)'!A:J,10,0) -> S00237-05.05.R50 | K3: =VLOOKUP(A:A,'UE Full List (534)'!A:O,15,0) -> 24310 | L3: =D3 -> L+G IEC U3350 3PH CT CONN LC | M3: =VLOOKUP(A:A,'UE Full List (534)'!A:F,6,0) -> 00L6aC4V02
A4: 5010950 | B4: BVT - 20/04/2026 | C4: =VLOOKUP(A:A,'UE Full List (534)'!A:D,4,0) -> 00:13:50:05:ff:02:93:fb | D4: =VLOOKUP(A:A,'UE Full List (534)'!A:I,9,0) -> L+G IEC U3350 3PH CT CONN LC | E4: =VLOOKUP(A:A,'UE Full List (534)'!A:G,7,0) -> Active | F4: =VLOOKUP(A:A,'UE Full List (534)'!A:H,8,0) -> Active | G4: =VLOOKUP(A:A,'UE Full List (534)'!A:L,12,0) -> 5 | H4: =VLOOKUP(A:A,'UE Full List (534)'!A:M,13,0) -> 4 | I4: =VLOOKUP(A:A,'UE Full List (534)'!A:N,14,0) -> 33 | J4: =VLOOKUP(A:A,'UE Full List (534)'!A:J,10,0) -> S00237-05.05.R50 | K4: =VLOOKUP(A:A,'UE Full List (534)'!A:O,15,0) -> 24310 | L4: =D4 -> L+G IEC U3350 3PH CT CONN LC | M4: =VLOOKUP(A:A,'UE Full List (534)'!A:F,6,0) -> 00L6aC4V02
A5: 5010936 | B5: BVT - 20/04/2026 | C5: =VLOOKUP(A:A,'UE Full List (534)'!A:D,4,0) -> 00:13:50:05:ff:02:94:0b | D5: =VLOOKUP(A:A,'UE Full List (534)'!A:I,9,0) -> L+G IEC U3350 3PH CT CONN LC | E5: =VLOOKUP(A:A,'UE Full List (534)'!A:G,7,0) -> Active | F5: =VLOOKUP(A:A,'UE Full List (534)'!A:H,8,0) -> Active | G5: =VLOOKUP(A:A,'UE Full List (534)'!A:L,12,0) -> 5 | H5: =VLOOKUP(A:A,'UE Full List (534)'!A:M,13,0) -> 4 | I5: =VLOOKUP(A:A,'UE Full List (534)'!A:N,14,0) -> 33 | J5: =VLOOKUP(A:A,'UE Full List (534)'!A:J,10,0) -> S00237-05.05.R50 | K5: =VLOOKUP(A:A,'UE Full List (534)'!A:O,15,0) -> 24310 | L5: =D5 -> L+G IEC U3350 3PH CT CONN LC | M5: =VLOOKUP(A:A,'UE Full List (534)'!A:F,6,0) -> 00L6aC4V02
A6: 5010958 | B6: BVT - 20/04/2026 | C6: =VLOOKUP(A:A,'UE Full List (534)'!A:D,4,0) -> 00:13:50:05:ff:02:94:43 | D6: =VLOOKUP(A:A,'UE Full List (534)'!A:I,9,0) -> L+G IEC U3350 3PH CT CONN LC | E6: =VLOOKUP(A:A,'UE Full List (534)'!A:G,7,0) -> Active | F6: =VLOOKUP(A:A,'UE Full List (534)'!A:H,8,0) -> Active | G6: =VLOOKUP(A:A,'UE Full List (534)'!A:L,12,0) -> 5 | H6: =VLOOKUP(A:A,'UE Full List (534)'!A:M,13,0) -> 4 | I6: =VLOOKUP(A:A,'UE Full List (534)'!A:N,14,0) -> 33 | J6: =VLOOKUP(A:A,'UE Full List (534)'!A:J,10,0) -> S00237-05.05.R50 | K6: =VLOOKUP(A:A,'UE Full List (534)'!A:O,15,0) -> 24310 | L6: =D6 -> L+G IEC U3350 3PH CT CONN LC | M6: =VLOOKUP(A:A,'UE Full List (534)'!A:F,6,0) -> 00L6aC4V02
A7: 5010952 | B7: BVT - 20/04/2026 | C7: =VLOOKUP(A:A,'UE Full List (534)'!A:D,4,0) -> 00:13:50:05:ff:02:94:89 | D7: =VLOOKUP(A:A,'UE Full List (534)'!A:I,9,0) -> L+G IEC U3350 3PH CT CONN LC | E7: =VLOOKUP(A:A,'UE Full List (534)'!A:G,7,0) -> Active | F7: =VLOOKUP(A:A,'UE Full List (534)'!A:H,8,0) -> Active | G7: =VLOOKUP(A:A,'UE Full List (534)'!A:L,12,0) -> 5 | H7: =VLOOKUP(A:A,'UE Full List (534)'!A:M,13,0) -> 4 | I7: =VLOOKUP(A:A,'UE Full List (534)'!A:N,14,0) -> 33 | J7: =VLOOKUP(A:A,'UE Full List (534)'!A:J,10,0) -> S00237-05.05.R50 | K7: =VLOOKUP(A:A,'UE Full List (534)'!A:O,15,0) -> 24310 | L7: =D7 -> L+G IEC U3350 3PH CT CONN LC | M7: =VLOOKUP(A:A,'UE Full List (534)'!A:F,6,0) -> 00L6aC4V02
A8: 5010943 | B8: BVT - 20/04/2026 | C8: =VLOOKUP(A:A,'UE Full List (534)'!A:D,4,0) -> 00:13:50:05:ff:02:94:c9 | D8: =VLOOKUP(A:A,'UE Full List (534)'!A:I,9,0) -> L+G IEC U3350 3PH CT CONN LC | E8: =VLOOKUP(A:A,'UE Full List (534)'!A:G,7,0) -> Active | F8: =VLOOKUP(A:A,'UE Full List (534)'!A:H,8,0) -> Active | G8: =VLOOKUP(A:A,'UE Full List (534)'!A:L,12,0) -> 5 | H8: =VLOOKUP(A:A,'UE Full List (534)'!A:M,13,0) -> 4 | I8: =VLOOKUP(A:A,'UE Full List (534)'!A:N,14,0) -> 33 | J8: =VLOOKUP(A:A,'UE Full List (534)'!A:J,10,0) -> S00237-05.05.R50 | K8: =VLOOKUP(A:A,'UE Full List (534)'!A:O,15,0) -> 24310 | L8: =D8 -> L+G IEC U3350 3PH CT CONN LC | M8: =VLOOKUP(A:A,'UE Full List (534)'!A:F,6,0) -> 00L6aC4V02
A9: 5010929 | B9: BVT - 20/04/2026 | C9: =VLOOKUP(A:A,'UE Full List (534)'!A:D,4,0) -> 00:13:50:05:ff:02:94:de | D9: =VLOOKUP(A:A,'UE Full List (534)'!A:I,9,0) -> L+G IEC U3350 3PH CT CONN LC | E9: =VLOOKUP(A:A,'UE Full List (534)'!A:G,7,0) -> Active | F9: =VLOOKUP(A:A,'UE Full List (534)'!A:H,8,0) -> Active | G9: =VLOOKUP(A:A,'UE Full List (534)'!A:L,12,0) -> 5 | H9: =VLOOKUP(A:A,'UE Full List (534)'!A:M,13,0) -> 4 | I9: =VLOOKUP(A:A,'UE Full List (534)'!A:N,14,0) -> 33 | J9: =VLOOKUP(A:A,'UE Full List (534)'!A:J,10,0) -> S00237-05.05.R50 | K9: =VLOOKUP(A:A,'UE Full List (534)'!A:O,15,0) -> 24310 | L9: =D9 -> L+G IEC U3350 3PH CT CONN LC | M9: =VLOOKUP(A:A,'UE Full List (534)'!A:F,6,0) -> 00L6aC4V02
A10: 5010971 | B10: BVT - 20/04/2026 | C10: =VLOOKUP(A:A,'UE Full List (534)'!A:D,4,0) -> 00:13:50:05:ff:02:94:df | D10: =VLOOKUP(A:A,'UE Full List (534)'!A:I,9,0) -> L+G IEC U3350 3PH CT CONN LC | E10: =VLOOKUP(A:A,'UE Full List (534)'!A:G,7,0) -> Active | F10: =VLOOKUP(A:A,'UE Full List (534)'!A:H,8,0) -> Active | G10: =VLOOKUP(A:A,'UE Full List (534)'!A:L,12,0) -> 5 | H10: =VLOOKUP(A:A,'UE Full List (534)'!A:M,13,0) -> 4 | I10: =VLOOKUP(A:A,'UE Full List (534)'!A:N,14,0) -> 33 | J10: =VLOOKUP(A:A,'UE Full List (534)'!A:J,10,0) -> S00237-05.05.R50 | K10: =VLOOKUP(A:A,'UE Full List (534)'!A:O,15,0) -> 24310 | L10: =D10 -> L+G IEC U3350 3PH CT CONN LC | M10: =VLOOKUP(A:A,'UE Full List (534)'!A:F,6,0) -> 00L6aC4V02
A11: 5010974 | B11: BVT - 20/04/2026 | C11: =VLOOKUP(A:A,'UE Full List (534)'!A:D,4,0) -> 00:13:50:05:ff:02:95:23 | D11: =VLOOKUP(A:A,'UE Full List (534)'!A:I,9,0) -> L+G IEC U3350 3PH CT CONN LC | E11: =VLOOKUP(A:A,'UE Full List (534)'!A:G,7,0) -> Active | F11: =VLOOKUP(A:A,'UE Full List (534)'!A:H,8,0) -> Active | G11: =VLOOKUP(A:A,'UE Full List (534)'!A:L,12,0) -> 5 | H11: =VLOOKUP(A:A,'UE Full List (534)'!A:M,13,0) -> 4 | I11: =VLOOKUP(A:A,'UE Full List (534)'!A:N,14,0) -> 33 | J11: =VLOOKUP(A:A,'UE Full List (534)'!A:J,10,0) -> S00237-05.05.R50 | K11: =VLOOKUP(A:A,'UE Full List (534)'!A:O,15,0) -> 24310 | L11: =D11 -> L+G IEC U3350 3PH CT CONN LC | M11: =VLOOKUP(A:A,'UE Full List (534)'!A:F,6,0) -> 00L6aC4V02
A12: 5010441 | B12: BVT - 20/04/2026 | C12: =VLOOKUP(A:A,'UE Full List (534)'!A:D,4,0) -> 00:13:50:05:ff:36:1a:9b | D12: =VLOOKUP(A:A,'UE Full List (534)'!A:I,9,0) -> L+G IEC U3350 3PH CT CONN LC | E12: =VLOOKUP(A:A,'UE Full List (534)'!A:G,7,0) -> Active | F12: =VLOOKUP(A:A,'UE Full List (534)'!A:H,8,0) -> Active | G12: =VLOOKUP(A:A,'UE Full List (534)'!A:L,12,0) -> 5 | H12: =VLOOKUP(A:A,'UE Full List (534)'!A:M,13,0) -> 4 | I12: =VLOOKUP(A:A,'UE Full List (534)'!A:N,14,0) -> 33 | J12: =VLOOKUP(A:A,'UE Full List (534)'!A:J,10,0) -> S00237-05.05.R50 | K12: =VLOOKUP(A:A,'UE Full List (534)'!A:O,15,0) -> 24310 | L12: =D12 -> L+G IEC U3350 3PH CT CONN LC | M12: =VLOOKUP(A:A,'UE Full List (534)'!A:F,6,0) -> 00L6aC4V02
A13: 5014386 | B13: BVT - 20/04/2026 | C13: =VLOOKUP(A:A,'UE Full List (534)'!A:D,4,0) -> 00:13:50:05:ff:4d:a9:1a | D13: =VLOOKUP(A:A,'UE Full List (534)'!A:I,9,0) -> L+G IEC U3350 3PH CT CONN LC | E13: =VLOOKUP(A:A,'UE Full List (534)'!A:G,7,0) -> Active | F13: =VLOOKUP(A:A,'UE Full List (534)'!A:H,8,0) -> Active | G13: =VLOOKUP(A:A,'UE Full List (534)'!A:L,12,0) -> 5 | H13: =VLOOKUP(A:A,'UE Full List (534)'!A:M,13,0) -> 4 | I13: =VLOOKUP(A:A,'UE Full List (534)'!A:N,14,0) -> 33 | J13: =VLOOKUP(A:A,'UE Full List (534)'!A:J,10,0) -> S00237-05.05.R50 | K13: =VLOOKUP(A:A,'UE Full List (534)'!A:O,15,0) -> 24310 | L13: =D13 -> L+G IEC U3350 3PH CT CONN LC | M13: =VLOOKUP(A:A,'UE Full List (534)'!A:F,6,0) -> 00L6aC4V02
A14: 5014504 | B14: BVT - 20/04/2026 | C14: =VLOOKUP(A:A,'UE Full List (534)'!A:D,4,0) -> 00:13:50:05:ff:4d:a9:56 | D14: =VLOOKUP(A:A,'UE Full List (534)'!A:I,9,0) -> L+G IEC U3350 3PH CT CONN LC | E14: =VLOOKUP(A:A,'UE Full List (534)'!A:G,7,0) -> Active | F14: =VLOOKUP(A:A,'UE Full List (534)'!A:H,8,0) -> Active | G14: =VLOOKUP(A:A,'UE Full List (534)'!A:L,12,0) -> 5 | H14: =VLOOKUP(A:A,'UE Full List (534)'!A:M,13,0) -> 4 | I14: =VLOOKUP(A:A,'UE Full List (534)'!A:N,14,0) -> 33 | J14: =VLOOKUP(A:A,'UE Full List (534)'!A:J,10,0) -> S00237-05.05.R50 | K14: =VLOOKUP(A:A,'UE Full List (534)'!A:O,15,0) -> 24310 | L14: =D14 -> L+G IEC U3350 3PH CT CONN LC | M14: =VLOOKUP(A:A,'UE Full List (534)'!A:F,6,0) -> 00L6aC4V02
... A25: 5014503 | B25: BVT - 20/04/2026 | C25: =VLOOKUP(A:A,'UE Full List (534)'!A:D,4,0) -> 00:13:50:05:ff:4d:ab:22 | D25: =VLOOKUP(A:A,'UE Full List (534)'!A:I,9,0) -> L+G IEC U3350 3PH CT CONN LC | E25: =VLOOKUP(A:A,'UE Full List (534)'!A:G,7,0) -> Active | F25: =VLOOKUP(A:A,'UE Full List (534)'!A:H,8,0) -> Active | G25: =VLOOKUP(A:A,'UE Full List (534)'!A:L,12,0) -> 5 | H25: =VLOOKUP(A:A,'UE Full List (534)'!A:M,13,0) -> 4 | I25: =VLOOKUP(A:A,'UE Full List (534)'!A:N,14,0) -> 33 | J25: =VLOOKUP(A:A,'UE Full List (534)'!A:J,10,0) -> S00237-05.05.R50 | K25: =VLOOKUP(A:A,'UE Full List (534)'!A:O,15,0) -> 24310 | L25: =D25 -> L+G IEC U3350 3PH CT CONN LC | M25: =VLOOKUP(A:A,'UE Full List (534)'!A:F,6,0) -> 00L6aC4V02
A26: 5014524 | B26: BVT - 20/04/2026 | C26: 00:13:50:05:ff:4d:ac:05 | D26: L+G IEC U3350 3PH CT CONN LC | E26: Active | F26: Active | G26: 5 | H26: 4 | I26: 33 | J26: S00237-05.05.R50 | K26: 24306 | L26: =D26 -> L+G IEC U3350 3PH CT CONN LC | M26: 00L6aC3V02
A27: 5014195 | B27: BVT - 20/04/2026 | C27: =VLOOKUP(A:A,'UE Full List (534)'!A:D,4,0) -> 00:13:50:05:ff:4d:ab:25 | D27: =VLOOKUP(A:A,'UE Full List (534)'!A:I,9,0) -> L+G IEC U3350 3PH CT CONN LC | E27: =VLOOKUP(A:A,'UE Full List (534)'!A:G,7,0) -> Active | F27: =VLOOKUP(A:A,'UE Full List (534)'!A:H,8,0) -> Active | G27: =VLOOKUP(A:A,'UE Full List (534)'!A:L,12,0) -> 5 | H27: =VLOOKUP(A:A,'UE Full List (534)'!A:M,13,0) -> 4 | I27: =VLOOKUP(A:A,'UE Full List (534)'!A:N,14,0) -> 33 | J27: =VLOOKUP(A:A,'UE Full List (534)'!A:J,10,0) -> S00237-05.05.R50 | K27: =VLOOKUP(A:A,'UE Full List (534)'!A:O,15,0) -> 24310 | L27: =D27 -> L+G IEC U3350 3PH CT CONN LC | M27: =VLOOKUP(A:A,'UE Full List (534)'!A:F,6,0) -> 00L6aC4V02
A28: 5014240 | B28: BVT - 20/04/2026 | C28: =VLOOKUP(A:A,'UE Full List (534)'!A:D,4,0) -> 00:13:50:05:ff:4d:ab:32 | D28: =VLOOKUP(A:A,'UE Full List (534)'!A:I,9,0) -> L+G IEC U3350 3PH CT CONN LC | E28: =VLOOKUP(A:A,'UE Full List (534)'!A:G,7,0) -> Active | F28: =VLOOKUP(A:A,'UE Full List (534)'!A:H,8,0) -> Active | G28: =VLOOKUP(A:A,'UE Full List (534)'!A:L,12,0) -> 5 | H28: =VLOOKUP(A:A,'UE Full List (534)'!A:M,13,0) -> 4 | I28: =VLOOKUP(A:A,'UE Full List (534)'!A:N,14,0) -> 33 | J28: =VLOOKUP(A:A,'UE Full List (534)'!A:J,10,0) -> S00237-05.05.R50 | K28: =VLOOKUP(A:A,'UE Full List (534)'!A:O,15,0) -> 24310 | L28: =D28 -> L+G IEC U3350 3PH CT CONN LC | M28: =VLOOKUP(A:A,'UE Full List (534)'!A:F,6,0) -> 00L6aC4V02
A29: 5014232 | B29: BVT - 20/04/2026 | C29: =VLOOKUP(A:A,'UE Full List (534)'!A:D,4,0) -> 00:13:50:05:ff:4d:ab:48 | D29: =VLOOKUP(A:A,'UE Full List (534)'!A:I,9,0) -> L+G IEC U3350 3PH CT CONN LC | E29: =VLOOKUP(A:A,'UE Full List (534)'!A:G,7,0) -> Active | F29: =VLOOKUP(A:A,'UE Full List (534)'!A:H,8,0) -> Active | G29: =VLOOKUP(A:A,'UE Full List (534)'!A:L,12,0) -> 5 | H29: =VLOOKUP(A:A,'UE Full List (534)'!A:M,13,0) -> 4 | I29: =VLOOKUP(A:A,'UE Full List (534)'!A:N,14,0) -> 33 | J29: =VLOOKUP(A:A,'UE Full List (534)'!A:J,10,0) -> S00237-05.05.R50 | K29: =VLOOKUP(A:A,'UE Full List (534)'!A:O,15,0) -> 24310 | L29: =D29 -> L+G IEC U3350 3PH CT CONN LC | M29: =VLOOKUP(A:A,'UE Full List (534)'!A:F,6,0) -> 00L6aC4V02
A30: 5014201 | B30: BVT - 20/04/2026 | C30: =VLOOKUP(A:A,'UE Full List (534)'!A:D,4,0) -> 00:13:50:05:ff:4d:ab:4d | D30: =VLOOKUP(A:A,'UE Full List (534)'!A:I,9,0) -> L+G IEC U3350 3PH CT CONN LC | E30: =VLOOKUP(A:A,'UE Full List (534)'!A:G,7,0) -> Active | F30: =VLOOKUP(A:A,'UE Full List (534)'!A:H,8,0) -> Active | G30: =VLOOKUP(A:A,'UE Full List (534)'!A:L,12,0) -> 5 | H30: =VLOOKUP(A:A,'UE Full List (534)'!A:M,13,0) -> 4 | I30: =VLOOKUP(A:A,'UE Full List (534)'!A:N,14,0) -> 33 | J30: =VLOOKUP(A:A,'UE Full List (534)'!A:J,10,0) -> S00237-05.05.R50 | K30: =VLOOKUP(A:A,'UE Full List (534)'!A:O,15,0) -> 24310 | L30: =D30 -> L+G IEC U3350 3PH CT CONN LC | M30: =VLOOKUP(A:A,'UE Full List (534)'!A:F,6,0) -> 00L6aC4V02
A31: 5014182 | B31: BVT - 20/04/2026 | C31: =VLOOKUP(A:A,'UE Full List (534)'!A:D,4,0) -> 00:13:50:05:ff:4d:ab:6e | D31: =VLOOKUP(A:A,'UE Full List (534)'!A:I,9,0) -> L+G IEC U3350 3PH CT CONN LC | E31: =VLOOKUP(A:A,'UE Full List (534)'!A:G,7,0) -> Active | F31: =VLOOKUP(A:A,'UE Full List (534)'!A:H,8,0) -> Active | G31: =VLOOKUP(A:A,'UE Full List (534)'!A:L,12,0) -> 5 | H31: =VLOOKUP(A:A,'UE Full List (534)'!A:M,13,0) -> 4 | I31: =VLOOKUP(A:A,'UE Full List (534)'!A:N,14,0) -> 33 | J31: =VLOOKUP(A:A,'UE Full List (534)'!A:J,10,0) -> S00237-05.05.R50 | K31: =VLOOKUP(A:A,'UE Full List (534)'!A:O,15,0) -> 24310 | L31: =D31 -> L+G IEC U3350 3PH CT CONN LC | M31: =VLOOKUP(A:A,'UE Full List (534)'!A:F,6,0) -> 00L6aC4V02
A32: 5014238 | B32: BVT - 20/04/2026 | C32: =VLOOKUP(A:A,'UE Full List (534)'!A:D,4,0) -> 00:13:50:05:ff:4d:ab:6f | D32: =VLOOKUP(A:A,'UE Full List (534)'!A:I,9,0) -> L+G IEC U3350 3PH CT CONN LC | E32: =VLOOKUP(A:A,'UE Full List (534)'!A:G,7,0) -> Active | F32: =VLOOKUP(A:A,'UE Full List (534)'!A:H,8,0) -> Active | G32: =VLOOKUP(A:A,'UE Full List (534)'!A:L,12,0) -> 5 | H32: =VLOOKUP(A:A,'UE Full List (534)'!A:M,13,0) -> 4 | I32: =VLOOKUP(A:A,'UE Full List (534)'!A:N,14,0) -> 33 | J32: =VLOOKUP(A:A,'UE Full List (534)'!A:J,10,0) -> S00237-05.05.R50 | K32: =VLOOKUP(A:A,'UE Full List (534)'!A:O,15,0) -> 24310 | L32: =D32 -> L+G IEC U3350 3PH CT CONN LC | M32: =VLOOKUP(A:A,'UE Full List (534)'!A:F,6,0) -> 00L6aC4V02
A33: 5014244 | B33: BVT - 20/04/2026 | C33: =VLOOKUP(A:A,'UE Full List (534)'!A:D,4,0) -> 00:13:50:05:ff:4d:ac:5b | D33: =VLOOKUP(A:A,'UE Full List (534)'!A:I,9,0) -> L+G IEC U3350 3PH CT CONN LC | E33: =VLOOKUP(A:A,'UE Full List (534)'!A:G,7,0) -> Active | F33: =VLOOKUP(A:A,'UE Full List (534)'!A:H,8,0) -> Active | G33: =VLOOKUP(A:A,'UE Full List (534)'!A:L,12,0) -> 5 | H33: =VLOOKUP(A:A,'UE Full List (534)'!A:M,13,0) -> 4 | I33: =VLOOKUP(A:A,'UE Full List (534)'!A:N,14,0) -> 33 | J33: =VLOOKUP(A:A,'UE Full List (534)'!A:J,10,0) -> S00237-05.05.R50 | K33: =VLOOKUP(A:A,'UE Full List (534)'!A:O,15,0) -> 25500 | L33: =D33 -> L+G IEC U3350 3PH CT CONN LC | M33: =VLOOKUP(A:A,'UE Full List (534)'!A:F,6,0) -> 00L6aC4V03
A34: 5023567 | B34: BVT - 20/04/2026 | C34: =VLOOKUP(A:A,'UE Full List (534)'!A:D,4,0) -> 00:13:50:05:ff:50:cb:d0 | D34: =VLOOKUP(A:A,'UE Full List (534)'!A:I,9,0) -> L+G IEC U3350 3PH CT CONN LC | E34: =VLOOKUP(A:A,'UE Full List (534)'!A:G,7,0) -> Active | F34: =VLOOKUP(A:A,'UE Full List (534)'!A:H,8,0) -> Active | G34: =VLOOKUP(A:A,'UE Full List (534)'!A:L,12,0) -> 5 | H34: =VLOOKUP(A:A,'UE Full List (534)'!A:M,13,0) -> 4 | I34: =VLOOKUP(A:A,'UE Full List (534)'!A:N,14,0) -> 33 | J34: =VLOOKUP(A:A,'UE Full List (534)'!A:J,10,0) -> S00237-05.05.R50 | K34: =VLOOKUP(A:A,'UE Full List (534)'!A:O,15,0) -> 25500 | L34: =D34 -> L+G IEC U3350 3PH CT CONN LC | M34: =VLOOKUP(A:A,'UE Full List (534)'!A:F,6,0) -> 00L6aC4V03
A35: 5023530 | B35: BVT - 20/04/2026 | C35: =VLOOKUP(A:A,'UE Full List (534)'!A:D,4,0) -> 00:13:50:05:ff:50:cb:d4 | D35: =VLOOKUP(A:A,'UE Full List (534)'!A:I,9,0) -> L+G IEC U3350 3PH CT CONN LC | E35: =VLOOKUP(A:A,'UE Full List (534)'!A:G,7,0) -> Active | F35: =VLOOKUP(A:A,'UE Full List (534)'!A:H,8,0) -> Active | G35: =VLOOKUP(A:A,'UE Full List (534)'!A:L,12,0) -> 5 | H35: =VLOOKUP(A:A,'UE Full List (534)'!A:M,13,0) -> 4 | I35: =VLOOKUP(A:A,'UE Full List (534)'!A:N,14,0) -> 33 | J35: =VLOOKUP(A:A,'UE Full List (534)'!A:J,10,0) -> S00237-05.05.R50 | K35: =VLOOKUP(A:A,'UE Full List (534)'!A:O,15,0) -> 25500 | L35: =D35 -> L+G IEC U3350 3PH CT CONN LC | M35: =VLOOKUP(A:A,'UE Full List (534)'!A:F,6,0) -> 00L6aC4V03
A36: 5023577 | B36: BVT - 20/04/2026 | C36: =VLOOKUP(A:A,'UE Full List (534)'!A:D,4,0) -> 00:13:50:05:ff:50:cb:d8 | D36: =VLOOKUP(A:A,'UE Full List (534)'!A:I,9,0) -> L+G IEC U3350 3PH CT CONN LC | E36: =VLOOKUP(A:A,'UE Full List (534)'!A:G,7,0) -> Active | F36: =VLOOKUP(A:A,'UE Full List (534)'!A:H,8,0) -> Active | G36: =VLOOKUP(A:A,'UE Full List (534)'!A:L,12,0) -> 5 | H36: =VLOOKUP(A:A,'UE Full List (534)'!A:M,13,0) -> 4 | I36: =VLOOKUP(A:A,'UE Full List (534)'!A:N,14,0) -> 33 | J36: =VLOOKUP(A:A,'UE Full List (534)'!A:J,10,0) -> S00237-05.05.R50 | K36: =VLOOKUP(A:A,'UE Full List (534)'!A:O,15,0) -> 25500 | L36: =D36 -> L+G IEC U3350 3PH CT CONN LC | M36: =VLOOKUP(A:A,'UE Full List (534)'!A:F,6,0) -> 00L6aC4V03
A37: 5023514 | B37: BVT - 20/04/2026 | C37: =VLOOKUP(A:A,'UE Full List (534)'!A:D,4,0) -> 00:13:50:05:ff:50:cb:df | D37: =VLOOKUP(A:A,'UE Full List (534)'!A:I,9,0) -> L+G IEC U3350 3PH CT CONN LC | E37: =VLOOKUP(A:A,'UE Full List (534)'!A:G,7,0) -> Active | F37: =VLOOKUP(A:A,'UE Full List (534)'!A:H,8,0) -> Active | G37: =VLOOKUP(A:A,'UE Full List (534)'!A:L,12,0) -> 5 | H37: =VLOOKUP(A:A,'UE Full List (534)'!A:M,13,0) -> 4 | I37: =VLOOKUP(A:A,'UE Full List (534)'!A:N,14,0) -> 33 | J37: =VLOOKUP(A:A,'UE Full List (534)'!A:J,10,0) -> S00237-05.05.R50 | K37: =VLOOKUP(A:A,'UE Full List (534)'!A:O,15,0) -> 25500 | L37: =D37 -> L+G IEC U3350 3PH CT CONN LC | M37: =VLOOKUP(A:A,'UE Full List (534)'!A:F,6,0) -> 00L6aC4V03
A38: 5023564 | B38: BVT - 20/04/2026 | C38: =VLOOKUP(A:A,'UE Full List (534)'!A:D,4,0) -> 00:13:50:05:ff:50:cb:ea | D38: =VLOOKUP(A:A,'UE Full List (534)'!A:I,9,0) -> L+G IEC U3350 3PH CT CONN LC | E38: =VLOOKUP(A:A,'UE Full List (534)'!A:G,7,0) -> Active | F38: =VLOOKUP(A:A,'UE Full List (534)'!A:H,8,0) -> Active | G38: =VLOOKUP(A:A,'UE Full List (534)'!A:L,12,0) -> 5 | H38: =VLOOKUP(A:A,'UE Full List (534)'!A:M,13,0) -> 4 | I38: =VLOOKUP(A:A,'UE Full List (534)'!A:N,14,0) -> 33 | J38: =VLOOKUP(A:A,'UE Full List (534)'!A:J,10,0) -> S00237-05.05.R50 | K38: =VLOOKUP(A:A,'UE Full List (534)'!A:O,15,0) -> 26203 | L38: =D38 -> L+G IEC U3350 3PH CT CONN LC | M38: =VLOOKUP(A:A,'UE Full List (534)'!A:F,6,0) -> 00L6aC3V03
... A52: 5023505 | B52: BVT - 20/04/2026 | C52: =VLOOKUP(A:A,'UE Full List (534)'!A:D,4,0) -> 00:13:50:05:ff:50:cc:3e | D52: =VLOOKUP(A:A,'UE Full List (534)'!A:I,9,0) -> L+G IEC U3350 3PH CT CONN LC | E52: =VLOOKUP(A:A,'UE Full List (534)'!A:G,7,0) -> Active | F52: =VLOOKUP(A:A,'UE Full List (534)'!A:H,8,0) -> Active | G52: =VLOOKUP(A:A,'UE Full List (534)'!A:L,12,0) -> 5 | H52: =VLOOKUP(A:A,'UE Full List (534)'!A:M,13,0) -> 4 | I52: =VLOOKUP(A:A,'UE Full List (534)'!A:N,14,0) -> 33 | J52: =VLOOKUP(A:A,'UE Full List (534)'!A:J,10,0) -> S00237-05.05.R50 | K52: =VLOOKUP(A:A,'UE Full List (534)'!A:O,15,0) -> 25500 | L52: =D52 -> L+G IEC U3350 3PH CT CONN LC | M52: =VLOOKUP(A:A,'UE Full List (534)'!A:F,6,0) -> 00L6aC4V03

Sheet Stage 1 (100) 
J1: Pre Upgrade | O1: Post Upgrade
A2: Device_Util_ID | B2: Stage | C2: MAC Address | D2: Meter Subtype | E2: Device_Status | F2: Device_Operational_Status | G2: NIC_SW_Ver_No | H2: NIC_SW_Rev_No | I2: NIC_SW_Patch_No | J2: Device_SW_Ver_No | K2: Meter_Program_ID | L2: Meter_Form_Type | M2: Tariff_Id | N2: Pre Upgrade Interval reads | O2: Device_SW_Ver_No | P2: Meter_Program_ID | Q2: Meter_Form_Type | R2: Tariff_Id | S2: Post Upgrade Interval reads

Sheet Stage 2 (500)
J1: Pre Upgrade | O1: Post Upgrade
A2: Device_Util_ID | B2: Stage | C2: MAC Address | D2: Meter Subtype | E2: Device_Status | F2: Device_Operational_Status | G2: NIC_SW_Ver_No | H2: NIC_SW_Rev_No | I2: NIC_SW_Patch_No | J2: Device_SW_Ver_No | K2: Meter_Program_ID | L2: Meter_Form_Type | M2: Tariff_Id | N2: Pre Upgrade Interval reads | O2: Device_SW_Ver_No | P2: Meter_Program_ID | Q2: Meter_Form_Type | R2: Tariff_Id | S2: Post Upgrade Interval reads
