Workbook

Sheet Days
A1: 1 | B1: Mon | E1: Target Test Velocity per Tester | F1: 8
A2: 2 | B2: Tue | E2: Total Planned # of test cases | F2: 274
A3: 3 | B3: Wed | E3: Total Actual # of test cases | F3: =COUNT('2024 - L&G R64 - Test Instances'!A:A)-1 -> 361
A4: 4 | B4: Thu | E4: Allowance | F4: 0.1
A5: 5 | B5: Fri | E5: Effort (Man Days) | F5: =(F2*(1+F4))/F1 -> 37.675
A6: 6 | B6: Sat | E6: # of resources | F6: 2
A7: 7 | B7: Sun | E7: # of days | F7: =ROUNDUP(F5/F6,0) -> 19
E9: Scheduled Start | F9: 45555
A10: Date | B10: Day | C10: Holiday | E10: Scheduled Finish | F10: 45582
A11: 45292 | B11: =VLOOKUP(WEEKDAY(A11,2),$A$1:$B$7,2,0) -> Mon | C11: New Year's Day | E11: Projected Finish | F11: =VLOOKUP(TODAY(),'2024 - L&G R64 Tracking'!AM:AQ,5,0) -> 45612.2
A12: 45317 | B12: =VLOOKUP(WEEKDAY(A12,2),$A$1:$B$7,2,0) -> Fri | C12: Australia Day | E12: Project Delay | F12: =NETWORKDAYS(F10,F11,$A$11:$A$38) -> 21
A13: 45362 | B13: =VLOOKUP(WEEKDAY(A13,2),$A$1:$B$7,2,0) -> Mon | C13: Labour Day (VIC) | E13: Project Delay | F13: =(NETWORKDAYS(F9,F10,$A$11:$A$38)-NETWORKDAYS(F10,F11,$A$11:$A$38))/NETWORKDAYS(F9,F10,$A$11:$A$38) -> -0.10526316
A14: 45380 | B14: =VLOOKUP(WEEKDAY(A14,2),$A$1:$B$7,2,0) -> Fri | C14: Good Friday
A15: 45381 | B15: =VLOOKUP(WEEKDAY(A15,2),$A$1:$B$7,2,0) -> Sat | C15: Easter Saturday | E15: Original Deadline
A16: 45382 | B16: =VLOOKUP(WEEKDAY(A16,2),$A$1:$B$7,2,0) -> Sun | C16: Easter Sunday | E16: Adjusted Deadline (VPN)
A17: 45383 | B17: =VLOOKUP(WEEKDAY(A17,2),$A$1:$B$7,2,0) -> Mon | C17: Easter Monday | E17: New Deadline (Project)
A18: 45407 | B18: =VLOOKUP(WEEKDAY(A18,2),$A$1:$B$7,2,0) -> Thu | C18: Anzac Day
A19: 45453 | B19: =VLOOKUP(WEEKDAY(A19,2),$A$1:$B$7,2,0) -> Mon | C19: Kings's Birthday
A20: 45562 | B20: =VLOOKUP(WEEKDAY(A20,2),$A$1:$B$7,2,0) -> Fri | C20: AFL Grand Final
A21: 45601 | B21: =VLOOKUP(WEEKDAY(A21,2),$A$1:$B$7,2,0) -> Tue | C21: Melbourne Cup (VIC)
A22: 45651 | B22: =VLOOKUP(WEEKDAY(A22,2),$A$1:$B$7,2,0) -> Wed | C22: Christmas | E22: Target Test Velocity per Tester | F22: =$F$1 -> 8
A23: 45652 | B23: =VLOOKUP(WEEKDAY(A23,2),$A$1:$B$7,2,0) -> Thu | C23: Boxing Day | E23: VPN - Planned # of test cases (UIQ-Patch123) | F23: =ROUND((N11+N14)*1.1,0) -> 0
A24: 45653 | B24: =VLOOKUP(WEEKDAY(A24,2),$A$1:$B$7,2,0) -> Fri | C24: Powercor Day | E24: VPN - Actual # of test cases (UIQ-Patch123) | F24: =GETPIVOTDATA("Executed",'2024 - L&G R64 Pivot'!$A$2) -> #REF!
A25: 45658 | B25: =VLOOKUP(WEEKDAY(A25,2),$A$1:$B$7,2,0) -> Wed | C25: New Year's Day
A26: 45684 | B26: =VLOOKUP(WEEKDAY(A26,2),$A$1:$B$7,2,0) -> Mon | C26: Australia Day | E26: Target Test Velocity per Tester | F26: =$F$1 -> 8
A27: 45726 | B27: =VLOOKUP(WEEKDAY(A27,2),$A$1:$B$7,2,0) -> Mon | C27: Labour Day (VIC) | E27: UE - Planned # of test cases (Phase 2b) | F27: =ROUND(N12*1.1,0) -> 0
A28: 45765 | B28: =VLOOKUP(WEEKDAY(A28,2),$A$1:$B$7,2,0) -> Fri | C28: Good Friday | E28: UE - ACtual # of test cases (Phase 2b) | F28: =GETPIVOTDATA("Executed",'2024 - L&G R64 Pivot'!$A$2,"Target Cycle:","UE_Phase_1a")-GETPIVOTDATA("Executed",'2024 - L&G R64 Pivot'!$A$2,"Target Cycle:","UE_Phase_1a","Executed","RBT") -> #REF!
A29: 45766 | B29: =VLOOKUP(WEEKDAY(A29,2),$A$1:$B$7,2,0) -> Sat | C29: Easter Saturday
A30: 45767 | B30: =VLOOKUP(WEEKDAY(A30,2),$A$1:$B$7,2,0) -> Sun | C30: Easter Sunday | E30: Target Test Velocity per Tester | F30: =$F$1 -> 8
A31: 45768 | B31: =VLOOKUP(WEEKDAY(A31,2),$A$1:$B$7,2,0) -> Mon | C31: Easter Monday | E31: UE - Planned # of test cases (Phase 2b) | F31: =ROUND(N13*1.1,0) -> 0
A32: 45772 | B32: =VLOOKUP(WEEKDAY(A32,2),$A$1:$B$7,2,0) -> Fri | C32: Anzac Day | E32: UE - ACtual # of test cases (Phase 2b) | F32: =GETPIVOTDATA("Executed",'2024 - L&G R64 Pivot'!$A$2,"Target Cycle:","UE_Phase_1b")-GETPIVOTDATA("Executed",'2024 - L&G R64 Pivot'!$A$2,"Target Cycle:","UE_Phase_1b","Executed","RBT") -> #REF!
A33: 45817 | B33: =VLOOKUP(WEEKDAY(A33,2),$A$1:$B$7,2,0) -> Mon | C33: Kings's Birthday
A34: 45926 | B34: =VLOOKUP(WEEKDAY(A34,2),$A$1:$B$7,2,0) -> Fri | C34: AFL Grand Final
A35: 45965 | B35: =VLOOKUP(WEEKDAY(A35,2),$A$1:$B$7,2,0) -> Tue | C35: Melbourne Cup (VIC)
A36: 46016 | B36: =VLOOKUP(WEEKDAY(A36,2),$A$1:$B$7,2,0) -> Thu | C36: Christmas
A37: 46017 | B37: =VLOOKUP(WEEKDAY(A37,2),$A$1:$B$7,2,0) -> Fri | C37: Boxing Day
A38: 46020 | B38: =VLOOKUP(WEEKDAY(A38,2),$A$1:$B$7,2,0) -> Mon | C38: Powercor Day

Sheet 2024 - L&G R64 - Test Instances
A1: Test Configuration: Test ID | B1: Target Cycle: | C1: Test Set: Name: | D1: Test: Subject: | E1: Test: Test Name: | F1: Test: Test Priority: | G1: Comments: | H1: Exec Date: | I1: Time | J1: Test: Execution Status: | K1: Status: | L1: Tester: | M1: Responsible Tester | N1: Executed | O1: Done | P1: Name | Q1: Responsible Testers
A2: 36 | B2: L&G 82-R64 | C2: U3400 R6.4 - NIC5 | D2: 001 - Commissioning | E2: Meter state transitions - New to xxx to Active | F2: 1-Critical | H2: 45559 | I2: 0.72012731 | J2: Blocked | K2: RBT | L2: mkalra(Manoj Kalra) | M2: mkalra(Manoj Kalra) | N2: =IF(OR(K2="No Run",K2="Blocked",K2="N/A"),"No Run",IF(OR(K2="RBT"),"RBT","Executed")) -> RBT | O2: =IF(OR(K2="No Run",K2="Not Completed"),"Unfinished",IF(OR(K2="asdfs"),"RBT",IF(OR(K2="N/A"),"N/A",IF(OR(K2="Passed",K2="Failed",K2="RBT"),"Done",IF(OR(K2="Blocked"),"Blocked","-"))))) -> Done | P2: =CONCATENATE(C2," - ",E2) -> U3400 R6.4 - NIC5 - Meter state transitions - New to xxx to Active
A3: 36 | B3: L&G 82-R64 | C3: U3400 R6.4 - NIC5 | D3: 001 - Commissioning | E3: Meter state transitions - New to xxx to Active | F3: 1-Critical | H3: 45559 | I3: 0.72013889 | J3: Blocked | K3: RBT | L3: mkalra(Manoj Kalra) | M3: mkalra(Manoj Kalra) | N3: =IF(OR(K3="No Run",K3="Blocked",K3="N/A"),"No Run",IF(OR(K3="RBT"),"RBT","Executed")) -> RBT | O3: =IF(OR(K3="No Run",K3="Not Completed"),"Unfinished",IF(OR(K3="asdfs"),"RBT",IF(OR(K3="N/A"),"N/A",IF(OR(K3="Passed",K3="Failed",K3="RBT"),"Done",IF(OR(K3="Blocked"),"Blocked","-"))))) -> Done | P3: =CONCATENATE(C3," - ",E3) -> U3400 R6.4 - NIC5 - Meter state transitions - New to xxx to Active
A4: 36 | B4: L&G 82-R64 | C4: U3400 R6.4 - NIC3 | D4: 001 - Commissioning | E4: Meter state transitions - New to xxx to Active | F4: 1-Critical | H4: 45559 | I4: 0.71958333 | J4: Blocked | K4: RBT | L4: mkalra(Manoj Kalra) | M4: mkalra(Manoj Kalra) | N4: =IF(OR(K4="No Run",K4="Blocked",K4="N/A"),"No Run",IF(OR(K4="RBT"),"RBT","Executed")) -> RBT | O4: =IF(OR(K4="No Run",K4="Not Completed"),"Unfinished",IF(OR(K4="asdfs"),"RBT",IF(OR(K4="N/A"),"N/A",IF(OR(K4="Passed",K4="Failed",K4="RBT"),"Done",IF(OR(K4="Blocked"),"Blocked","-"))))) -> Done | P4: =CONCATENATE(C4," - ",E4) -> U3400 R6.4 - NIC3 - Meter state transitions - New to xxx to Active
A5: 36 | B5: L&G 82-R64 | C5: U3400 R6.4 - NIC3 | D5: 001 - Commissioning | E5: Meter state transitions - New to xxx to Active | F5: 1-Critical | H5: 45559 | I5: 0.71957176 | J5: Blocked | K5: RBT | L5: mkalra(Manoj Kalra) | M5: mkalra(Manoj Kalra) | N5: =IF(OR(K5="No Run",K5="Blocked",K5="N/A"),"No Run",IF(OR(K5="RBT"),"RBT","Executed")) -> RBT | O5: =IF(OR(K5="No Run",K5="Not Completed"),"Unfinished",IF(OR(K5="asdfs"),"RBT",IF(OR(K5="N/A"),"N/A",IF(OR(K5="Passed",K5="Failed",K5="RBT"),"Done",IF(OR(K5="Blocked"),"Blocked","-"))))) -> Done | P5: =CONCATENATE(C5," - ",E5) -> U3400 R6.4 - NIC3 - Meter state transitions - New to xxx to Active
A6: 36 | B6: L&G 82-R64 | C6: U1300 R6.4 - NIC5 | D6: 001 - Commissioning | E6: Meter state transitions - New to xxx to Active | F6: 1-Critical | H6: 45559 | I6: 0.71859954 | J6: Blocked | K6: RBT | L6: mkalra(Manoj Kalra) | M6: knjuguna(Kamau Njuguna) | N6: =IF(OR(K6="No Run",K6="Blocked",K6="N/A"),"No Run",IF(OR(K6="RBT"),"RBT","Executed")) -> RBT | O6: =IF(OR(K6="No Run",K6="Not Completed"),"Unfinished",IF(OR(K6="asdfs"),"RBT",IF(OR(K6="N/A"),"N/A",IF(OR(K6="Passed",K6="Failed",K6="RBT"),"Done",IF(OR(K6="Blocked"),"Blocked","-"))))) -> Done | P6: =CONCATENATE(C6," - ",E6) -> U1300 R6.4 - NIC5 - Meter state transitions - New to xxx to Active
A7: 36 | B7: L&G 82-R64 | C7: U1300 R6.4 - NIC5 | D7: 001 - Commissioning | E7: Meter state transitions - New to xxx to Active | F7: 1-Critical | H7: 45559 | I7: 0.71861111 | J7: Blocked | K7: RBT | L7: mkalra(Manoj Kalra) | M7: knjuguna(Kamau Njuguna) | N7: =IF(OR(K7="No Run",K7="Blocked",K7="N/A"),"No Run",IF(OR(K7="RBT"),"RBT","Executed")) -> RBT | O7: =IF(OR(K7="No Run",K7="Not Completed"),"Unfinished",IF(OR(K7="asdfs"),"RBT",IF(OR(K7="N/A"),"N/A",IF(OR(K7="Passed",K7="Failed",K7="RBT"),"Done",IF(OR(K7="Blocked"),"Blocked","-"))))) -> Done | P7: =CONCATENATE(C7," - ",E7) -> U1300 R6.4 - NIC5 - Meter state transitions - New to xxx to Active
A8: 36 | B8: L&G 82-R64 | C8: U1300 R6.4 - NIC3 | D8: 001 - Commissioning | E8: Meter state transitions - New to xxx to Active | F8: 1-Critical | H8: 45559 | I8: 0.71833333 | J8: Blocked | K8: RBT | L8: mkalra(Manoj Kalra) | M8: knjuguna(Kamau Njuguna) | N8: =IF(OR(K8="No Run",K8="Blocked",K8="N/A"),"No Run",IF(OR(K8="RBT"),"RBT","Executed")) -> RBT | O8: =IF(OR(K8="No Run",K8="Not Completed"),"Unfinished",IF(OR(K8="asdfs"),"RBT",IF(OR(K8="N/A"),"N/A",IF(OR(K8="Passed",K8="Failed",K8="RBT"),"Done",IF(OR(K8="Blocked"),"Blocked","-"))))) -> Done | P8: =CONCATENATE(C8," - ",E8) -> U1300 R6.4 - NIC3 - Meter state transitions - New to xxx to Active
A9: 36 | B9: L&G 82-R64 | C9: U1300 R6.4 - NIC3 | D9: 001 - Commissioning | E9: Meter state transitions - New to xxx to Active | F9: 1-Critical | H9: 45559 | I9: 0.71829861 | J9: Blocked | K9: RBT | L9: mkalra(Manoj Kalra) | M9: knjuguna(Kamau Njuguna) | N9: =IF(OR(K9="No Run",K9="Blocked",K9="N/A"),"No Run",IF(OR(K9="RBT"),"RBT","Executed")) -> RBT | O9: =IF(OR(K9="No Run",K9="Not Completed"),"Unfinished",IF(OR(K9="asdfs"),"RBT",IF(OR(K9="N/A"),"N/A",IF(OR(K9="Passed",K9="Failed",K9="RBT"),"Done",IF(OR(K9="Blocked"),"Blocked","-"))))) -> Done | P9: =CONCATENATE(C9," - ",E9) -> U1300 R6.4 - NIC3 - Meter state transitions - New to xxx to Active
A10: 32 | B10: L&G 82-R64 | C10: U1300 R6.4 - NIC3 | D10: 001 - Commissioning | E10: Reloading RMA meters into UIQ | F10: 1-Critical | H10: 45559 | I10: 0.71835648 | J10: RBT | K10: RBT | L10: mkalra(Manoj Kalra) | M10: knjuguna(Kamau Njuguna) | N10: =IF(OR(K10="No Run",K10="Blocked",K10="N/A"),"No Run",IF(OR(K10="RBT"),"RBT","Executed")) -> RBT | O10: =IF(OR(K10="No Run",K10="Not Completed"),"Unfinished",IF(OR(K10="asdfs"),"RBT",IF(OR(K10="N/A"),"N/A",IF(OR(K10="Passed",K10="Failed",K10="RBT"),"Done",IF(OR(K10="Blocked"),"Blocked","-"))))) -> Done | P10: =CONCATENATE(C10," - ",E10) -> U1300 R6.4 - NIC3 - Reloading RMA meters into UIQ
A11: 32 | B11: L&G 82-R64 | C11: U1300 R6.4 - NIC3 | D11: 001 - Commissioning | E11: Reloading RMA meters into UIQ | F11: 1-Critical | H11: 45559 | I11: 0.71844907 | J11: RBT | K11: RBT | L11: mkalra(Manoj Kalra) | M11: knjuguna(Kamau Njuguna) | N11: =IF(OR(K11="No Run",K11="Blocked",K11="N/A"),"No Run",IF(OR(K11="RBT"),"RBT","Executed")) -> RBT | O11: =IF(OR(K11="No Run",K11="Not Completed"),"Unfinished",IF(OR(K11="asdfs"),"RBT",IF(OR(K11="N/A"),"N/A",IF(OR(K11="Passed",K11="Failed",K11="RBT"),"Done",IF(OR(K11="Blocked"),"Blocked","-"))))) -> Done | P11: =CONCATENATE(C11," - ",E11) -> U1300 R6.4 - NIC3 - Reloading RMA meters into UIQ
A12: 32 | B12: L&G 82-R64 | C12: U1300 R6.4 - NIC5 | D12: 001 - Commissioning | E12: Reloading RMA meters into UIQ | F12: 1-Critical | H12: 45559 | I12: 0.71857639 | J12: RBT | K12: RBT | L12: mkalra(Manoj Kalra) | M12: knjuguna(Kamau Njuguna) | N12: =IF(OR(K12="No Run",K12="Blocked",K12="N/A"),"No Run",IF(OR(K12="RBT"),"RBT","Executed")) -> RBT | O12: =IF(OR(K12="No Run",K12="Not Completed"),"Unfinished",IF(OR(K12="asdfs"),"RBT",IF(OR(K12="N/A"),"N/A",IF(OR(K12="Passed",K12="Failed",K12="RBT"),"Done",IF(OR(K12="Blocked"),"Blocked","-"))))) -> Done | P12: =CONCATENATE(C12," - ",E12) -> U1300 R6.4 - NIC5 - Reloading RMA meters into UIQ
A13: 32 | B13: L&G 82-R64 | C13: U1300 R6.4 - NIC5 | D13: 001 - Commissioning | E13: Reloading RMA meters into UIQ | F13: 1-Critical | H13: 45559 | I13: 0.71855324 | J13: RBT | K13: RBT | L13: mkalra(Manoj Kalra) | M13: knjuguna(Kamau Njuguna) | N13: =IF(OR(K13="No Run",K13="Blocked",K13="N/A"),"No Run",IF(OR(K13="RBT"),"RBT","Executed")) -> RBT | O13: =IF(OR(K13="No Run",K13="Not Completed"),"Unfinished",IF(OR(K13="asdfs"),"RBT",IF(OR(K13="N/A"),"N/A",IF(OR(K13="Passed",K13="Failed",K13="RBT"),"Done",IF(OR(K13="Blocked"),"Blocked","-"))))) -> Done | P13: =CONCATENATE(C13," - ",E13) -> U1300 R6.4 - NIC5 - Reloading RMA meters into UIQ
... A50: 39 | B50: L&G 82-R64 | C50: U3400 R6.4 - NIC3 | D50: 007 - Meter Firmware | E50: FWU meter firmware upgrade - (seedingpercent) percent seeded - Uninterrupted | F50: 1-Critical | H50: 45573 | I50: 0.42417824 | J50: Failed | K50: Failed | L50: mkalra(Manoj Kalra) | M50: mkalra(Manoj Kalra) | N50: =IF(OR(K50="No Run",K50="Blocked",K50="N/A"),"No Run",IF(OR(K50="RBT"),"RBT","Executed")) -> Executed | O50: =IF(OR(K50="No Run",K50="Not Completed"),"Unfinished",IF(OR(K50="asdfs"),"RBT",IF(OR(K50="N/A"),"N/A",IF(OR(K50="Passed",K50="Failed",K50="RBT"),"Done",IF(OR(K50="Blocked"),"Blocked","-"))))) -> Done | P50: =CONCATENATE(C50," - ",E50) -> U3400 R6.4 - NIC3 - FWU meter firmware upgrade - (seedingpercent) percent seeded - Uninterrupted
A51: 1703 | B51: L&G 82-R64 | C51: U3400 R6.4 - NIC3 | D51: 007 - Meter Firmware | E51: FWU meter firmware upgrade - (seedingpercent) percent seeded - Interrupted | F51: 1-Critical | G51: This Test is performed on U1300 meter | H51: 45579 | I51: 0.68684028 | J51: Failed | K51: RBT | L51: mkalra(Manoj Kalra) | M51: mkalra(Manoj Kalra) | N51: =IF(OR(K51="No Run",K51="Blocked",K51="N/A"),"No Run",IF(OR(K51="RBT"),"RBT","Executed")) -> RBT | O51: =IF(OR(K51="No Run",K51="Not Completed"),"Unfinished",IF(OR(K51="asdfs"),"RBT",IF(OR(K51="N/A"),"N/A",IF(OR(K51="Passed",K51="Failed",K51="RBT"),"Done",IF(OR(K51="Blocked"),"Blocked","-"))))) -> Done | P51: =CONCATENATE(C51," - ",E51) -> U3400 R6.4 - NIC3 - FWU meter firmware upgrade - (seedingpercent) percent seeded - Interrupted
A52: 38 | B52: L&G 82-R64 | C52: U3400 R6.4 - NIC3 | D52: 007 - Meter Firmware | E52: Meter firmware audit | F52: 1-Critical | H52: 45569 | I52: 0.38296296 | J52: Passed | K52: Passed | L52: mkalra(Manoj Kalra) | M52: mkalra(Manoj Kalra) | N52: =IF(OR(K52="No Run",K52="Blocked",K52="N/A"),"No Run",IF(OR(K52="RBT"),"RBT","Executed")) -> Executed | O52: =IF(OR(K52="No Run",K52="Not Completed"),"Unfinished",IF(OR(K52="asdfs"),"RBT",IF(OR(K52="N/A"),"N/A",IF(OR(K52="Passed",K52="Failed",K52="RBT"),"Done",IF(OR(K52="Blocked"),"Blocked","-"))))) -> Done | P52: =CONCATENATE(C52," - ",E52) -> U3400 R6.4 - NIC3 - Meter firmware audit
A53: 39 | B53: L&G 82-R64 | C53: U1300 R6.4 - NIC3 | D53: 007 - Meter Firmware | E53: FWU meter firmware upgrade - (seedingpercent) percent seeded - Uninterrupted | F53: 1-Critical | H53: 45555 | I53: 0.45847222 | J53: Failed | K53: Failed | L53: knjuguna(Kamau Njuguna) | M53: knjuguna(Kamau Njuguna) | N53: =IF(OR(K53="No Run",K53="Blocked",K53="N/A"),"No Run",IF(OR(K53="RBT"),"RBT","Executed")) -> Executed | O53: =IF(OR(K53="No Run",K53="Not Completed"),"Unfinished",IF(OR(K53="asdfs"),"RBT",IF(OR(K53="N/A"),"N/A",IF(OR(K53="Passed",K53="Failed",K53="RBT"),"Done",IF(OR(K53="Blocked"),"Blocked","-"))))) -> Done | P53: =CONCATENATE(C53," - ",E53) -> U1300 R6.4 - NIC3 - FWU meter firmware upgrade - (seedingpercent) percent seeded - Uninterrupted
A54: 1703 | B54: L&G 82-R64 | C54: U1300 R6.4 - NIC3 | D54: 007 - Meter Firmware | E54: FWU meter firmware upgrade - (seedingpercent) percent seeded - Interrupted | F54: 1-Critical | H54: 45581 | I54: 0.3975 | J54: Failed | K54: Failed | L54: knjuguna(Kamau Njuguna) | M54: knjuguna(Kamau Njuguna) | N54: =IF(OR(K54="No Run",K54="Blocked",K54="N/A"),"No Run",IF(OR(K54="RBT"),"RBT","Executed")) -> Executed | O54: =IF(OR(K54="No Run",K54="Not Completed"),"Unfinished",IF(OR(K54="asdfs"),"RBT",IF(OR(K54="N/A"),"N/A",IF(OR(K54="Passed",K54="Failed",K54="RBT"),"Done",IF(OR(K54="Blocked"),"Blocked","-"))))) -> Done | P54: =CONCATENATE(C54," - ",E54) -> U1300 R6.4 - NIC3 - FWU meter firmware upgrade - (seedingpercent) percent seeded - Interrupted
A55: 38 | B55: L&G 82-R64 | C55: U1300 R6.4 - NIC3 | D55: 007 - Meter Firmware | E55: Meter firmware audit | F55: 1-Critical | H55: 45555 | I55: 0.55539352 | J55: Passed | K55: Passed | L55: knjuguna(Kamau Njuguna) | M55: knjuguna(Kamau Njuguna) | N55: =IF(OR(K55="No Run",K55="Blocked",K55="N/A"),"No Run",IF(OR(K55="RBT"),"RBT","Executed")) -> Executed | O55: =IF(OR(K55="No Run",K55="Not Completed"),"Unfinished",IF(OR(K55="asdfs"),"RBT",IF(OR(K55="N/A"),"N/A",IF(OR(K55="Passed",K55="Failed",K55="RBT"),"Done",IF(OR(K55="Blocked"),"Blocked","-"))))) -> Done | P55: =CONCATENATE(C55," - ",E55) -> U1300 R6.4 - NIC3 - Meter firmware audit
A56: 39 | B56: L&G 82-R64 | C56: U3400 R6.4 - NIC5 | D56: 007 - Meter Firmware | E56: FWU meter firmware upgrade - (seedingpercent) percent seeded - Uninterrupted | F56: 1-Critical | H56: 45573 | I56: 0.42483796 | J56: Failed | K56: Failed | L56: mkalra(Manoj Kalra) | M56: mkalra(Manoj Kalra) | N56: =IF(OR(K56="No Run",K56="Blocked",K56="N/A"),"No Run",IF(OR(K56="RBT"),"RBT","Executed")) -> Executed | O56: =IF(OR(K56="No Run",K56="Not Completed"),"Unfinished",IF(OR(K56="asdfs"),"RBT",IF(OR(K56="N/A"),"N/A",IF(OR(K56="Passed",K56="Failed",K56="RBT"),"Done",IF(OR(K56="Blocked"),"Blocked","-"))))) -> Done | P56: =CONCATENATE(C56," - ",E56) -> U3400 R6.4 - NIC5 - FWU meter firmware upgrade - (seedingpercent) percent seeded - Uninterrupted
A57: 1703 | B57: L&G 82-R64 | C57: U3400 R6.4 - NIC5 | D57: 007 - Meter Firmware | E57: FWU meter firmware upgrade - (seedingpercent) percent seeded - Interrupted | F57: 1-Critical | G57: This Test is performed on U1300 meter | H57: 45580 | I57: 0.44834491 | J57: Failed | K57: RBT | L57: mkalra(Manoj Kalra) | M57: mkalra(Manoj Kalra) | N57: =IF(OR(K57="No Run",K57="Blocked",K57="N/A"),"No Run",IF(OR(K57="RBT"),"RBT","Executed")) -> RBT | O57: =IF(OR(K57="No Run",K57="Not Completed"),"Unfinished",IF(OR(K57="asdfs"),"RBT",IF(OR(K57="N/A"),"N/A",IF(OR(K57="Passed",K57="Failed",K57="RBT"),"Done",IF(OR(K57="Blocked"),"Blocked","-"))))) -> Done | P57: =CONCATENATE(C57," - ",E57) -> U3400 R6.4 - NIC5 - FWU meter firmware upgrade - (seedingpercent) percent seeded - Interrupted
A58: 38 | B58: L&G 82-R64 | C58: U3400 R6.4 - NIC5 | D58: 007 - Meter Firmware | E58: Meter firmware audit | F58: 1-Critical | H58: 45569 | I58: 0.38293981 | J58: Passed | K58: Passed | L58: mkalra(Manoj Kalra) | M58: mkalra(Manoj Kalra) | N58: =IF(OR(K58="No Run",K58="Blocked",K58="N/A"),"No Run",IF(OR(K58="RBT"),"RBT","Executed")) -> Executed | O58: =IF(OR(K58="No Run",K58="Not Completed"),"Unfinished",IF(OR(K58="asdfs"),"RBT",IF(OR(K58="N/A"),"N/A",IF(OR(K58="Passed",K58="Failed",K58="RBT"),"Done",IF(OR(K58="Blocked"),"Blocked","-"))))) -> Done | P58: =CONCATENATE(C58," - ",E58) -> U3400 R6.4 - NIC5 - Meter firmware audit
A59: 39 | B59: L&G 82-R64 | C59: U1300 R6.4 - NIC5 | D59: 007 - Meter Firmware | E59: FWU meter firmware upgrade - (seedingpercent) percent seeded - Uninterrupted | F59: 1-Critical | H59: 45555 | I59: 0.47291667 | J59: Failed | K59: Failed | L59: knjuguna(Kamau Njuguna) | M59: knjuguna(Kamau Njuguna) | N59: =IF(OR(K59="No Run",K59="Blocked",K59="N/A"),"No Run",IF(OR(K59="RBT"),"RBT","Executed")) -> Executed | O59: =IF(OR(K59="No Run",K59="Not Completed"),"Unfinished",IF(OR(K59="asdfs"),"RBT",IF(OR(K59="N/A"),"N/A",IF(OR(K59="Passed",K59="Failed",K59="RBT"),"Done",IF(OR(K59="Blocked"),"Blocked","-"))))) -> Done | P59: =CONCATENATE(C59," - ",E59) -> U1300 R6.4 - NIC5 - FWU meter firmware upgrade - (seedingpercent) percent seeded - Uninterrupted
A60: 1703 | B60: L&G 82-R64 | C60: U1300 R6.4 - NIC5 | D60: 007 - Meter Firmware | E60: FWU meter firmware upgrade - (seedingpercent) percent seeded - Interrupted | F60: 1-Critical | G60: NIC320 meter has been tested | H60: 45580 | I60: 0.49413194 | J60: Failed | K60: RBT | L60: knjuguna(Kamau Njuguna) | M60: knjuguna(Kamau Njuguna) | N60: =IF(OR(K60="No Run",K60="Blocked",K60="N/A"),"No Run",IF(OR(K60="RBT"),"RBT","Executed")) -> RBT | O60: =IF(OR(K60="No Run",K60="Not Completed"),"Unfinished",IF(OR(K60="asdfs"),"RBT",IF(OR(K60="N/A"),"N/A",IF(OR(K60="Passed",K60="Failed",K60="RBT"),"Done",IF(OR(K60="Blocked"),"Blocked","-"))))) -> Done | P60: =CONCATENATE(C60," - ",E60) -> U1300 R6.4 - NIC5 - FWU meter firmware upgrade - (seedingpercent) percent seeded - Interrupted
A61: 38 | B61: L&G 82-R64 | C61: U1300 R6.4 - NIC5 | D61: 007 - Meter Firmware | E61: Meter firmware audit | F61: 1-Critical | H61: 45555 | I61: 0.6258912 | J61: Passed | K61: Passed | L61: knjuguna(Kamau Njuguna) | M61: knjuguna(Kamau Njuguna) | N61: =IF(OR(K61="No Run",K61="Blocked",K61="N/A"),"No Run",IF(OR(K61="RBT"),"RBT","Executed")) -> Executed | O61: =IF(OR(K61="No Run",K61="Not Completed"),"Unfinished",IF(OR(K61="asdfs"),"RBT",IF(OR(K61="N/A"),"N/A",IF(OR(K61="Passed",K61="Failed",K61="RBT"),"Done",IF(OR(K61="Blocked"),"Blocked","-"))))) -> Done | P61: =CONCATENATE(C61," - ",E61) -> U1300 R6.4 - NIC5 - Meter firmware audit
A62: 41 | B62: L&G 82-R64 | C62: U3400 R6.4 - NIC3 | D62: 008 - Meter Program | E62: Meter Program - Remote 1 - Load a full meter program (New Meter Program in UIQ) | F62: 1-Critical | H62: 45572 | I62: 0.65039352 | J62: Not Completed | K62: Passed | L62: mkalra(Manoj Kalra) | M62: mkalra(Manoj Kalra) | N62: =IF(OR(K62="No Run",K62="Blocked",K62="N/A"),"No Run",IF(OR(K62="RBT"),"RBT","Executed")) -> Executed | O62: =IF(OR(K62="No Run",K62="Not Completed"),"Unfinished",IF(OR(K62="asdfs"),"RBT",IF(OR(K62="N/A"),"N/A",IF(OR(K62="Passed",K62="Failed",K62="RBT"),"Done",IF(OR(K62="Blocked"),"Blocked","-"))))) -> Done | P62: =CONCATENATE(C62," - ",E62) -> U3400 R6.4 - NIC3 - Meter Program - Remote 1 - Load a full meter program (New Meter Program in UIQ)
A63: 42 | B63: L&G 82-R64 | C63: U3400 R6.4 - NIC3 | D63: 008 - Meter Program | E63: Meter Program - Remote 4 - Load a full meter program (Meter Program exists in UIQ) | F63: 1-Critical | H63: 45573 | I63: 0.74234954 | J63: Passed | K63: Passed | L63: mkalra(Manoj Kalra) | M63: mkalra(Manoj Kalra) | N63: =IF(OR(K63="No Run",K63="Blocked",K63="N/A"),"No Run",IF(OR(K63="RBT"),"RBT","Executed")) -> Executed | O63: =IF(OR(K63="No Run",K63="Not Completed"),"Unfinished",IF(OR(K63="asdfs"),"RBT",IF(OR(K63="N/A"),"N/A",IF(OR(K63="Passed",K63="Failed",K63="RBT"),"Done",IF(OR(K63="Blocked"),"Blocked","-"))))) -> Done | P63: =CONCATENATE(C63," - ",E63) -> U3400 R6.4 - NIC3 - Meter Program - Remote 4 - Load a full meter program (Meter Program exists in UIQ)
A64: 61 | B64: L&G 82-R64 | C64: U3400 R6.4 - NIC3 | D64: 008 - Meter Program | E64: Meter Program - export events | F64: 1-Critical | H64: 45565 | I64: 0.57336806 | J64: RBT | K64: Passed | L64: mkalra(Manoj Kalra) | M64: mkalra(Manoj Kalra) | N64: =IF(OR(K64="No Run",K64="Blocked",K64="N/A"),"No Run",IF(OR(K64="RBT"),"RBT","Executed")) -> Executed | O64: =IF(OR(K64="No Run",K64="Not Completed"),"Unfinished",IF(OR(K64="asdfs"),"RBT",IF(OR(K64="N/A"),"N/A",IF(OR(K64="Passed",K64="Failed",K64="RBT"),"Done",IF(OR(K64="Blocked"),"Blocked","-"))))) -> Done | P64: =CONCATENATE(C64," - ",E64) -> U3400 R6.4 - NIC3 - Meter Program - export events
A65: 40 | B65: L&G 82-R64 | C65: U3400 R6.4 - NIC3 | D65: 008 - Meter Program | E65: Meter program audit | F65: 1-Critical | H65: 45572 | I65: 0.66690972 | J65: Passed | K65: Passed | L65: mkalra(Manoj Kalra) | M65: mkalra(Manoj Kalra) | N65: =IF(OR(K65="No Run",K65="Blocked",K65="N/A"),"No Run",IF(OR(K65="RBT"),"RBT","Executed")) -> Executed | O65: =IF(OR(K65="No Run",K65="Not Completed"),"Unfinished",IF(OR(K65="asdfs"),"RBT",IF(OR(K65="N/A"),"N/A",IF(OR(K65="Passed",K65="Failed",K65="RBT"),"Done",IF(OR(K65="Blocked"),"Blocked","-"))))) -> Done | P65: =CONCATENATE(C65," - ",E65) -> U3400 R6.4 - NIC3 - Meter program audit
A66: 41 | B66: L&G 82-R64 | C66: U1300 R6.4 - NIC3 | D66: 008 - Meter Program | E66: Meter Program - Remote 1 - Load a full meter program (New Meter Program in UIQ) | F66: 1-Critical | H66: 45568 | I66: 0.61731481 | J66: Not Completed | K66: Failed | L66: knjuguna(Kamau Njuguna) | M66: knjuguna(Kamau Njuguna) | N66: =IF(OR(K66="No Run",K66="Blocked",K66="N/A"),"No Run",IF(OR(K66="RBT"),"RBT","Executed")) -> Executed | O66: =IF(OR(K66="No Run",K66="Not Completed"),"Unfinished",IF(OR(K66="asdfs"),"RBT",IF(OR(K66="N/A"),"N/A",IF(OR(K66="Passed",K66="Failed",K66="RBT"),"Done",IF(OR(K66="Blocked"),"Blocked","-"))))) -> Done | P66: =CONCATENATE(C66," - ",E66) -> U1300 R6.4 - NIC3 - Meter Program - Remote 1 - Load a full meter program (New Meter Program in UIQ)
A67: 42 | B67: L&G 82-R64 | C67: U1300 R6.4 - NIC3 | D67: 008 - Meter Program | E67: Meter Program - Remote 4 - Load a full meter program (Meter Program exists in UIQ) | F67: 1-Critical | H67: 45568 | I67: 0.66568287 | J67: Passed | K67: Failed | L67: knjuguna(Kamau Njuguna) | M67: knjuguna(Kamau Njuguna) | N67: =IF(OR(K67="No Run",K67="Blocked",K67="N/A"),"No Run",IF(OR(K67="RBT"),"RBT","Executed")) -> Executed | O67: =IF(OR(K67="No Run",K67="Not Completed"),"Unfinished",IF(OR(K67="asdfs"),"RBT",IF(OR(K67="N/A"),"N/A",IF(OR(K67="Passed",K67="Failed",K67="RBT"),"Done",IF(OR(K67="Blocked"),"Blocked","-"))))) -> Done | P67: =CONCATENATE(C67," - ",E67) -> U1300 R6.4 - NIC3 - Meter Program - Remote 4 - Load a full meter program (Meter Program exists in UIQ)
A68: 61 | B68: L&G 82-R64 | C68: U1300 R6.4 - NIC3 | D68: 008 - Meter Program | E68: Meter Program - export events | F68: 1-Critical | G68: Covered in Meter Data Integrity test | H68: 45589 | I68: 0.61400463 | J68: RBT | K68: RBT | L68: knjuguna(Kamau Njuguna) | M68: knjuguna(Kamau Njuguna) | N68: =IF(OR(K68="No Run",K68="Blocked",K68="N/A"),"No Run",IF(OR(K68="RBT"),"RBT","Executed")) -> RBT | O68: =IF(OR(K68="No Run",K68="Not Completed"),"Unfinished",IF(OR(K68="asdfs"),"RBT",IF(OR(K68="N/A"),"N/A",IF(OR(K68="Passed",K68="Failed",K68="RBT"),"Done",IF(OR(K68="Blocked"),"Blocked","-"))))) -> Done | P68: =CONCATENATE(C68," - ",E68) -> U1300 R6.4 - NIC3 - Meter Program - export events
A69: 40 | B69: L&G 82-R64 | C69: U1300 R6.4 - NIC3 | D69: 008 - Meter Program | E69: Meter program audit | F69: 1-Critical | H69: 45566 | I69: 0.6930787 | J69: Passed | K69: Failed | L69: knjuguna(Kamau Njuguna) | M69: knjuguna(Kamau Njuguna) | N69: =IF(OR(K69="No Run",K69="Blocked",K69="N/A"),"No Run",IF(OR(K69="RBT"),"RBT","Executed")) -> Executed | O69: =IF(OR(K69="No Run",K69="Not Completed"),"Unfinished",IF(OR(K69="asdfs"),"RBT",IF(OR(K69="N/A"),"N/A",IF(OR(K69="Passed",K69="Failed",K69="RBT"),"Done",IF(OR(K69="Blocked"),"Blocked","-"))))) -> Done | P69: =CONCATENATE(C69," - ",E69) -> U1300 R6.4 - NIC3 - Meter program audit
A70: 41 | B70: L&G 82-R64 | C70: U3400 R6.4 - NIC5 | D70: 008 - Meter Program | E70: Meter Program - Remote 1 - Load a full meter program (New Meter Program in UIQ) | F70: 1-Critical | H70: 45572 | I70: 0.63010417 | J70: Not Completed | K70: Passed | L70: mkalra(Manoj Kalra) | M70: mkalra(Manoj Kalra) | N70: =IF(OR(K70="No Run",K70="Blocked",K70="N/A"),"No Run",IF(OR(K70="RBT"),"RBT","Executed")) -> Executed | O70: =IF(OR(K70="No Run",K70="Not Completed"),"Unfinished",IF(OR(K70="asdfs"),"RBT",IF(OR(K70="N/A"),"N/A",IF(OR(K70="Passed",K70="Failed",K70="RBT"),"Done",IF(OR(K70="Blocked"),"Blocked","-"))))) -> Done | P70: =CONCATENATE(C70," - ",E70) -> U3400 R6.4 - NIC5 - Meter Program - Remote 1 - Load a full meter program (New Meter Program in UIQ)
A71: 42 | B71: L&G 82-R64 | C71: U3400 R6.4 - NIC5 | D71: 008 - Meter Program | E71: Meter Program - Remote 4 - Load a full meter program (Meter Program exists in UIQ) | F71: 1-Critical | H71: 45573 | I71: 0.74237269 | J71: Passed | K71: Passed | L71: mkalra(Manoj Kalra) | M71: mkalra(Manoj Kalra) | N71: =IF(OR(K71="No Run",K71="Blocked",K71="N/A"),"No Run",IF(OR(K71="RBT"),"RBT","Executed")) -> Executed | O71: =IF(OR(K71="No Run",K71="Not Completed"),"Unfinished",IF(OR(K71="asdfs"),"RBT",IF(OR(K71="N/A"),"N/A",IF(OR(K71="Passed",K71="Failed",K71="RBT"),"Done",IF(OR(K71="Blocked"),"Blocked","-"))))) -> Done | P71: =CONCATENATE(C71," - ",E71) -> U3400 R6.4 - NIC5 - Meter Program - Remote 4 - Load a full meter program (Meter Program exists in UIQ)
A72: 61 | B72: L&G 82-R64 | C72: U3400 R6.4 - NIC5 | D72: 008 - Meter Program | E72: Meter Program - export events | F72: 1-Critical | H72: 45565 | I72: 0.56559028 | J72: RBT | K72: Passed | L72: mkalra(Manoj Kalra) | M72: mkalra(Manoj Kalra) | N72: =IF(OR(K72="No Run",K72="Blocked",K72="N/A"),"No Run",IF(OR(K72="RBT"),"RBT","Executed")) -> Executed | O72: =IF(OR(K72="No Run",K72="Not Completed"),"Unfinished",IF(OR(K72="asdfs"),"RBT",IF(OR(K72="N/A"),"N/A",IF(OR(K72="Passed",K72="Failed",K72="RBT"),"Done",IF(OR(K72="Blocked"),"Blocked","-"))))) -> Done | P72: =CONCATENATE(C72," - ",E72) -> U3400 R6.4 - NIC5 - Meter Program - export events
A73: 40 | B73: L&G 82-R64 | C73: U3400 R6.4 - NIC5 | D73: 008 - Meter Program | E73: Meter program audit | F73: 1-Critical | H73: 45572 | I73: 0.666875 | J73: Passed | K73: Passed | L73: mkalra(Manoj Kalra) | M73: mkalra(Manoj Kalra) | N73: =IF(OR(K73="No Run",K73="Blocked",K73="N/A"),"No Run",IF(OR(K73="RBT"),"RBT","Executed")) -> Executed | O73: =IF(OR(K73="No Run",K73="Not Completed"),"Unfinished",IF(OR(K73="asdfs"),"RBT",IF(OR(K73="N/A"),"N/A",IF(OR(K73="Passed",K73="Failed",K73="RBT"),"Done",IF(OR(K73="Blocked"),"Blocked","-"))))) -> Done | P73: =CONCATENATE(C73," - ",E73) -> U3400 R6.4 - NIC5 - Meter program audit
A74: 41 | B74: L&G 82-R64 | C74: U1300 R6.4 - NIC5 | D74: 008 - Meter Program | E74: Meter Program - Remote 1 - Load a full meter program (New Meter Program in UIQ) | F74: 1-Critical | H74: 45568 | I74: 0.61173611 | J74: Not Completed | K74: Failed | L74: knjuguna(Kamau Njuguna) | M74: knjuguna(Kamau Njuguna) | N74: =IF(OR(K74="No Run",K74="Blocked",K74="N/A"),"No Run",IF(OR(K74="RBT"),"RBT","Executed")) -> Executed | O74: =IF(OR(K74="No Run",K74="Not Completed"),"Unfinished",IF(OR(K74="asdfs"),"RBT",IF(OR(K74="N/A"),"N/A",IF(OR(K74="Passed",K74="Failed",K74="RBT"),"Done",IF(OR(K74="Blocked"),"Blocked","-"))))) -> Done | P74: =CONCATENATE(C74," - ",E74) -> U1300 R6.4 - NIC5 - Meter Program - Remote 1 - Load a full meter program (New Meter Program in UIQ)
A75: 42 | B75: L&G 82-R64 | C75: U1300 R6.4 - NIC5 | D75: 008 - Meter Program | E75: Meter Program - Remote 4 - Load a full meter program (Meter Program exists in UIQ) | F75: 1-Critical | H75: 45568 | I75: 0.68877315 | J75: Passed | K75: Failed | L75: knjuguna(Kamau Njuguna) | M75: knjuguna(Kamau Njuguna) | N75: =IF(OR(K75="No Run",K75="Blocked",K75="N/A"),"No Run",IF(OR(K75="RBT"),"RBT","Executed")) -> Executed | O75: =IF(OR(K75="No Run",K75="Not Completed"),"Unfinished",IF(OR(K75="asdfs"),"RBT",IF(OR(K75="N/A"),"N/A",IF(OR(K75="Passed",K75="Failed",K75="RBT"),"Done",IF(OR(K75="Blocked"),"Blocked","-"))))) -> Done | P75: =CONCATENATE(C75," - ",E75) -> U1300 R6.4 - NIC5 - Meter Program - Remote 4 - Load a full meter program (Meter Program exists in UIQ)
A76: 61 | B76: L&G 82-R64 | C76: U1300 R6.4 - NIC5 | D76: 008 - Meter Program | E76: Meter Program - export events | F76: 1-Critical | G76: Covered in Meter Data Integrity test | H76: 45589 | I76: 0.615 | J76: RBT | K76: RBT | L76: knjuguna(Kamau Njuguna) | M76: knjuguna(Kamau Njuguna) | N76: =IF(OR(K76="No Run",K76="Blocked",K76="N/A"),"No Run",IF(OR(K76="RBT"),"RBT","Executed")) -> RBT | O76: =IF(OR(K76="No Run",K76="Not Completed"),"Unfinished",IF(OR(K76="asdfs"),"RBT",IF(OR(K76="N/A"),"N/A",IF(OR(K76="Passed",K76="Failed",K76="RBT"),"Done",IF(OR(K76="Blocked"),"Blocked","-"))))) -> Done | P76: =CONCATENATE(C76," - ",E76) -> U1300 R6.4 - NIC5 - Meter Program - export events
...

Sheet 2024 - L&G R64 Pivot
A2: TC Status | B2: Status | P2: Make sure this is only sorted by Test Name
B3: knjuguna(Kamau Njuguna) | F3: knjuguna(Kamau Njuguna) Total | G3: mkalra(Manoj Kalra) | K3: mkalra(Manoj Kalra) Total | L3: Grand Total | P3: Count of Test: Test Name: | Q3: Column Labels
A4: Test Cycle | B4: Done | C4: Unfinished | D4: - | E4: N/A | G4: Done | H4: - | I4: N/A | J4: Blocked | P4: Row Labels | Q4: U1300 R6.4 - NIC3 | R4: U1300 R6.4 - NIC5 | S4: U3400 R6.4 - NIC3 | T4: U3400 R6.4 - NIC5 | U4: Grand Total | V4: Remarks
A5: L&G 82-R64 | B5: 169 | C5: 4 | D5: 1 | E5: 6 | F5: 180 | G5: 171 | H5: 3 | I5: 6 | J5: 2 | K5: 182 | L5: 362 | P5: 01 Meter Time synchronisation to NIC - forward within interval (Auto) | Q5: 1 | R5: 1 | S5: 1 | T5: 1 | U5: 4 | V5: Execute at the same time
A6: Grand Total | B6: 169 | C6: 4 | D6: 1 | E6: 6 | F6: 180 | G6: 171 | H6: 3 | I6: 6 | J6: 2 | K6: 182 | L6: 362 | P6: 02 L&G PQ Configuration - Remote Enable-Disable | Q6: 1 | R6: 1 | S6: 1 | T6: 1 | U6: 4 | V6: Execute at the same time
P7: 02 Meter Time synchronisation to NIC - forward within interval (Force) | Q7: 1 | R7: 1 | S7: 1 | T7: 1 | U7: 4 | V7: Execute at the same time
P8: 03 L&G PQ Polling - Data Integrity | Q8: 1 | R8: 1 | S8: 1 | T8: 1 | U8: 4 | V8: Execute at the same time
P9: 03 Meter Time synchronisation to NIC - backward within interval (Auto) | Q9: 1 | R9: 1 | S9: 1 | T9: 1 | U9: 4 | V9: Execute at the same time
A10: TC Status | B10: Status | P10: 04 Meter Time synchronisation to NIC - backward within interval (Force) | Q10: 1 | R10: 1 | S10: 1 | T10: 1 | U10: 4 | V10: Execute at the same time
B11: knjuguna(Kamau Njuguna) | F11: knjuguna(Kamau Njuguna) Total | G11: mkalra(Manoj Kalra) | K11: mkalra(Manoj Kalra) Total | L11: Grand Total | P11: 05 Meter Time synchronisation to NIC - forward crossing interval (Auto) | Q11: 1 | R11: 1 | S11: 1 | T11: 1 | U11: 4 | V11: Execute at the same time
A12: Test Cycle | B12: Done | C12: Unfinished | D12: - | E12: N/A | G12: Done | H12: - | I12: N/A | J12: Blocked | P12: 06 Meter Time synchronisation to NIC - forward crossing interval (Force) | Q12: 1 | R12: 1 | S12: 1 | T12: 1 | U12: 4 | V12: Execute at the same time
A13: L&G 82-R64 | B13: 0.46685083 | C13: 0.011049724 | D13: 0.0027624309 | E13: 0.016574586 | F13: 0.49723757 | G13: 0.47237569 | H13: 0.0082872928 | I13: 0.016574586 | J13: 0.0055248619 | K13: 0.50276243 | L13: 1 | P13: 07 Meter Time synchronisation to NIC - backward crossing interval (Auto) | Q13: 1 | R13: 1 | S13: 1 | T13: 1 | U13: 4
A14: Grand Total | B14: 0.46685083 | C14: 0.011049724 | D14: 0.0027624309 | E14: 0.016574586 | F14: 0.49723757 | G14: 0.47237569 | H14: 0.0082872928 | I14: 0.016574586 | J14: 0.0055248619 | K14: 0.50276243 | L14: 1 | P14: 08 Meter Time synchronisation to NIC - backward crossing interval (Force) | Q14: 1 | R14: 1 | S14: 1 | T14: 1 | U14: 4
P15: AMM - On Demand Read - C1219 Read | Q15: 1 | R15: 1 | S15: 1 | T15: 1 | U15: 4
P16: AMM - On Demand Read - Interval | Q16: 1 | R16: 1 | S16: 1 | T16: 1 | U16: 4
P17: AMM - On Demand Read - New Data | Q17: 1 | R17: 1 | S17: 1 | T17: 1 | U17: 4
P18: AMM - On Demand Read - NIC Event Log | Q18: 1 | R18: 1 | S18: 1 | T18: 1 | U18: 4
P19: AMM - On Demand Read - Register | Q19: 1 | R19: 1 | S19: 1 | T19: 1 | U19: 4
A20: Target Cycle: | B20: L&G 82-R64 | P20: AMM - On Demand Read - Stored Self Read | Q20: 1 | R20: 1 | S20: 1 | T20: 1 | U20: 4
P21: Auto-Disconnect - Disabled | Q21: 1 | R21: 1 | S21: 1 | T21: 1 | U21: 4
A22: Count of Done | B22: Column Labels | P22: Auto-Disconnect - Enabled | Q22: 1 | R22: 1 | S22: 1 | T22: 1 | U22: 4
A23: Row Labels | B23: 1-Critical | C23: 2-High | D23: 3-Medium | E23: 4-Low | F23: Grand Total | P23: Auto-Disconnect - Override For NAP (L+G) | Q23: 1 | R23: 1 | S23: 1 | T23: 1 | U23: 4
A24: Done | B24: 174 | C24: 139 | D24: 23 | E24: 4 | F24: 340 | P24: Auto-Disconnect - Remote Lockout | Q24: 1 | R24: 1 | S24: 1 | T24: 1 | U24: 4
A25: Unfinished | B25: 3 | C25: 1 | F25: 4 | P25: Boost operation - Disabled | Q25: 1 | R25: 1 | S25: 1 | T25: 1 | U25: 4
A26: - | B26: 4 | F26: 4 | P26: Boost operation - Enabled - Boost (Boost Duration) minutes | Q26: 1 | R26: 1 | S26: 1 | T26: 1 | U26: 4
A27: N/A | B27: 8 | D27: 4 | F27: 12 | P27: Boost Primacy - Boost time longer than LC override | Q27: 1 | R27: 1 | S27: 1 | T27: 1 | U27: 4 | V27: Execute at the same time
A28: Blocked | B28: 1 | D28: 1 | F28: 2 | P28: Boost Primacy - Disabled | Q28: 1 | R28: 1 | S28: 1 | T28: 1 | U28: 4 | V28: Execute at the same time
A29: Grand Total | B29: 190 | C29: 140 | D29: 28 | E29: 4 | F29: 362 | P29: Boost Primacy - Enable-Disable | Q29: 1 | R29: 1 | S29: 1 | T29: 1 | U29: 4 | V29: Execute at the same time
P30: Broadcast - Load contactor connect via broadcast (immediate, no randomisation) | Q30: 1 | R30: 1 | S30: 1 | T30: 1 | U30: 4 | V30: Execute at the same time
P31: Broadcast - Load contactor connect via broadcast (immediate, randomisation) | Q31: 1 | R31: 1 | S31: 1 | T31: 1 | U31: 4 | V31: Execute at the same time
P32: Broadcast - Load contactor connect via broadcast (scheduled, no randomisation) | Q32: 1 | R32: 1 | S32: 1 | T32: 1 | U32: 4 | V32: Execute at the same time
P33: Broadcast - Load contactor disconnect via broadcast (immediate, no randomisation) | Q33: 1 | R33: 1 | S33: 1 | T33: 1 | U33: 4 | V33: Execute at the same time
P34: Broadcast - Load contactor disconnect via broadcast (immediate, randomisation) | Q34: 1 | R34: 1 | S34: 1 | T34: 1 | U34: 4 | V34: Execute at the same time
P35: Broadcast - Load contactor disconnect via broadcast (scheduled, no randomisation) | Q35: 1 | R35: 1 | S35: 1 | T35: 1 | U35: 4 | V35: Execute at the same time
P36: Broadcast 01 - Broadcast Groups - UIQ to meter | Q36: 1 | R36: 1 | S36: 1 | T36: 1 | U36: 4 | V36: Execute at the same time
P37: Broadcast 02 - Broadcast Groups - meter to UIQ | Q37: 1 | R37: 1 | S37: 1 | T37: 1 | U37: 4
P38: Broadcast 04 - Confirm the range of broadcast groups | Q38: 1 | R38: 1 | S38: 1 | T38: 1 | U38: 4
A39: Status: | B39: (All) | P39: Broadcast 05 - Broadcast cert upload via netmgr | Q39: 1 | R39: 1 | S39: 1 | T39: 1 | U39: 4
A40: Target Cycle: | B40: (All) | P40: Broadcast 06 - Broadcast cert upload via FSU | Q40: 1 | R40: 1 | S40: 1 | T40: 1 | U40: 4
P41: Broadcast 07 - Broadcast cert upload via Network Centre | Q41: 1 | R41: 1 | S41: 1 | T41: 1 | U41: 4
...

Sheet 2024 - L&G R64  Tracking
D1: Actual Resource Availability | H1: Planned Resource Availability | L1: Planned Velocity | P1: Delta Velocity | V1: Actual Velocity | Z1: Running Average Velocity | AD1: Daily Velocity | AI1: Total Velocity | AM1: Projection | AR1: # of testers = 2 | AS1: Target Finish Date | AU1: =Days!F10 -> 45582 | AV1: Actual Resource Availability (Based on if testing that day) | AZ1: Running Average Velocity (Based on if testing that day)
A2: Day | B2: Date | C2: Working Day | D2: Kamau | E2: Manoj | F2: Leonard | H2: Kamau | I2: Manoj | J2: Leonard | L2: Kamau | M2: Manoj | N2: Leonard | P2: Kamau | Q2: Manoj | R2: Leonard | T2: Date | U2: Working Day | V2: knjuguna(Kamau Njuguna) | W2: mkalra(Manoj Kalra) | X2: ljarillas(Leonard Jarillas) | Y2: Target | Z2: knjuguna(Kamau Njuguna) | AA2: mkalra(Manoj Kalra) | AB2: ljarillas(Leonard Jarillas) | AD2: Date | AE2: Planned | AF2: Actual | AG2: Average | AI2: Date | AJ2: Planned | AK2: Actual | AM2: Date | AN2: 5D Running Average | AO2: 5D Running Average / Resource | AP2: Average/Resource | AQ2: Projected Finish | AR2: Needed velocity | AS2: Needed velocity / tester | AU2: Notes | AV2: Kamau | AW2: Manoj | AX2: Leonard | AY2: Date | AZ2: knjuguna(Kamau Njuguna) | BA2: mkalra(Manoj Kalra) | BB2: ljarillas(Leonard Jarillas)
A3: =VLOOKUP(WEEKDAY(B3,2),Days!$A$1:$B$7,2,0) -> Fri | B3: 45555 | C3: =IF(AND(A3<>"Sat",A3<>"Sun",ISERROR(VLOOKUP(B3,Days!$A$10:$A$38,1,0))),1,(IF(AF3<>0,1,0))) -> 1 | D3: 1 | E3: 1 | F3: 0 | H3: 1 | I3: 1 | J3: 0 | L3: =$C3*H3*Days!$F$1 -> 8 | M3: =$C3*I3*Days!$F$1 -> 8 | N3: =$C3*J3*Days!$F$1 -> 0 | P3: =IF(B3>TODAY(),0,V3-L3) -> 2 | Q3: =IF(B3>TODAY(),0,W3-M3) -> 0 | R3: =IF(B3>TODAY(),0,X3-N3) -> 0 | T3: =B3 -> 45555 | U3: =C3 -> 1 | V3: =COUNTIFS('2024 - L&G R64 - Test Instances'!H:H,B3,'2024 - L&G R64 - Test Instances'!L:L,$V$2,'2024 - L&G R64 - Test Instances'!O:O,"Done") -> 10 | W3: =COUNTIFS('2024 - L&G R64 - Test Instances'!H:H,B3,'2024 - L&G R64 - Test Instances'!L:L,$W$2,'2024 - L&G R64 - Test Instances'!O:O,"Done") -> 8 | X3: =COUNTIFS('2024 - L&G R64 - Test Instances'!H:H,B3,'2024 - L&G R64 - Test Instances'!L:L,$X$2,'2024 - L&G R64 - Test Instances'!O:O,"Done") -> 0 | Y3: 8 | Z3: =IF(B3>TODAY(),"",SUM($V$3:V3)/SUM($D$3:D3)) -> 10 | AA3: =IF(B3>TODAY(),"",SUM($W$3:W3)/SUM($E$3:E3)) -> 8 | AB3: =IF(B3>TODAY(),"",SUM($X$3:X3)/SUM($F$3:F3)) -> #DIV/0! | AD3: =B3 -> 45555 | AE3: =SUM(L3:N3) -> 16 | AF3: =SUM(V3:W3) -> 18 | AG3: =SUMIF(Z3:AA3,"<>#DIV/0!",Z3:AA3) -> 18 | AI3: =B3 -> 45555 | AJ3: =Days!F2 -> 274 | AK3: =Days!F3 -> 361 | AM3: =B3 -> 45555 | AP3: =IF(ISERROR(AF3/SUM(D3:F3)),0,AF3/SUM(D3:F3)) -> 9 | AR3: =AK3/(NETWORKDAYS(B3,$AU$1,Days!$A$11:$A$25)-1) -> 20.055556 | AS3: =AR3/((RIGHT($AR$1,1)*1)) -> 10.027778 | AV3: =IF(V3>0,1,0) -> 1 | AW3: =IF(W3>0,1,0) -> 1 | AX3: =IF(X3>0,1,0) -> 0 | AY3: =B3 -> 45555 | AZ3: =IF(B3>TODAY(),"",SUM($V$3:V3)/SUM($AV$3:AV3)) -> 10 | BA3: =IF(B3>TODAY(),"",SUM($W$3:W3)/SUM($AW$3:AW3)) -> 8 | BB3: =IF(B3>TODAY(),"",SUM($X$3:X3)/SUM($AX$3:AX3)) -> #DIV/0!
A4: =VLOOKUP(WEEKDAY(B4,2),Days!$A$1:$B$7,2,0) -> Sat | B4: =B3+1 -> 45556 | C4: =IF(AND(A4<>"Sat",A4<>"Sun",ISERROR(VLOOKUP(B4,Days!$A$10:$A$38,1,0))),1,(IF(AF4<>0,1,0))) -> 0 | D4: 0 | E4: 0 | F4: 0 | H4: 0 | I4: 0 | J4: 0 | L4: =$C4*H4*Days!$F$1 -> 0 | M4: =$C4*I4*Days!$F$1 -> 0 | N4: =$C4*J4*Days!$F$1 -> 0 | P4: =IF(B4>TODAY(),0,V4-L4) -> 0 | Q4: =IF(B4>TODAY(),0,W4-M4) -> 0 | R4: =IF(B4>TODAY(),0,X4-N4) -> 0 | T4: =B4 -> 45556 | U4: =C4 -> 0 | V4: =COUNTIFS('2024 - L&G R64 - Test Instances'!H:H,B4,'2024 - L&G R64 - Test Instances'!L:L,$V$2,'2024 - L&G R64 - Test Instances'!O:O,"Done") -> 0 | W4: =COUNTIFS('2024 - L&G R64 - Test Instances'!H:H,B4,'2024 - L&G R64 - Test Instances'!L:L,$W$2,'2024 - L&G R64 - Test Instances'!O:O,"Done") -> 0 | X4: =COUNTIFS('2024 - L&G R64 - Test Instances'!H:H,B4,'2024 - L&G R64 - Test Instances'!L:L,$X$2,'2024 - L&G R64 - Test Instances'!O:O,"Done") -> 0 | Y4: 8 | Z4: =IF(B4>TODAY(),"",SUM($V$3:V4)/SUM($D$3:D4)) -> 10 | AA4: =IF(B4>TODAY(),"",SUM($W$3:W4)/SUM($E$3:E4)) -> 8 | AB4: =IF(B4>TODAY(),"",SUM($X$3:X4)/SUM($F$3:F4)) -> #DIV/0! | AD4: =B4 -> 45556 | AE4: =SUM(L4:N4) -> 0 | AF4: =SUM(V4:W4) -> 0 | AG4: =SUMIF(Z4:AA4,"<>#DIV/0!",Z4:AA4) -> 18 | AI4: =B4 -> 45556 | AJ4: =AJ3-AE4 -> 274 | AK4: =IF(B4>TODAY(),"",AK3-AF4) -> 361 | AM4: =B4 -> 45556 | AP4: =IF(ISERROR(AF4/SUM(D4:F4)),0,AF4/SUM(D4:F4)) -> 0 | AR4: =AK4/(NETWORKDAYS(B4,$AU$1,Days!$A$11:$A$25)-1) -> 21.235294 | AS4: =AR4/((RIGHT($AR$1,1)*1)) -> 10.617647 | AV4: =IF(V4>0,1,0) -> 0 | AW4: =IF(W4>0,1,0) -> 0 | AX4: =IF(X4>0,1,0) -> 0 | AY4: =B4 -> 45556 | AZ4: =IF(B4>TODAY(),"",SUM($V$3:V4)/SUM($AV$3:AV4)) -> 10 | BA4: =IF(B4>TODAY(),"",SUM($W$3:W4)/SUM($AW$3:AW4)) -> 8 | BB4: =IF(B4>TODAY(),"",SUM($X$3:X4)/SUM($AX$3:AX4)) -> #DIV/0!
A5: =VLOOKUP(WEEKDAY(B5,2),Days!$A$1:$B$7,2,0) -> Sun | B5: =B4+1 -> 45557 | C5: =IF(AND(A5<>"Sat",A5<>"Sun",ISERROR(VLOOKUP(B5,Days!$A$10:$A$38,1,0))),1,(IF(AF5<>0,1,0))) -> 0 | D5: 0 | E5: 0 | F5: 0 | H5: 0 | I5: 0 | J5: 0 | L5: =$C5*H5*Days!$F$1 -> 0 | M5: =$C5*I5*Days!$F$1 -> 0 | N5: =$C5*J5*Days!$F$1 -> 0 | P5: =IF(B5>TODAY(),0,V5-L5) -> 0 | Q5: =IF(B5>TODAY(),0,W5-M5) -> 0 | R5: =IF(B5>TODAY(),0,X5-N5) -> 0 | T5: =B5 -> 45557 | U5: =C5 -> 0 | V5: =COUNTIFS('2024 - L&G R64 - Test Instances'!H:H,B5,'2024 - L&G R64 - Test Instances'!L:L,$V$2,'2024 - L&G R64 - Test Instances'!O:O,"Done") -> 0 | W5: =COUNTIFS('2024 - L&G R64 - Test Instances'!H:H,B5,'2024 - L&G R64 - Test Instances'!L:L,$W$2,'2024 - L&G R64 - Test Instances'!O:O,"Done") -> 0 | X5: =COUNTIFS('2024 - L&G R64 - Test Instances'!H:H,B5,'2024 - L&G R64 - Test Instances'!L:L,$X$2,'2024 - L&G R64 - Test Instances'!O:O,"Done") -> 0 | Y5: 8 | Z5: =IF(B5>TODAY(),"",SUM($V$3:V5)/SUM($D$3:D5)) -> 10 | AA5: =IF(B5>TODAY(),"",SUM($W$3:W5)/SUM($E$3:E5)) -> 8 | AB5: =IF(B5>TODAY(),"",SUM($X$3:X5)/SUM($F$3:F5)) -> #DIV/0! | AD5: =B5 -> 45557 | AE5: =SUM(L5:N5) -> 0 | AF5: =SUM(V5:W5) -> 0 | AG5: =SUMIF(Z5:AA5,"<>#DIV/0!",Z5:AA5) -> 18 | AI5: =B5 -> 45557 | AJ5: =AJ4-AE5 -> 274 | AK5: =IF(B5>TODAY(),"",AK4-AF5) -> 361 | AM5: =B5 -> 45557 | AP5: =IF(ISERROR(AF5/SUM(D5:F5)),0,AF5/SUM(D5:F5)) -> 0 | AR5: =AK5/(NETWORKDAYS(B5,$AU$1,Days!$A$11:$A$25)-1) -> 21.235294 | AS5: =AR5/((RIGHT($AR$1,1)*1)) -> 10.617647 | AV5: =IF(V5>0,1,0) -> 0 | AW5: =IF(W5>0,1,0) -> 0 | AX5: =IF(X5>0,1,0) -> 0 | AY5: =B5 -> 45557 | AZ5: =IF(B5>TODAY(),"",SUM($V$3:V5)/SUM($AV$3:AV5)) -> 10 | BA5: =IF(B5>TODAY(),"",SUM($W$3:W5)/SUM($AW$3:AW5)) -> 8 | BB5: =IF(B5>TODAY(),"",SUM($X$3:X5)/SUM($AX$3:AX5)) -> #DIV/0!
A6: =VLOOKUP(WEEKDAY(B6,2),Days!$A$1:$B$7,2,0) -> Mon | B6: =B5+1 -> 45558 | C6: =IF(AND(A6<>"Sat",A6<>"Sun",ISERROR(VLOOKUP(B6,Days!$A$10:$A$38,1,0))),1,(IF(AF6<>0,1,0))) -> 1 | D6: 1 | E6: 1 | F6: 0 | H6: 1 | I6: 1 | J6: 0 | L6: =$C6*H6*Days!$F$1 -> 8 | M6: =$C6*I6*Days!$F$1 -> 8 | N6: =$C6*J6*Days!$F$1 -> 0 | P6: =IF(B6>TODAY(),0,V6-L6) -> -6 | Q6: =IF(B6>TODAY(),0,W6-M6) -> -8 | R6: =IF(B6>TODAY(),0,X6-N6) -> 0 | T6: =B6 -> 45558 | U6: =C6 -> 1 | V6: =COUNTIFS('2024 - L&G R64 - Test Instances'!H:H,B6,'2024 - L&G R64 - Test Instances'!L:L,$V$2,'2024 - L&G R64 - Test Instances'!O:O,"Done") -> 2 | W6: =COUNTIFS('2024 - L&G R64 - Test Instances'!H:H,B6,'2024 - L&G R64 - Test Instances'!L:L,$W$2,'2024 - L&G R64 - Test Instances'!O:O,"Done") -> 0 | X6: =COUNTIFS('2024 - L&G R64 - Test Instances'!H:H,B6,'2024 - L&G R64 - Test Instances'!L:L,$X$2,'2024 - L&G R64 - Test Instances'!O:O,"Done") -> 0 | Y6: 8 | Z6: =IF(B6>TODAY(),"",SUM($V$3:V6)/SUM($D$3:D6)) -> 6 | AA6: =IF(B6>TODAY(),"",SUM($W$3:W6)/SUM($E$3:E6)) -> 4 | AB6: =IF(B6>TODAY(),"",SUM($X$3:X6)/SUM($F$3:F6)) -> #DIV/0! | AD6: =B6 -> 45558 | AE6: =SUM(L6:N6) -> 16 | AF6: =SUM(V6:W6) -> 2 | AG6: =SUMIF(Z6:AA6,"<>#DIV/0!",Z6:AA6) -> 10 | AI6: =B6 -> 45558 | AJ6: =AJ5-AE6 -> 258 | AK6: =IF(B6>TODAY(),"",AK5-AF6) -> 359 | AM6: =B6 -> 45558 | AP6: =IF(ISERROR(AF6/SUM(D6:F6)),0,AF6/SUM(D6:F6)) -> 1 | AR6: =AK6/(NETWORKDAYS(B6,$AU$1,Days!$A$11:$A$25)-1) -> 21.117647 | AS6: =AR6/((RIGHT($AR$1,1)*1)) -> 10.558824 | AV6: =IF(V6>0,1,0) -> 1 | AW6: =IF(W6>0,1,0) -> 0 | AX6: =IF(X6>0,1,0) -> 0 | AY6: =B6 -> 45558 | AZ6: =IF(B6>TODAY(),"",SUM($V$3:V6)/SUM($AV$3:AV6)) -> 6 | BA6: =IF(B6>TODAY(),"",SUM($W$3:W6)/SUM($AW$3:AW6)) -> 8 | BB6: =IF(B6>TODAY(),"",SUM($X$3:X6)/SUM($AX$3:AX6)) -> #DIV/0!
A7: =VLOOKUP(WEEKDAY(B7,2),Days!$A$1:$B$7,2,0) -> Tue | B7: =B6+1 -> 45559 | C7: =IF(AND(A7<>"Sat",A7<>"Sun",ISERROR(VLOOKUP(B7,Days!$A$10:$A$38,1,0))),1,(IF(AF7<>0,1,0))) -> 1 | D7: 1 | E7: 1 | F7: 0 | H7: 1 | I7: 1 | J7: 0 | L7: =$C7*H7*Days!$F$1 -> 8 | M7: =$C7*I7*Days!$F$1 -> 8 | N7: =$C7*J7*Days!$F$1 -> 0 | P7: =IF(B7>TODAY(),0,V7-L7) -> -3 | Q7: =IF(B7>TODAY(),0,W7-M7) -> 84 | R7: =IF(B7>TODAY(),0,X7-N7) -> 0 | T7: =B7 -> 45559 | U7: =C7 -> 1 | V7: =COUNTIFS('2024 - L&G R64 - Test Instances'!H:H,B7,'2024 - L&G R64 - Test Instances'!L:L,$V$2,'2024 - L&G R64 - Test Instances'!O:O,"Done") -> 5 | W7: =COUNTIFS('2024 - L&G R64 - Test Instances'!H:H,B7,'2024 - L&G R64 - Test Instances'!L:L,$W$2,'2024 - L&G R64 - Test Instances'!O:O,"Done") -> 92 | X7: =COUNTIFS('2024 - L&G R64 - Test Instances'!H:H,B7,'2024 - L&G R64 - Test Instances'!L:L,$X$2,'2024 - L&G R64 - Test Instances'!O:O,"Done") -> 0 | Y7: 8 | Z7: =IF(B7>TODAY(),"",SUM($V$3:V7)/SUM($D$3:D7)) -> 5.6666667 | AA7: =IF(B7>TODAY(),"",SUM($W$3:W7)/SUM($E$3:E7)) -> 33.333333 | AB7: =IF(B7>TODAY(),"",SUM($X$3:X7)/SUM($F$3:F7)) -> #DIV/0! | AD7: =B7 -> 45559 | AE7: =SUM(L7:N7) -> 16 | AF7: =SUM(V7:W7) -> 97 | AG7: =SUMIF(Z7:AA7,"<>#DIV/0!",Z7:AA7) -> 39 | AI7: =B7 -> 45559 | AJ7: =AJ6-AE7 -> 242 | AK7: =IF(B7>TODAY(),"",AK6-AF7) -> 262 | AM7: =B7 -> 45559 | AN7: =IF(B7>TODAY(),0,SUM(AF3:AF7)/SUM(C3:C7)) -> 39 | AO7: =IF(B7>TODAY(),0,SUM(AF3:AF7)/SUM(D3:F7)) -> 19.5 | AP7: =IF(ISERROR(AF7/SUM(D7:F7)),0,AF7/SUM(D7:F7)) -> 48.5 | AQ7: =IF(ISERROR(B7+(AK7/AN7)*(7/5)),AQ6,(B7+(AK7/AN7)*(7/5))) -> 45568.405 | AR7: =AK7/(NETWORKDAYS(B7,$AU$1,Days!$A$11:$A$25)-1) -> 16.375 | AS7: =AR7/((RIGHT($AR$1,1)*1)) -> 8.1875 | AV7: =IF(V7>0,1,0) -> 1 | AW7: =IF(W7>0,1,0) -> 1 | AX7: =IF(X7>0,1,0) -> 0 | AY7: =B7 -> 45559 | AZ7: =IF(B7>TODAY(),"",SUM($V$3:V7)/SUM($AV$3:AV7)) -> 5.6666667 | BA7: =IF(B7>TODAY(),"",SUM($W$3:W7)/SUM($AW$3:AW7)) -> 50 | BB7: =IF(B7>TODAY(),"",SUM($X$3:X7)/SUM($AX$3:AX7)) -> #DIV/0!
A8: =VLOOKUP(WEEKDAY(B8,2),Days!$A$1:$B$7,2,0) -> Wed | B8: =B7+1 -> 45560 | C8: =IF(AND(A8<>"Sat",A8<>"Sun",ISERROR(VLOOKUP(B8,Days!$A$10:$A$38,1,0))),1,(IF(AF8<>0,1,0))) -> 1 | D8: 0 | E8: 1 | F8: 0 | H8: 1 | I8: 1 | J8: 0 | L8: =$C8*H8*Days!$F$1 -> 8 | M8: =$C8*I8*Days!$F$1 -> 8 | N8: =$C8*J8*Days!$F$1 -> 0 | P8: =IF(B8>TODAY(),0,V8-L8) -> -8 | Q8: =IF(B8>TODAY(),0,W8-M8) -> 6 | R8: =IF(B8>TODAY(),0,X8-N8) -> 0 | T8: =B8 -> 45560 | U8: =C8 -> 1 | V8: =COUNTIFS('2024 - L&G R64 - Test Instances'!H:H,B8,'2024 - L&G R64 - Test Instances'!L:L,$V$2,'2024 - L&G R64 - Test Instances'!O:O,"Done") -> 0 | W8: =COUNTIFS('2024 - L&G R64 - Test Instances'!H:H,B8,'2024 - L&G R64 - Test Instances'!L:L,$W$2,'2024 - L&G R64 - Test Instances'!O:O,"Done") -> 14 | X8: =COUNTIFS('2024 - L&G R64 - Test Instances'!H:H,B8,'2024 - L&G R64 - Test Instances'!L:L,$X$2,'2024 - L&G R64 - Test Instances'!O:O,"Done") -> 0 | Y8: 8 | Z8: =IF(B8>TODAY(),"",SUM($V$3:V8)/SUM($D$3:D8)) -> 5.6666667 | AA8: =IF(B8>TODAY(),"",SUM($W$3:W8)/SUM($E$3:E8)) -> 28.5 | AB8: =IF(B8>TODAY(),"",SUM($X$3:X8)/SUM($F$3:F8)) -> #DIV/0! | AD8: =B8 -> 45560 | AE8: =SUM(L8:N8) -> 16 | AF8: =SUM(V8:W8) -> 14 | AG8: =SUMIF(Z8:AA8,"<>#DIV/0!",Z8:AA8) -> 34.166667 | AI8: =B8 -> 45560 | AJ8: =AJ7-AE8 -> 226 | AK8: =IF(B8>TODAY(),"",AK7-AF8) -> 248 | AM8: =B8 -> 45560 | AN8: =IF(B8>TODAY(),0,SUM(AF4:AF8)/SUM(C4:C8)) -> 37.666667 | AO8: =IF(B8>TODAY(),0,SUM(AF4:AF8)/SUM(D4:F8)) -> 22.6 | AP8: =IF(ISERROR(AF8/SUM(D8:F8)),0,AF8/SUM(D8:F8)) -> 14 | AQ8: =IF(ISERROR(B8+(AK8/AN8)*(7/5)),AQ7,(B8+(AK8/AN8)*(7/5))) -> 45569.218 | AR8: =AK8/(NETWORKDAYS(B8,$AU$1,Days!$A$11:$A$25)-1) -> 16.533333 | AS8: =AR8/((RIGHT($AR$1,1)*1)) -> 8.2666667 | AV8: =IF(V8>0,1,0) -> 0 | AW8: =IF(W8>0,1,0) -> 1 | AX8: =IF(X8>0,1,0) -> 0 | AY8: =B8 -> 45560 | AZ8: =IF(B8>TODAY(),"",SUM($V$3:V8)/SUM($AV$3:AV8)) -> 5.6666667 | BA8: =IF(B8>TODAY(),"",SUM($W$3:W8)/SUM($AW$3:AW8)) -> 38 | BB8: =IF(B8>TODAY(),"",SUM($X$3:X8)/SUM($AX$3:AX8)) -> #DIV/0!
A9: =VLOOKUP(WEEKDAY(B9,2),Days!$A$1:$B$7,2,0) -> Thu | B9: =B8+1 -> 45561 | C9: =IF(AND(A9<>"Sat",A9<>"Sun",ISERROR(VLOOKUP(B9,Days!$A$10:$A$38,1,0))),1,(IF(AF9<>0,1,0))) -> 1 | D9: 1 | E9: 1 | F9: 0 | H9: 1 | I9: 1 | J9: 0 | L9: =$C9*H9*Days!$F$1 -> 8 | M9: =$C9*I9*Days!$F$1 -> 8 | N9: =$C9*J9*Days!$F$1 -> 0 | P9: =IF(B9>TODAY(),0,V9-L9) -> 0 | Q9: =IF(B9>TODAY(),0,W9-M9) -> -3 | R9: =IF(B9>TODAY(),0,X9-N9) -> 0 | T9: =B9 -> 45561 | U9: =C9 -> 1 | V9: =COUNTIFS('2024 - L&G R64 - Test Instances'!H:H,B9,'2024 - L&G R64 - Test Instances'!L:L,$V$2,'2024 - L&G R64 - Test Instances'!O:O,"Done") -> 8 | W9: =COUNTIFS('2024 - L&G R64 - Test Instances'!H:H,B9,'2024 - L&G R64 - Test Instances'!L:L,$W$2,'2024 - L&G R64 - Test Instances'!O:O,"Done") -> 5 | X9: =COUNTIFS('2024 - L&G R64 - Test Instances'!H:H,B9,'2024 - L&G R64 - Test Instances'!L:L,$X$2,'2024 - L&G R64 - Test Instances'!O:O,"Done") -> 0 | Y9: 8 | Z9: =IF(B9>TODAY(),"",SUM($V$3:V9)/SUM($D$3:D9)) -> 6.25 | AA9: =IF(B9>TODAY(),"",SUM($W$3:W9)/SUM($E$3:E9)) -> 23.8 | AB9: =IF(B9>TODAY(),"",SUM($X$3:X9)/SUM($F$3:F9)) -> #DIV/0! | AD9: =B9 -> 45561 | AE9: =SUM(L9:N9) -> 16 | AF9: =SUM(V9:W9) -> 13 | AG9: =SUMIF(Z9:AA9,"<>#DIV/0!",Z9:AA9) -> 30.05 | AI9: =B9 -> 45561 | AJ9: =AJ8-AE9 -> 210 | AK9: =IF(B9>TODAY(),"",AK8-AF9) -> 235 | AM9: =B9 -> 45561 | AN9: =IF(B9>TODAY(),0,SUM(AF5:AF9)/SUM(C5:C9)) -> 31.5 | AO9: =IF(B9>TODAY(),0,SUM(AF5:AF9)/SUM(D5:F9)) -> 18 | AP9: =IF(ISERROR(AF9/SUM(D9:F9)),0,AF9/SUM(D9:F9)) -> 6.5 | AQ9: =IF(ISERROR(B9+(AK9/AN9)*(7/5)),AQ8,(B9+(AK9/AN9)*(7/5))) -> 45571.444 | AR9: =AK9/(NETWORKDAYS(B9,$AU$1,Days!$A$11:$A$25)-1) -> 16.785714 | AS9: =AR9/((RIGHT($AR$1,1)*1)) -> 8.3928571 | AV9: =IF(V9>0,1,0) -> 1 | AW9: =IF(W9>0,1,0) -> 1 | AX9: =IF(X9>0,1,0) -> 0 | AY9: =B9 -> 45561 | AZ9: =IF(B9>TODAY(),"",SUM($V$3:V9)/SUM($AV$3:AV9)) -> 6.25 | BA9: =IF(B9>TODAY(),"",SUM($W$3:W9)/SUM($AW$3:AW9)) -> 29.75 | BB9: =IF(B9>TODAY(),"",SUM($X$3:X9)/SUM($AX$3:AX9)) -> #DIV/0!
A10: =VLOOKUP(WEEKDAY(B10,2),Days!$A$1:$B$7,2,0) -> Fri | B10: =B9+1 -> 45562 | C10: =IF(AND(A10<>"Sat",A10<>"Sun",ISERROR(VLOOKUP(B10,Days!$A$10:$A$38,1,0))),1,(IF(AF10<>0,1,0))) -> 0 | D10: 0 | E10: 0 | F10: 0 | H10: 1 | I10: 1 | J10: 0 | L10: =$C10*H10*Days!$F$1 -> 0 | M10: =$C10*I10*Days!$F$1 -> 0 | N10: =$C10*J10*Days!$F$1 -> 0 | P10: =IF(B10>TODAY(),0,V10-L10) -> 0 | Q10: =IF(B10>TODAY(),0,W10-M10) -> 0 | R10: =IF(B10>TODAY(),0,X10-N10) -> 0 | T10: =B10 -> 45562 | U10: =C10 -> 0 | V10: =COUNTIFS('2024 - L&G R64 - Test Instances'!H:H,B10,'2024 - L&G R64 - Test Instances'!L:L,$V$2,'2024 - L&G R64 - Test Instances'!O:O,"Done") -> 0 | W10: =COUNTIFS('2024 - L&G R64 - Test Instances'!H:H,B10,'2024 - L&G R64 - Test Instances'!L:L,$W$2,'2024 - L&G R64 - Test Instances'!O:O,"Done") -> 0 | X10: =COUNTIFS('2024 - L&G R64 - Test Instances'!H:H,B10,'2024 - L&G R64 - Test Instances'!L:L,$X$2,'2024 - L&G R64 - Test Instances'!O:O,"Done") -> 0 | Y10: 8 | Z10: =IF(B10>TODAY(),"",SUM($V$3:V10)/SUM($D$3:D10)) -> 6.25 | AA10: =IF(B10>TODAY(),"",SUM($W$3:W10)/SUM($E$3:E10)) -> 23.8 | AB10: =IF(B10>TODAY(),"",SUM($X$3:X10)/SUM($F$3:F10)) -> #DIV/0! | AD10: =B10 -> 45562 | AE10: =SUM(L10:N10) -> 0 | AF10: =SUM(V10:W10) -> 0 | AG10: =SUMIF(Z10:AA10,"<>#DIV/0!",Z10:AA10) -> 30.05 | AI10: =B10 -> 45562 | AJ10: =AJ9-AE10 -> 210 | AK10: =IF(B10>TODAY(),"",AK9-AF10) -> 235 | AM10: =B10 -> 45562 | AN10: =IF(B10>TODAY(),0,SUM(AF6:AF10)/SUM(C6:C10)) -> 31.5 | AO10: =IF(B10>TODAY(),0,SUM(AF6:AF10)/SUM(D6:F10)) -> 18 | AP10: =IF(ISERROR(AF10/SUM(D10:F10)),0,AF10/SUM(D10:F10)) -> 0 | AQ10: =IF(ISERROR(B10+(AK10/AN10)*(7/5)),AQ9,(B10+(AK10/AN10)*(7/5))) -> 45572.444 | AR10: =AK10/(NETWORKDAYS(B10,$AU$1,Days!$A$11:$A$25)-1) -> 18.076923 | AS10: =AR10/((RIGHT($AR$1,1)*1)) -> 9.0384615 | AV10: =IF(V10>0,1,0) -> 0 | AW10: =IF(W10>0,1,0) -> 0 | AX10: =IF(X10>0,1,0) -> 0 | AY10: =B10 -> 45562 | AZ10: =IF(B10>TODAY(),"",SUM($V$3:V10)/SUM($AV$3:AV10)) -> 6.25 | BA10: =IF(B10>TODAY(),"",SUM($W$3:W10)/SUM($AW$3:AW10)) -> 29.75 | BB10: =IF(B10>TODAY(),"",SUM($X$3:X10)/SUM($AX$3:AX10)) -> #DIV/0!
A11: =VLOOKUP(WEEKDAY(B11,2),Days!$A$1:$B$7,2,0) -> Sat | B11: =B10+1 -> 45563 | C11: =IF(AND(A11<>"Sat",A11<>"Sun",ISERROR(VLOOKUP(B11,Days!$A$10:$A$38,1,0))),1,(IF(AF11<>0,1,0))) -> 0 | D11: 0 | E11: 0 | F11: 0 | H11: 0 | I11: 0 | J11: 0 | L11: =$C11*H11*Days!$F$1 -> 0 | M11: =$C11*I11*Days!$F$1 -> 0 | N11: =$C11*J11*Days!$F$1 -> 0 | P11: =IF(B11>TODAY(),0,V11-L11) -> 0 | Q11: =IF(B11>TODAY(),0,W11-M11) -> 0 | R11: =IF(B11>TODAY(),0,X11-N11) -> 0 | T11: =B11 -> 45563 | U11: =C11 -> 0 | V11: =COUNTIFS('2024 - L&G R64 - Test Instances'!H:H,B11,'2024 - L&G R64 - Test Instances'!L:L,$V$2,'2024 - L&G R64 - Test Instances'!O:O,"Done") -> 0 | W11: =COUNTIFS('2024 - L&G R64 - Test Instances'!H:H,B11,'2024 - L&G R64 - Test Instances'!L:L,$W$2,'2024 - L&G R64 - Test Instances'!O:O,"Done") -> 0 | X11: =COUNTIFS('2024 - L&G R64 - Test Instances'!H:H,B11,'2024 - L&G R64 - Test Instances'!L:L,$X$2,'2024 - L&G R64 - Test Instances'!O:O,"Done") -> 0 | Y11: 8 | Z11: =IF(B11>TODAY(),"",SUM($V$3:V11)/SUM($D$3:D11)) -> 6.25 | AA11: =IF(B11>TODAY(),"",SUM($W$3:W11)/SUM($E$3:E11)) -> 23.8 | AB11: =IF(B11>TODAY(),"",SUM($X$3:X11)/SUM($F$3:F11)) -> #DIV/0! | AD11: =B11 -> 45563 | AE11: =SUM(L11:N11) -> 0 | AF11: =SUM(V11:W11) -> 0 | AG11: =SUMIF(Z11:AA11,"<>#DIV/0!",Z11:AA11) -> 30.05 | AI11: =B11 -> 45563 | AJ11: =AJ10-AE11 -> 210 | AK11: =IF(B11>TODAY(),"",AK10-AF11) -> 235 | AM11: =B11 -> 45563 | AN11: =IF(B11>TODAY(),0,SUM(AF7:AF11)/SUM(C7:C11)) -> 41.333333 | AO11: =IF(B11>TODAY(),0,SUM(AF7:AF11)/SUM(D7:F11)) -> 24.8 | AP11: =IF(ISERROR(AF11/SUM(D11:F11)),0,AF11/SUM(D11:F11)) -> 0 | AQ11: =IF(ISERROR(B11+(AK11/AN11)*(7/5)),AQ10,(B11+(AK11/AN11)*(7/5))) -> 45570.96 | AR11: =AK11/(NETWORKDAYS(B11,$AU$1,Days!$A$11:$A$25)-1) -> 18.076923 | AS11: =AR11/((RIGHT($AR$1,1)*1)) -> 9.0384615 | AV11: =IF(V11>0,1,0) -> 0 | AW11: =IF(W11>0,1,0) -> 0 | AX11: =IF(X11>0,1,0) -> 0 | AY11: =B11 -> 45563 | AZ11: =IF(B11>TODAY(),"",SUM($V$3:V11)/SUM($AV$3:AV11)) -> 6.25 | BA11: =IF(B11>TODAY(),"",SUM($W$3:W11)/SUM($AW$3:AW11)) -> 29.75 | BB11: =IF(B11>TODAY(),"",SUM($X$3:X11)/SUM($AX$3:AX11)) -> #DIV/0!
A12: =VLOOKUP(WEEKDAY(B12,2),Days!$A$1:$B$7,2,0) -> Sun | B12: =B11+1 -> 45564 | C12: =IF(AND(A12<>"Sat",A12<>"Sun",ISERROR(VLOOKUP(B12,Days!$A$10:$A$38,1,0))),1,(IF(AF12<>0,1,0))) -> 0 | D12: 0 | E12: 0 | F12: 0 | H12: 0 | I12: 0 | J12: 0 | L12: =$C12*H12*Days!$F$1 -> 0 | M12: =$C12*I12*Days!$F$1 -> 0 | N12: =$C12*J12*Days!$F$1 -> 0 | P12: =IF(B12>TODAY(),0,V12-L12) -> 0 | Q12: =IF(B12>TODAY(),0,W12-M12) -> 0 | R12: =IF(B12>TODAY(),0,X12-N12) -> 0 | T12: =B12 -> 45564 | U12: =C12 -> 0 | V12: =COUNTIFS('2024 - L&G R64 - Test Instances'!H:H,B12,'2024 - L&G R64 - Test Instances'!L:L,$V$2,'2024 - L&G R64 - Test Instances'!O:O,"Done") -> 0 | W12: =COUNTIFS('2024 - L&G R64 - Test Instances'!H:H,B12,'2024 - L&G R64 - Test Instances'!L:L,$W$2,'2024 - L&G R64 - Test Instances'!O:O,"Done") -> 0 | X12: =COUNTIFS('2024 - L&G R64 - Test Instances'!H:H,B12,'2024 - L&G R64 - Test Instances'!L:L,$X$2,'2024 - L&G R64 - Test Instances'!O:O,"Done") -> 0 | Y12: 8 | Z12: =IF(B12>TODAY(),"",SUM($V$3:V12)/SUM($D$3:D12)) -> 6.25 | AA12: =IF(B12>TODAY(),"",SUM($W$3:W12)/SUM($E$3:E12)) -> 23.8 | AB12: =IF(B12>TODAY(),"",SUM($X$3:X12)/SUM($F$3:F12)) -> #DIV/0! | AD12: =B12 -> 45564 | AE12: =SUM(L12:N12) -> 0 | AF12: =SUM(V12:W12) -> 0 | AG12: =SUMIF(Z12:AA12,"<>#DIV/0!",Z12:AA12) -> 30.05 | AI12: =B12 -> 45564 | AJ12: =AJ11-AE12 -> 210 | AK12: =IF(B12>TODAY(),"",AK11-AF12) -> 235 | AM12: =B12 -> 45564 | AN12: =IF(B12>TODAY(),0,SUM(AF8:AF12)/SUM(C8:C12)) -> 13.5 | AO12: =IF(B12>TODAY(),0,SUM(AF8:AF12)/SUM(D8:F12)) -> 9 | AP12: =IF(ISERROR(AF12/SUM(D12:F12)),0,AF12/SUM(D12:F12)) -> 0 | AQ12: =IF(ISERROR(B12+(AK12/AN12)*(7/5)),AQ11,(B12+(AK12/AN12)*(7/5))) -> 45588.37 | AR12: =AK12/(NETWORKDAYS(B12,$AU$1,Days!$A$11:$A$25)-1) -> 18.076923 | AS12: =AR12/((RIGHT($AR$1,1)*1)) -> 9.0384615 | AV12: =IF(V12>0,1,0) -> 0 | AW12: =IF(W12>0,1,0) -> 0 | AX12: =IF(X12>0,1,0) -> 0 | AY12: =B12 -> 45564 | AZ12: =IF(B12>TODAY(),"",SUM($V$3:V12)/SUM($AV$3:AV12)) -> 6.25 | BA12: =IF(B12>TODAY(),"",SUM($W$3:W12)/SUM($AW$3:AW12)) -> 29.75 | BB12: =IF(B12>TODAY(),"",SUM($X$3:X12)/SUM($AX$3:AX12)) -> #DIV/0!
